Workbook

Sheet Capital & Ownership
B1: LOKA — CAPITAL, OWNERSHIP & PRE-OPENING EXPENSES
B2: Last updated: 22 May 2026 14:13 | Blue = hardcoded inputs Yellow = add new expenses here
B4: A. OWNERSHIP STRUCTURE
B5: Owner | C5: Share % | D5: Capital ($) | E5: Expenses ($) | F5: Remaining ($) | G5: Role / Notes
B6: Lohith Reddy | C6: 0.5 | D6: 300000 | E6: =D47 -> 28947 | F6: =D6-E6 -> 271053 | G6: 50% — Managing Partner
B7: Kashigoud Patil | C7: 0.3 | D7: 180000 | E7: =D34 -> 140695 | F7: =D7-E7 -> 39305 | G7: 30% — Partner
B8: Shashirekha Basavaraju | C8: 0.2 | D8: 120000 | E8: =D59 -> 100000 | F8: =D8-E8 -> 20000 | G8: 20% — Partner
B9: TOTAL | C9: =SUM(C6:C8) -> 1 | D9: =SUM(D6:D8) -> 600000 | E9: =SUM(E6:E8) -> 269642 | F9: =SUM(F6:F8) -> 330358
B11: B. RESTAURANT ACQUISITION — $390,000 TOTAL
B12: Description | C12: Date | D12: Amount ($) | E12: Paid By | F12: Status | G12: Notes
B13: TOTAL Purchase Price — Previous Owners | D13: 390000 | E13: All Partners | F13: ⚠️ NOT YET FULLY PAID | G13: Full acquisition amount
B14: Advance Payment (paid by Lohith) | D14: 5000 | E14: Lohith Reddy | F14: ✅ PAID | G14: Advance to previous owners
B15: Balance Remaining | D15: =D13-D14 -> 385000 | E15: — | F15: ⏳ PENDING | G15: Funded by partner transfers
B17: PAYMENT BREAKDOWN — How the $390,000 will be funded
B18: Source | C18: From | D18: Amount ($) | E18: Toward % | F18: Cumulative | G18: Notes
B19: Kashigoud Transfer to Lohith | C19: Kashigoud Patil | D19: 125000 | E19: =D19/390000 -> 0.32051282 | F19: =D19 -> 125000 | G19: Full Kashi transfer
B20: Shashirekha Transfer to Lohith | C20: Shashirekha B. | D20: 100000 | E20: =D20/390000 -> 0.25641026 | F20: =D19+D20 -> 225000 | G20: Full Shashi transfer
B21: Lohith Reddy (own funds) | C21: Lohith Reddy | D21: =390000-D19-D20 -> 165000 | E21: =D21/390000 -> 0.42307692 | F21: =D20+D21 -> 265000 | G21: Balance from Lohith
B22: Advance Already Paid | C22: Lohith Reddy | D22: 5000 | E22: =D22/390000 -> 0.012820513 | F22: Paid ✅ | G22: Already paid
B24: C. PRE-OPENING EXPENSES — KASHIGOUD PATIL
B25: Description | C25: Date | D25: Amount ($) | E25: Paid To | F25: Category | G25: Notes
B26: Transfer to Lohith Reddy (capital allocation) | D26: 125000 | E26: Bank → Lohith | F26: Internal Transfer | G26: For acquisition & expenses
B27: Soft Restaurant License & Tools | D27: 15195 | E27: Soft App | F27: Software / License | G27: POS + mgmt tools
B28: Mercado Pago Terminal | D28: 500 | E28: Mercado Pago | F28: Equipment | G28: Card payment terminal
B34: KASHIGOUD TOTAL | D34: =SUM(D26:D33) -> 140695
B36: D. PRE-OPENING EXPENSES — LOHITH REDDY
B37: Description | C37: Date | D37: Amount ($) | E37: Paid To | F37: Category | G37: Notes
B38: Advance Payment to Previous Owners | D38: 5000 | E38: Previous Owners | F38: Acquisition | G38: 5k advance on 390k purchase
B39: Notary Fees | D39: 15797 | E39: Notary Office | F39: Legal / Notary | G39: Notarization of purchase docs
B40: Poliza Juridica (Legal Policy) | D40: 5150 | E40: Legal Office | F40: Legal / Insurance | G40: Juridical property policy
B41: Alejandra — Documentation Asst. | D41: 3000 | E41: Alejandra | F41: Professional Services | G41: Paperwork & documentation
B47: LOHITH TOTAL | D47: =SUM(D38:D46) -> 28947
B49: E. PRE-OPENING EXPENSES — SHASHIREKHA BASAVARAJU
B50: Description | C50: Date | D50: Amount ($) | E50: Paid To | F50: Category | G50: Notes
B51: Transfer to Lohith Reddy (capital allocation) | D51: 100000 | E51: Bank → Lohith | F51: Internal Transfer | G51: For acquisition & expenses
B59: SHASHIREKHA TOTAL | D59: =SUM(D51:D58) -> 100000
B61: F. GRAND SUMMARY — CAPITAL DEPLOYMENT
B62: Line Item | C62: Amount ($) | D62: % of Budget | E62: Notes
B63: Total Budget (All Partners) | C63: =SUM(D6:D8) -> 600000 | D63: =C63/$C$63 -> 1 | E63: 100% of committed capital
B64: Restaurant Acquisition — Full Price | C64: =D13 -> 390000 | D64: =C64/$C$63 -> 0.65 | E64: To be paid to previous owners
...

Sheet 📊 Dashboard
A2: 🍽️ LOKA Cafe Restaurante | H2: Restaurant Manager — powered by Soft + Excel
B5: 📌 HOW TO USE: ① Each update, go to 📅 Daily Log → enter Date + Revenue + Orders from Soft App ② Fill 💸 Expenses for costs paid ③ Update 📦 Inventory when stock changes ④ This dashboard updates automatically
B7: 💰 REVENUE (auto-pulled from Daily Log)
B9: TODAY'S REVENUE | D9: WEEK REVENUE | F9: MONTH REVENUE | H9: TODAY'S EXPENSES | J9: TODAY'S NET PROFIT | L9: AVG TICKET
B10: ='📅 Daily Log'!E5 -> 0 | D10: ='📅 Daily Log'!N5 -> 0 | F10: ='📅 Daily Log'!O5 -> 0 | H10: ='💸 Expenses'!H5 -> TODAY TOTAL | J10: ='💸 Expenses'!H6 -> 0 | L10: ='📅 Daily Log'!G5 -> 0
B14: 📊 OPERATIONS
B16: TODAY'S ORDERS | D16: WEEK ORDERS | F16: PROFIT MARGIN % | H16: LOW STOCK ITEMS | J16: WEEK EXPENSES | L16: PENDING ORDERS
B17: ='📅 Daily Log'!F5 -> 0 | D17: ='📅 Daily Log'!P5 -> 0 | F17: =IFERROR(('📅 Daily Log'!E5-'💸 Expenses'!H5)/'📅 Daily Log'!E5,0) -> 0 | H17: ='📦 Inventory'!H5 -> ALERT COUNT | J17: ='💸 Expenses'!I5 -> WEEK TOTAL | L17: ='🚚 Suppliers'!H5 -> PENDING COUNT
B21: 📅 LAST 10 DAYS (from Daily Log — updates automatically)
B22: Date | C22: Day | D22: Revenue ($) | E22: Orders | F22: Avg Ticket | G22: Expenses ($) | H22: Net Profit ($) | I22: Margin % | J22: Notes | K22: vs Prev Day
B23: ='📅 Daily Log'!B8 -> 0 | C23: =IFERROR(TEXT('📅 Daily Log'!B8,"DDD"),"") -> Sat | D23: ='📅 Daily Log'!E8 -> 0 | E23: ='📅 Daily Log'!F8 -> 0 | F23: ='📅 Daily Log'!G8 -> 0 | G23: ='📅 Daily Log'!H8 -> 0 | H23: ='📅 Daily Log'!I8 -> 0 | I23: ='📅 Daily Log'!J8 -> 0 | J23: ='📅 Daily Log'!K8 -> 0 | K23: —
B24: ='📅 Daily Log'!B9 -> 0 | C24: =IFERROR(TEXT('📅 Daily Log'!B9,"DDD"),"") -> Sat | D24: ='📅 Daily Log'!E9 -> 0 | E24: ='📅 Daily Log'!F9 -> 0 | F24: ='📅 Daily Log'!G9 -> 0 | G24: ='📅 Daily Log'!H9 -> 0 | H24: ='📅 Daily Log'!I9 -> 0 | I24: ='📅 Daily Log'!J9 -> 0 | J24: ='📅 Daily Log'!K9 -> 0 | K24: =IFERROR(IF(D24>D23,"▲ +"&TEXT(D24-D23,"$#,##0"),IF(D24<D23,"▼ "&TEXT(D24-D23,"$#,##0"),"— same")),"") -> — same
B25: ='📅 Daily Log'!B10 -> 0 | C25: =IFERROR(TEXT('📅 Daily Log'!B10,"DDD"),"") -> Sat | D25: ='📅 Daily Log'!E10 -> 0 | E25: ='📅 Daily Log'!F10 -> 0 | F25: ='📅 Daily Log'!G10 -> 0 | G25: ='📅 Daily Log'!H10 -> 0 | H25: ='📅 Daily Log'!I10 -> 0 | I25: ='📅 Daily Log'!J10 -> 0 | J25: ='📅 Daily Log'!K10 -> 0 | K25: =IFERROR(IF(D25>D24,"▲ +"&TEXT(D25-D24,"$#,##0"),IF(D25<D24,"▼ "&TEXT(D25-D24,"$#,##0"),"— same")),"") -> — same
B26: ='📅 Daily Log'!B11 -> 0 | C26: =IFERROR(TEXT('📅 Daily Log'!B11,"DDD"),"") -> Sat | D26: ='📅 Daily Log'!E11 -> 0 | E26: ='📅 Daily Log'!F11 -> 0 | F26: ='📅 Daily Log'!G11 -> 0 | G26: ='📅 Daily Log'!H11 -> 0 | H26: ='📅 Daily Log'!I11 -> 0 | I26: ='📅 Daily Log'!J11 -> 0 | J26: ='📅 Daily Log'!K11 -> 0 | K26: =IFERROR(IF(D26>D25,"▲ +"&TEXT(D26-D25,"$#,##0"),IF(D26<D25,"▼ "&TEXT(D26-D25,"$#,##0"),"— same")),"") -> — same
B27: ='📅 Daily Log'!B12 -> 0 | C27: =IFERROR(TEXT('📅 Daily Log'!B12,"DDD"),"") -> Sat | D27: ='📅 Daily Log'!E12 -> 0 | E27: ='📅 Daily Log'!F12 -> 0 | F27: ='📅 Daily Log'!G12 -> 0 | G27: ='📅 Daily Log'!H12 -> 0 | H27: ='📅 Daily Log'!I12 -> 0 | I27: ='📅 Daily Log'!J12 -> 0 | J27: ='📅 Daily Log'!K12 -> 0 | K27: =IFERROR(IF(D27>D26,"▲ +"&TEXT(D27-D26,"$#,##0"),IF(D27<D26,"▼ "&TEXT(D27-D26,"$#,##0"),"— same")),"") -> — same
B28: ='📅 Daily Log'!B13 -> 0 | C28: =IFERROR(TEXT('📅 Daily Log'!B13,"DDD"),"") -> Sat | D28: ='📅 Daily Log'!E13 -> 0 | E28: ='📅 Daily Log'!F13 -> 0 | F28: ='📅 Daily Log'!G13 -> 0 | G28: ='📅 Daily Log'!H13 -> 0 | H28: ='📅 Daily Log'!I13 -> 0 | I28: ='📅 Daily Log'!J13 -> 0 | J28: ='📅 Daily Log'!K13 -> 0 | K28: =IFERROR(IF(D28>D27,"▲ +"&TEXT(D28-D27,"$#,##0"),IF(D28<D27,"▼ "&TEXT(D28-D27,"$#,##0"),"— same")),"") -> — same
B29: ='📅 Daily Log'!B14 -> 0 | C29: =IFERROR(TEXT('📅 Daily Log'!B14,"DDD"),"") -> Sat | D29: ='📅 Daily Log'!E14 -> 0 | E29: ='📅 Daily Log'!F14 -> 0 | F29: ='📅 Daily Log'!G14 -> 0 | G29: ='📅 Daily Log'!H14 -> 0 | H29: ='📅 Daily Log'!I14 -> 0 | I29: ='📅 Daily Log'!J14 -> 0 | J29: ='📅 Daily Log'!K14 -> 0 | K29: =IFERROR(IF(D29>D28,"▲ +"&TEXT(D29-D28,"$#,##0"),IF(D29<D28,"▼ "&TEXT(D29-D28,"$#,##0"),"— same")),"") -> — same
B30: ='📅 Daily Log'!B15 -> 0 | C30: =IFERROR(TEXT('📅 Daily Log'!B15,"DDD"),"") -> Sat | D30: ='📅 Daily Log'!E15 -> 0 | E30: ='📅 Daily Log'!F15 -> 0 | F30: ='📅 Daily Log'!G15 -> 0 | G30: ='📅 Daily Log'!H15 -> 0 | H30: ='📅 Daily Log'!I15 -> 0 | I30: ='📅 Daily Log'!J15 -> 0 | J30: ='📅 Daily Log'!K15 -> 0 | K30: =IFERROR(IF(D30>D29,"▲ +"&TEXT(D30-D29,"$#,##0"),IF(D30<D29,"▼ "&TEXT(D30-D29,"$#,##0"),"— same")),"") -> — same
B31: ='📅 Daily Log'!B16 -> 0 | C31: =IFERROR(TEXT('📅 Daily Log'!B16,"DDD"),"") -> Sat | D31: ='📅 Daily Log'!E16 -> 0 | E31: ='📅 Daily Log'!F16 -> 0 | F31: ='📅 Daily Log'!G16 -> 0 | G31: ='📅 Daily Log'!H16 -> 0 | H31: ='📅 Daily Log'!I16 -> 0 | I31: ='📅 Daily Log'!J16 -> 0 | J31: ='📅 Daily Log'!K16 -> 0 | K31: =IFERROR(IF(D31>D30,"▲ +"&TEXT(D31-D30,"$#,##0"),IF(D31<D30,"▼ "&TEXT(D31-D30,"$#,##0"),"— same")),"") -> — same
B32: ='📅 Daily Log'!B17 -> 0 | C32: =IFERROR(TEXT('📅 Daily Log'!B17,"DDD"),"") -> Sat | D32: ='📅 Daily Log'!E17 -> 0 | E32: ='📅 Daily Log'!F17 -> 0 | F32: ='📅 Daily Log'!G17 -> 0 | G32: ='📅 Daily Log'!H17 -> 0 | H32: ='📅 Daily Log'!I17 -> 0 | I32: ='📅 Daily Log'!J17 -> 0 | J32: ='📅 Daily Log'!K17 -> 0 | K32: =IFERROR(IF(D32>D31,"▲ +"&TEXT(D32-D31,"$#,##0"),IF(D32<D31,"▼ "&TEXT(D32-D31,"$#,##0"),"— same")),"") -> — same
B34: ⚠️ INVENTORY ALERTS (from Inventory sheet)
B35: Ingredient | F35: Min Level | H35: Status | J35: Action Needed
B36: ='📦 Inventory'!B9 -> Ingredient | E36: ='📦 Inventory'!E9 -> Current Stock | G36: ='📦 Inventory'!F9 -> Min Level | I36: ='📦 Inventory'!J9 -> Status | K36: =IF('📦 Inventory'!E9=0,"🚫 Order immediately",IF('📦 Inventory'!E9<='📦 Inventory'!F9,"⚠️ Reorder soon","✅ OK")) -> ⚠️ Reorder soon
B37: ='📦 Inventory'!B10 -> Tortillas Blanco | E37: ='📦 Inventory'!E10 -> 200 | G37: ='📦 Inventory'!F10 -> 100 | I37: ='📦 Inventory'!J10 -> ✅ OK | K37: =IF('📦 Inventory'!E10=0,"🚫 Order immediately",IF('📦 Inventory'!E10<='📦 Inventory'!F10,"⚠️ Reorder soon","✅ OK")) -> ✅ OK
B38: ='📦 Inventory'!B11 -> Tortillas de Trigo | E38: ='📦 Inventory'!E11 -> 100 | G38: ='📦 Inventory'!F11 -> 50 | I38: ='📦 Inventory'!J11 -> ✅ OK | K38: =IF('📦 Inventory'!E11=0,"🚫 Order immediately",IF('📦 Inventory'!E11<='📦 Inventory'!F11,"⚠️ Reorder soon","✅ OK")) -> ✅ OK
B39: ='📦 Inventory'!B12 -> Pan Artesanal Masa Madre | E39: ='📦 Inventory'!E12 -> 30 | G39: ='📦 Inventory'!F12 -> 15 | I39: ='📦 Inventory'!J12 -> ✅ OK | K39: =IF('📦 Inventory'!E12=0,"🚫 Order immediately",IF('📦 Inventory'!E12<='📦 Inventory'!F12,"⚠️ Reorder soon","✅ OK")) -> ✅ OK
B40: ='📦 Inventory'!B13 -> Pan Suave Hamburguesa | E40: ='📦 Inventory'!E13 -> 40 | G40: ='📦 Inventory'!F13 -> 20 | I40: ='📦 Inventory'!J13 -> ✅ OK | K40: =IF('📦 Inventory'!E13=0,"🚫 Order immediately",IF('📦 Inventory'!E13<='📦 Inventory'!F13,"⚠️ Reorder soon","✅ OK")) -> ✅ OK
B42: 💼 CAPITAL & ACQUISITION STATUS — live from Capital & Ownership sheet
B44: TOTAL BUDGET | D44: TOTAL CASH OUT | F44: REMAINING BUDGET | H44: ACQUISITION PRICE | J44: ADVANCE PAID | L44: BALANCE PENDING
B45: ='Capital & Ownership'!C63 -> 600000 | D45: ='Capital & Ownership'!C72 -> 434642 | F45: ='Capital & Ownership'!C73 -> 165358 | H45: ='Capital & Ownership'!C64 -> 390000 | J45: ='Capital & Ownership'!C65 -> 5000 | L45: ='Capital & Ownership'!C66 -> 385000
B46: All 3 partners | D46: Excl. internal transfers | F46: Available for operations | H46: To previous owners | J46: ✅ Paid by Lohith | L46: ⏳ Outstanding
B48: 👥 OWNER CAPITAL SUMMARY
B49: OWNER | D49: SHARE % | F49: CAPITAL ($) | G49: ROLE | H49: EXPENSES ($) | J49: REMAINING ($) | L49: % SPENT
B50: ='Capital & Ownership'!B6 -> Lohith Reddy | D50: ='Capital & Ownership'!C6 -> 0.5 | F50: ='Capital & Ownership'!D6 -> 300000 | G50: 50% — Managing Partner | H50: ='Capital & Ownership'!E6 -> 28947 | J50: ='Capital & Ownership'!F6 -> 271053 | L50: =IFERROR('Capital & Ownership'!E6/'Capital & Ownership'!D6,0) -> 0.09649
B51: ='Capital & Ownership'!B7 -> Kashigoud Patil | D51: ='Capital & Ownership'!C7 -> 0.3 | F51: ='Capital & Ownership'!D7 -> 180000 | G51: 30% — Partner | H51: ='Capital & Ownership'!E7 -> 140695 | J51: ='Capital & Ownership'!F7 -> 39305 | L51: =IFERROR('Capital & Ownership'!E7/'Capital & Ownership'!D7,0) -> 0.78163889
B52: ='Capital & Ownership'!B8 -> Shashirekha Basavaraju | D52: ='Capital & Ownership'!C8 -> 0.2 | F52: ='Capital & Ownership'!D8 -> 120000 | G52: 20% — Partner | H52: ='Capital & Ownership'!E8 -> 100000 | J52: ='Capital & Ownership'!F8 -> 20000 | L52: =IFERROR('Capital & Ownership'!E8/'Capital & Ownership'!D8,0) -> 0.83333333
B53: TOTAL | D53: ='Capital & Ownership'!C9 -> 1 | F53: ='Capital & Ownership'!D9 -> 600000 | H53: ='Capital & Ownership'!E9 -> 269642 | J53: ='Capital & Ownership'!F9 -> 330358 | L53: =IFERROR('Capital & Ownership'!E9/'Capital & Ownership'!D9,0) -> 0.44940333
B55: 🧾 PRE-OPENING EXPENSES BREAKDOWN
B56: EXPENSE ITEM | E56: PAID BY | G56: AMOUNT ($) | I56: CATEGORY | K56: STATUS
B57: ='Capital & Ownership'!B13 -> TOTAL Purchase Price — Previous Owners | E57: All Partners | G57: ='Capital & Ownership'!D13 -> 390000 | I57: Acquisition | K57: ⚠️ Not Fully Paid
...

Sheet 📅 Daily Log
A2: 📅 LOKA — DAILY LOG | I2: Enter 2 values from Soft App each day → everything else calculates
B5: ✏️ INSTRUCTIONS: Each time you open this file, add a new row below. Fill only the BLUE cells: 📌 Date | 💰 Revenue (from Soft App end-of-day report) | 🛒 Orders (from Soft App) | 📝 Notes (optional). All other columns calculate automatically.
B6: =IF(B8<>"",TEXT(B8,"DD/MM DDD"),"—") -> — | D6: =IFERROR(E8,0) -> 0 | E6: =IFERROR(F8,0) -> 0 | F6: =IFERROR(G8,0) -> 0 | G6: =IFERROR(H8,0) -> 0 | H6: =IFERROR(I8,0) -> 0 | I6: =IFERROR(J8,0) -> 0 | K6: =IFERROR(N8,0) -> 0 | L6: =IFERROR(P8,0) -> 0 | M6: =IFERROR(Q8,0) -> 0 | N6: =IFERROR(L8,0) -> 0 | O6: =IFERROR(O8,0) -> 0
B7: Date | C7: Day | D7: Source | E7: Revenue $ ← Soft | F7: Orders ← Soft | G7: Avg Ticket | H7: Expenses $ | I7: Net Profit $ | J7: Margin % | K7: WEEK REVENUE | L7: WEEK EXPENSES | M7: WEEK PROFIT | N7: CUMUL. REVENUE | O7: MONTH REVENUE | P7: Week Expenses | Q7: Week Profit
C8: =IF(B8="","",TEXT(B8,"DDD")) | D8: =IF(B8="","","Soft App") | G8: =IFERROR(E8/F8,0) -> 0 | H8: =IFERROR(SUMIF('💸 Expenses'!B9:B508,B8,'💸 Expenses'!F9:F508),0) -> 0 | I8: =IFERROR(E8-H8,0) -> 0 | J8: =IFERROR(I8/E8,0) -> 0 | L8: =E8 -> 0 | M8: =H8 -> 0 | N8: =IFERROR(L8-M8,0) -> 0 | O8: =IFERROR(SUMIF(B8:B8,">="&(B8-WEEKDAY(B8,2)+1),E8:E8),0) -> 0 | P8: =IFERROR(SUMIF(B8:B8,">="&(B8-WEEKDAY(B8,2)+1),H8:H8),0) -> 0 | Q8: =IFERROR(O8-P8,0) -> 0
C9: =IF(B9="","",TEXT(B9,"DDD")) | D9: =IF(B9="","","Soft App") | G9: =IFERROR(E9/F9,0) -> 0 | H9: =IFERROR(SUMIF('💸 Expenses'!B9:B508,B9,'💸 Expenses'!F9:F508),0) -> 0 | I9: =IFERROR(E9-H9,0) -> 0 | J9: =IFERROR(I9/E9,0) -> 0 | L9: =IFERROR(L8+E9,0) -> 0 | M9: =IFERROR(M8+H9,0) -> 0 | N9: =IFERROR(L9-M9,0) -> 0 | O9: =IFERROR(SUMIF(B8:B9,">="&(B9-WEEKDAY(B9,2)+1),E8:E9),0) -> 0 | P9: =IFERROR(SUMIF(B8:B9,">="&(B9-WEEKDAY(B9,2)+1),H8:H9),0) -> 0 | Q9: =IFERROR(O9-P9,0) -> 0
C10: =IF(B10="","",TEXT(B10,"DDD")) | D10: =IF(B10="","","Soft App") | G10: =IFERROR(E10/F10,0) -> 0 | H10: =IFERROR(SUMIF('💸 Expenses'!B9:B508,B10,'💸 Expenses'!F9:F508),0) -> 0 | I10: =IFERROR(E10-H10,0) -> 0 | J10: =IFERROR(I10/E10,0) -> 0 | L10: =IFERROR(L9+E10,0) -> 0 | M10: =IFERROR(M9+H10,0) -> 0 | N10: =IFERROR(L10-M10,0) -> 0 | O10: =IFERROR(SUMIF(B8:B10,">="&(B10-WEEKDAY(B10,2)+1),E8:E10),0) -> 0 | P10: =IFERROR(SUMIF(B8:B10,">="&(B10-WEEKDAY(B10,2)+1),H8:H10),0) -> 0 | Q10: =IFERROR(O10-P10,0) -> 0
C11: =IF(B11="","",TEXT(B11,"DDD")) | D11: =IF(B11="","","Soft App") | G11: =IFERROR(E11/F11,0) -> 0 | H11: =IFERROR(SUMIF('💸 Expenses'!B9:B508,B11,'💸 Expenses'!F9:F508),0) -> 0 | I11: =IFERROR(E11-H11,0) -> 0 | J11: =IFERROR(I11/E11,0) -> 0 | L11: =IFERROR(L10+E11,0) -> 0 | M11: =IFERROR(M10+H11,0) -> 0 | N11: =IFERROR(L11-M11,0) -> 0 | O11: =IFERROR(SUMIF(B8:B11,">="&(B11-WEEKDAY(B11,2)+1),E8:E11),0) -> 0 | P11: =IFERROR(SUMIF(B8:B11,">="&(B11-WEEKDAY(B11,2)+1),H8:H11),0) -> 0 | Q11: =IFERROR(O11-P11,0) -> 0
C12: =IF(B12="","",TEXT(B12,"DDD")) | D12: =IF(B12="","","Soft App") | G12: =IFERROR(E12/F12,0) -> 0 | H12: =IFERROR(SUMIF('💸 Expenses'!B9:B508,B12,'💸 Expenses'!F9:F508),0) -> 0 | I12: =IFERROR(E12-H12,0) -> 0 | J12: =IFERROR(I12/E12,0) -> 0 | L12: =IFERROR(L11+E12,0) -> 0 | M12: =IFERROR(M11+H12,0) -> 0 | N12: =IFERROR(L12-M12,0) -> 0 | O12: =IFERROR(SUMIF(B8:B12,">="&(B12-WEEKDAY(B12,2)+1),E8:E12),0) -> 0 | P12: =IFERROR(SUMIF(B8:B12,">="&(B12-WEEKDAY(B12,2)+1),H8:H12),0) -> 0 | Q12: =IFERROR(O12-P12,0) -> 0
C13: =IF(B13="","",TEXT(B13,"DDD")) | D13: =IF(B13="","","Soft App") | G13: =IFERROR(E13/F13,0) -> 0 | H13: =IFERROR(SUMIF('💸 Expenses'!B9:B508,B13,'💸 Expenses'!F9:F508),0) -> 0 | I13: =IFERROR(E13-H13,0) -> 0 | J13: =IFERROR(I13/E13,0) -> 0 | L13: =IFERROR(L12+E13,0) -> 0 | M13: =IFERROR(M12+H13,0) -> 0 | N13: =IFERROR(L13-M13,0) -> 0 | O13: =IFERROR(SUMIF(B8:B13,">="&(B13-WEEKDAY(B13,2)+1),E8:E13),0) -> 0 | P13: =IFERROR(SUMIF(B8:B13,">="&(B13-WEEKDAY(B13,2)+1),H8:H13),0) -> 0 | Q13: =IFERROR(O13-P13,0) -> 0
C14: =IF(B14="","",TEXT(B14,"DDD")) | D14: =IF(B14="","","Soft App") | G14: =IFERROR(E14/F14,0) -> 0 | H14: =IFERROR(SUMIF('💸 Expenses'!B9:B508,B14,'💸 Expenses'!F9:F508),0) -> 0 | I14: =IFERROR(E14-H14,0) -> 0 | J14: =IFERROR(I14/E14,0) -> 0 | L14: =IFERROR(L13+E14,0) -> 0 | M14: =IFERROR(M13+H14,0) -> 0 | N14: =IFERROR(L14-M14,0) -> 0 | O14: =IFERROR(SUMIF(B8:B14,">="&(B14-WEEKDAY(B14,2)+1),E8:E14),0) -> 0 | P14: =IFERROR(SUMIF(B8:B14,">="&(B14-WEEKDAY(B14,2)+1),H8:H14),0) -> 0 | Q14: =IFERROR(O14-P14,0) -> 0
C15: =IF(B15="","",TEXT(B15,"DDD")) | D15: =IF(B15="","","Soft App") | G15: =IFERROR(E15/F15,0) -> 0 | H15: =IFERROR(SUMIF('💸 Expenses'!B9:B508,B15,'💸 Expenses'!F9:F508),0) -> 0 | I15: =IFERROR(E15-H15,0) -> 0 | J15: =IFERROR(I15/E15,0) -> 0 | L15: =IFERROR(L14+E15,0) -> 0 | M15: =IFERROR(M14+H15,0) -> 0 | N15: =IFERROR(L15-M15,0) -> 0 | O15: =IFERROR(SUMIF(B8:B15,">="&(B15-WEEKDAY(B15,2)+1),E8:E15),0) -> 0 | P15: =IFERROR(SUMIF(B8:B15,">="&(B15-WEEKDAY(B15,2)+1),H8:H15),0) -> 0 | Q15: =IFERROR(O15-P15,0) -> 0
C16: =IF(B16="","",TEXT(B16,"DDD")) | D16: =IF(B16="","","Soft App") | G16: =IFERROR(E16/F16,0) -> 0 | H16: =IFERROR(SUMIF('💸 Expenses'!B9:B508,B16,'💸 Expenses'!F9:F508),0) -> 0 | I16: =IFERROR(E16-H16,0) -> 0 | J16: =IFERROR(I16/E16,0) -> 0 | L16: =IFERROR(L15+E16,0) -> 0 | M16: =IFERROR(M15+H16,0) -> 0 | N16: =IFERROR(L16-M16,0) -> 0 | O16: =IFERROR(SUMIF(B8:B16,">="&(B16-WEEKDAY(B16,2)+1),E8:E16),0) -> 0 | P16: =IFERROR(SUMIF(B8:B16,">="&(B16-WEEKDAY(B16,2)+1),H8:H16),0) -> 0 | Q16: =IFERROR(O16-P16,0) -> 0
C17: =IF(B17="","",TEXT(B17,"DDD")) | D17: =IF(B17="","","Soft App") | G17: =IFERROR(E17/F17,0) -> 0 | H17: =IFERROR(SUMIF('💸 Expenses'!B9:B508,B17,'💸 Expenses'!F9:F508),0) -> 0 | I17: =IFERROR(E17-H17,0) -> 0 | J17: =IFERROR(I17/E17,0) -> 0 | L17: =IFERROR(L16+E17,0) -> 0 | M17: =IFERROR(M16+H17,0) -> 0 | N17: =IFERROR(L17-M17,0) -> 0 | O17: =IFERROR(SUMIF(B8:B17,">="&(B17-WEEKDAY(B17,2)+1),E8:E17),0) -> 0 | P17: =IFERROR(SUMIF(B8:B17,">="&(B17-WEEKDAY(B17,2)+1),H8:H17),0) -> 0 | Q17: =IFERROR(O17-P17,0) -> 0
C18: =IF(B18="","",TEXT(B18,"DDD")) | D18: =IF(B18="","","Soft App") | G18: =IFERROR(E18/F18,0) -> 0 | H18: =IFERROR(SUMIF('💸 Expenses'!B9:B508,B18,'💸 Expenses'!F9:F508),0) -> 0 | I18: =IFERROR(E18-H18,0) -> 0 | J18: =IFERROR(I18/E18,0) -> 0 | L18: =IFERROR(L17+E18,0) -> 0 | M18: =IFERROR(M17+H18,0) -> 0 | N18: =IFERROR(L18-M18,0) -> 0 | O18: =IFERROR(SUMIF(B8:B18,">="&(B18-WEEKDAY(B18,2)+1),E8:E18),0) -> 0 | P18: =IFERROR(SUMIF(B8:B18,">="&(B18-WEEKDAY(B18,2)+1),H8:H18),0) -> 0 | Q18: =IFERROR(O18-P18,0) -> 0
C19: =IF(B19="","",TEXT(B19,"DDD")) | D19: =IF(B19="","","Soft App") | G19: =IFERROR(E19/F19,0) -> 0 | H19: =IFERROR(SUMIF('💸 Expenses'!B9:B508,B19,'💸 Expenses'!F9:F508),0) -> 0 | I19: =IFERROR(E19-H19,0) -> 0 | J19: =IFERROR(I19/E19,0) -> 0 | L19: =IFERROR(L18+E19,0) -> 0 | M19: =IFERROR(M18+H19,0) -> 0 | N19: =IFERROR(L19-M19,0) -> 0 | O19: =IFERROR(SUMIF(B8:B19,">="&(B19-WEEKDAY(B19,2)+1),E8:E19),0) -> 0 | P19: =IFERROR(SUMIF(B8:B19,">="&(B19-WEEKDAY(B19,2)+1),H8:H19),0) -> 0 | Q19: =IFERROR(O19-P19,0) -> 0
C20: =IF(B20="","",TEXT(B20,"DDD")) | D20: =IF(B20="","","Soft App") | G20: =IFERROR(E20/F20,0) -> 0 | H20: =IFERROR(SUMIF('💸 Expenses'!B9:B508,B20,'💸 Expenses'!F9:F508),0) -> 0 | I20: =IFERROR(E20-H20,0) -> 0 | J20: =IFERROR(I20/E20,0) -> 0 | L20: =IFERROR(L19+E20,0) -> 0 | M20: =IFERROR(M19+H20,0) -> 0 | N20: =IFERROR(L20-M20,0) -> 0 | O20: =IFERROR(SUMIF(B8:B20,">="&(B20-WEEKDAY(B20,2)+1),E8:E20),0) -> 0 | P20: =IFERROR(SUMIF(B8:B20,">="&(B20-WEEKDAY(B20,2)+1),H8:H20),0) -> 0 | Q20: =IFERROR(O20-P20,0) -> 0
C21: =IF(B21="","",TEXT(B21,"DDD")) | D21: =IF(B21="","","Soft App") | G21: =IFERROR(E21/F21,0) -> 0 | H21: =IFERROR(SUMIF('💸 Expenses'!B9:B508,B21,'💸 Expenses'!F9:F508),0) -> 0 | I21: =IFERROR(E21-H21,0) -> 0 | J21: =IFERROR(I21/E21,0) -> 0 | L21: =IFERROR(L20+E21,0) -> 0 | M21: =IFERROR(M20+H21,0) -> 0 | N21: =IFERROR(L21-M21,0) -> 0 | O21: =IFERROR(SUMIF(B8:B21,">="&(B21-WEEKDAY(B21,2)+1),E8:E21),0) -> 0 | P21: =IFERROR(SUMIF(B8:B21,">="&(B21-WEEKDAY(B21,2)+1),H8:H21),0) -> 0 | Q21: =IFERROR(O21-P21,0) -> 0
C22: =IF(B22="","",TEXT(B22,"DDD")) | D22: =IF(B22="","","Soft App") | G22: =IFERROR(E22/F22,0) -> 0 | H22: =IFERROR(SUMIF('💸 Expenses'!B9:B508,B22,'💸 Expenses'!F9:F508),0) -> 0 | I22: =IFERROR(E22-H22,0) -> 0 | J22: =IFERROR(I22/E22,0) -> 0 | L22: =IFERROR(L21+E22,0) -> 0 | M22: =IFERROR(M21+H22,0) -> 0 | N22: =IFERROR(L22-M22,0) -> 0 | O22: =IFERROR(SUMIF(B8:B22,">="&(B22-WEEKDAY(B22,2)+1),E8:E22),0) -> 0 | P22: =IFERROR(SUMIF(B8:B22,">="&(B22-WEEKDAY(B22,2)+1),H8:H22),0) -> 0 | Q22: =IFERROR(O22-P22,0) -> 0
C23: =IF(B23="","",TEXT(B23,"DDD")) | D23: =IF(B23="","","Soft App") | G23: =IFERROR(E23/F23,0) -> 0 | H23: =IFERROR(SUMIF('💸 Expenses'!B9:B508,B23,'💸 Expenses'!F9:F508),0) -> 0 | I23: =IFERROR(E23-H23,0) -> 0 | J23: =IFERROR(I23/E23,0) -> 0 | L23: =IFERROR(L22+E23,0) -> 0 | M23: =IFERROR(M22+H23,0) -> 0 | N23: =IFERROR(L23-M23,0) -> 0 | O23: =IFERROR(SUMIF(B8:B23,">="&(B23-WEEKDAY(B23,2)+1),E8:E23),0) -> 0 | P23: =IFERROR(SUMIF(B8:B23,">="&(B23-WEEKDAY(B23,2)+1),H8:H23),0) -> 0 | Q23: =IFERROR(O23-P23,0) -> 0
C24: =IF(B24="","",TEXT(B24,"DDD")) | D24: =IF(B24="","","Soft App") | G24: =IFERROR(E24/F24,0) -> 0 | H24: =IFERROR(SUMIF('💸 Expenses'!B9:B508,B24,'💸 Expenses'!F9:F508),0) -> 0 | I24: =IFERROR(E24-H24,0) -> 0 | J24: =IFERROR(I24/E24,0) -> 0 | L24: =IFERROR(L23+E24,0) -> 0 | M24: =IFERROR(M23+H24,0) -> 0 | N24: =IFERROR(L24-M24,0) -> 0 | O24: =IFERROR(SUMIF(B8:B24,">="&(B24-WEEKDAY(B24,2)+1),E8:E24),0) -> 0 | P24: =IFERROR(SUMIF(B8:B24,">="&(B24-WEEKDAY(B24,2)+1),H8:H24),0) -> 0 | Q24: =IFERROR(O24-P24,0) -> 0
C25: =IF(B25="","",TEXT(B25,"DDD")) | D25: =IF(B25="","","Soft App") | G25: =IFERROR(E25/F25,0) -> 0 | H25: =IFERROR(SUMIF('💸 Expenses'!B9:B508,B25,'💸 Expenses'!F9:F508),0) -> 0 | I25: =IFERROR(E25-H25,0) -> 0 | J25: =IFERROR(I25/E25,0) -> 0 | L25: =IFERROR(L24+E25,0) -> 0 | M25: =IFERROR(M24+H25,0) -> 0 | N25: =IFERROR(L25-M25,0) -> 0 | O25: =IFERROR(SUMIF(B8:B25,">="&(B25-WEEKDAY(B25,2)+1),E8:E25),0) -> 0 | P25: =IFERROR(SUMIF(B8:B25,">="&(B25-WEEKDAY(B25,2)+1),H8:H25),0) -> 0 | Q25: =IFERROR(O25-P25,0) -> 0
C26: =IF(B26="","",TEXT(B26,"DDD")) | D26: =IF(B26="","","Soft App") | G26: =IFERROR(E26/F26,0) -> 0 | H26: =IFERROR(SUMIF('💸 Expenses'!B9:B508,B26,'💸 Expenses'!F9:F508),0) -> 0 | I26: =IFERROR(E26-H26,0) -> 0 | J26: =IFERROR(I26/E26,0) -> 0 | L26: =IFERROR(L25+E26,0) -> 0 | M26: =IFERROR(M25+H26,0) -> 0 | N26: =IFERROR(L26-M26,0) -> 0 | O26: =IFERROR(SUMIF(B8:B26,">="&(B26-WEEKDAY(B26,2)+1),E8:E26),0) -> 0 | P26: =IFERROR(SUMIF(B8:B26,">="&(B26-WEEKDAY(B26,2)+1),H8:H26),0) -> 0 | Q26: =IFERROR(O26-P26,0) -> 0
C27: =IF(B27="","",TEXT(B27,"DDD")) | D27: =IF(B27="","","Soft App") | G27: =IFERROR(E27/F27,0) -> 0 | H27: =IFERROR(SUMIF('💸 Expenses'!B9:B508,B27,'💸 Expenses'!F9:F508),0) -> 0 | I27: =IFERROR(E27-H27,0) -> 0 | J27: =IFERROR(I27/E27,0) -> 0 | L27: =IFERROR(L26+E27,0) -> 0 | M27: =IFERROR(M26+H27,0) -> 0 | N27: =IFERROR(L27-M27,0) -> 0 | O27: =IFERROR(SUMIF(B8:B27,">="&(B27-WEEKDAY(B27,2)+1),E8:E27),0) -> 0 | P27: =IFERROR(SUMIF(B8:B27,">="&(B27-WEEKDAY(B27,2)+1),H8:H27),0) -> 0 | Q27: =IFERROR(O27-P27,0) -> 0
C28: =IF(B28="","",TEXT(B28,"DDD")) | D28: =IF(B28="","","Soft App") | G28: =IFERROR(E28/F28,0) -> 0 | H28: =IFERROR(SUMIF('💸 Expenses'!B9:B508,B28,'💸 Expenses'!F9:F508),0) -> 0 | I28: =IFERROR(E28-H28,0) -> 0 | J28: =IFERROR(I28/E28,0) -> 0 | L28: =IFERROR(L27+E28,0) -> 0 | M28: =IFERROR(M27+H28,0) -> 0 | N28: =IFERROR(L28-M28,0) -> 0 | O28: =IFERROR(SUMIF(B8:B28,">="&(B28-WEEKDAY(B28,2)+1),E8:E28),0) -> 0 | P28: =IFERROR(SUMIF(B8:B28,">="&(B28-WEEKDAY(B28,2)+1),H8:H28),0) -> 0 | Q28: =IFERROR(O28-P28,0) -> 0
C29: =IF(B29="","",TEXT(B29,"DDD")) | D29: =IF(B29="","","Soft App") | G29: =IFERROR(E29/F29,0) -> 0 | H29: =IFERROR(SUMIF('💸 Expenses'!B9:B508,B29,'💸 Expenses'!F9:F508),0) -> 0 | I29: =IFERROR(E29-H29,0) -> 0 | J29: =IFERROR(I29/E29,0) -> 0 | L29: =IFERROR(L28+E29,0) -> 0 | M29: =IFERROR(M28+H29,0) -> 0 | N29: =IFERROR(L29-M29,0) -> 0 | O29: =IFERROR(SUMIF(B8:B29,">="&(B29-WEEKDAY(B29,2)+1),E8:E29),0) -> 0 | P29: =IFERROR(SUMIF(B8:B29,">="&(B29-WEEKDAY(B29,2)+1),H8:H29),0) -> 0 | Q29: =IFERROR(O29-P29,0) -> 0
C30: =IF(B30="","",TEXT(B30,"DDD")) | D30: =IF(B30="","","Soft App") | G30: =IFERROR(E30/F30,0) -> 0 | H30: =IFERROR(SUMIF('💸 Expenses'!B9:B508,B30,'💸 Expenses'!F9:F508),0) -> 0 | I30: =IFERROR(E30-H30,0) -> 0 | J30: =IFERROR(I30/E30,0) -> 0 | L30: =IFERROR(L29+E30,0) -> 0 | M30: =IFERROR(M29+H30,0) -> 0 | N30: =IFERROR(L30-M30,0) -> 0 | O30: =IFERROR(SUMIF(B8:B30,">="&(B30-WEEKDAY(B30,2)+1),E8:E30),0) -> 0 | P30: =IFERROR(SUMIF(B8:B30,">="&(B30-WEEKDAY(B30,2)+1),H8:H30),0) -> 0 | Q30: =IFERROR(O30-P30,0) -> 0
C31: =IF(B31="","",TEXT(B31,"DDD")) | D31: =IF(B31="","","Soft App") | G31: =IFERROR(E31/F31,0) -> 0 | H31: =IFERROR(SUMIF('💸 Expenses'!B9:B508,B31,'💸 Expenses'!F9:F508),0) -> 0 | I31: =IFERROR(E31-H31,0) -> 0 | J31: =IFERROR(I31/E31,0) -> 0 | L31: =IFERROR(L30+E31,0) -> 0 | M31: =IFERROR(M30+H31,0) -> 0 | N31: =IFERROR(L31-M31,0) -> 0 | O31: =IFERROR(SUMIF(B8:B31,">="&(B31-WEEKDAY(B31,2)+1),E8:E31),0) -> 0 | P31: =IFERROR(SUMIF(B8:B31,">="&(B31-WEEKDAY(B31,2)+1),H8:H31),0) -> 0 | Q31: =IFERROR(O31-P31,0) -> 0
C32: =IF(B32="","",TEXT(B32,"DDD")) | D32: =IF(B32="","","Soft App") | G32: =IFERROR(E32/F32,0) -> 0 | H32: =IFERROR(SUMIF('💸 Expenses'!B9:B508,B32,'💸 Expenses'!F9:F508),0) -> 0 | I32: =IFERROR(E32-H32,0) -> 0 | J32: =IFERROR(I32/E32,0) -> 0 | L32: =IFERROR(L31+E32,0) -> 0 | M32: =IFERROR(M31+H32,0) -> 0 | N32: =IFERROR(L32-M32,0) -> 0 | O32: =IFERROR(SUMIF(B8:B32,">="&(B32-WEEKDAY(B32,2)+1),E8:E32),0) -> 0 | P32: =IFERROR(SUMIF(B8:B32,">="&(B32-WEEKDAY(B32,2)+1),H8:H32),0) -> 0 | Q32: =IFERROR(O32-P32,0) -> 0
C33: =IF(B33="","",TEXT(B33,"DDD")) | D33: =IF(B33="","","Soft App") | G33: =IFERROR(E33/F33,0) -> 0 | H33: =IFERROR(SUMIF('💸 Expenses'!B9:B508,B33,'💸 Expenses'!F9:F508),0) -> 0 | I33: =IFERROR(E33-H33,0) -> 0 | J33: =IFERROR(I33/E33,0) -> 0 | L33: =IFERROR(L32+E33,0) -> 0 | M33: =IFERROR(M32+H33,0) -> 0 | N33: =IFERROR(L33-M33,0) -> 0 | O33: =IFERROR(SUMIF(B8:B33,">="&(B33-WEEKDAY(B33,2)+1),E8:E33),0) -> 0 | P33: =IFERROR(SUMIF(B8:B33,">="&(B33-WEEKDAY(B33,2)+1),H8:H33),0) -> 0 | Q33: =IFERROR(O33-P33,0) -> 0
C34: =IF(B34="","",TEXT(B34,"DDD")) | D34: =IF(B34="","","Soft App") | G34: =IFERROR(E34/F34,0) -> 0 | H34: =IFERROR(SUMIF('💸 Expenses'!B9:B508,B34,'💸 Expenses'!F9:F508),0) -> 0 | I34: =IFERROR(E34-H34,0) -> 0 | J34: =IFERROR(I34/E34,0) -> 0 | L34: =IFERROR(L33+E34,0) -> 0 | M34: =IFERROR(M33+H34,0) -> 0 | N34: =IFERROR(L34-M34,0) -> 0 | O34: =IFERROR(SUMIF(B8:B34,">="&(B34-WEEKDAY(B34,2)+1),E8:E34),0) -> 0 | P34: =IFERROR(SUMIF(B8:B34,">="&(B34-WEEKDAY(B34,2)+1),H8:H34),0) -> 0 | Q34: =IFERROR(O34-P34,0) -> 0
C35: =IF(B35="","",TEXT(B35,"DDD")) | D35: =IF(B35="","","Soft App") | G35: =IFERROR(E35/F35,0) -> 0 | H35: =IFERROR(SUMIF('💸 Expenses'!B9:B508,B35,'💸 Expenses'!F9:F508),0) -> 0 | I35: =IFERROR(E35-H35,0) -> 0 | J35: =IFERROR(I35/E35,0) -> 0 | L35: =IFERROR(L34+E35,0) -> 0 | M35: =IFERROR(M34+H35,0) -> 0 | N35: =IFERROR(L35-M35,0) -> 0 | O35: =IFERROR(SUMIF(B8:B35,">="&(B35-WEEKDAY(B35,2)+1),E8:E35),0) -> 0 | P35: =IFERROR(SUMIF(B8:B35,">="&(B35-WEEKDAY(B35,2)+1),H8:H35),0) -> 0 | Q35: =IFERROR(O35-P35,0) -> 0
C36: =IF(B36="","",TEXT(B36,"DDD")) | D36: =IF(B36="","","Soft App") | G36: =IFERROR(E36/F36,0) -> 0 | H36: =IFERROR(SUMIF('💸 Expenses'!B9:B508,B36,'💸 Expenses'!F9:F508),0) -> 0 | I36: =IFERROR(E36-H36,0) -> 0 | J36: =IFERROR(I36/E36,0) -> 0 | L36: =IFERROR(L35+E36,0) -> 0 | M36: =IFERROR(M35+H36,0) -> 0 | N36: =IFERROR(L36-M36,0) -> 0 | O36: =IFERROR(SUMIF(B8:B36,">="&(B36-WEEKDAY(B36,2)+1),E8:E36),0) -> 0 | P36: =IFERROR(SUMIF(B8:B36,">="&(B36-WEEKDAY(B36,2)+1),H8:H36),0) -> 0 | Q36: =IFERROR(O36-P36,0) -> 0
C37: =IF(B37="","",TEXT(B37,"DDD")) | D37: =IF(B37="","","Soft App") | G37: =IFERROR(E37/F37,0) -> 0 | H37: =IFERROR(SUMIF('💸 Expenses'!B9:B508,B37,'💸 Expenses'!F9:F508),0) -> 0 | I37: =IFERROR(E37-H37,0) -> 0 | J37: =IFERROR(I37/E37,0) -> 0 | L37: =IFERROR(L36+E37,0) -> 0 | M37: =IFERROR(M36+H37,0) -> 0 | N37: =IFERROR(L37-M37,0) -> 0 | O37: =IFERROR(SUMIF(B8:B37,">="&(B37-WEEKDAY(B37,2)+1),E8:E37),0) -> 0 | P37: =IFERROR(SUMIF(B8:B37,">="&(B37-WEEKDAY(B37,2)+1),H8:H37),0) -> 0 | Q37: =IFERROR(O37-P37,0) -> 0
C38: =IF(B38="","",TEXT(B38,"DDD")) | D38: =IF(B38="","","Soft App") | G38: =IFERROR(E38/F38,0) -> 0 | H38: =IFERROR(SUMIF('💸 Expenses'!B9:B508,B38,'💸 Expenses'!F9:F508),0) -> 0 | I38: =IFERROR(E38-H38,0) -> 0 | J38: =IFERROR(I38/E38,0) -> 0 | L38: =IFERROR(L37+E38,0) -> 0 | M38: =IFERROR(M37+H38,0) -> 0 | N38: =IFERROR(L38-M38,0) -> 0 | O38: =IFERROR(SUMIF(B8:B38,">="&(B38-WEEKDAY(B38,2)+1),E8:E38),0) -> 0 | P38: =IFERROR(SUMIF(B8:B38,">="&(B38-WEEKDAY(B38,2)+1),H8:H38),0) -> 0 | Q38: =IFERROR(O38-P38,0) -> 0
C39: =IF(B39="","",TEXT(B39,"DDD")) | D39: =IF(B39="","","Soft App") | G39: =IFERROR(E39/F39,0) -> 0 | H39: =IFERROR(SUMIF('💸 Expenses'!B9:B508,B39,'💸 Expenses'!F9:F508),0) -> 0 | I39: =IFERROR(E39-H39,0) -> 0 | J39: =IFERROR(I39/E39,0) -> 0 | L39: =IFERROR(L38+E39,0) -> 0 | M39: =IFERROR(M38+H39,0) -> 0 | N39: =IFERROR(L39-M39,0) -> 0 | O39: =IFERROR(SUMIF(B8:B39,">="&(B39-WEEKDAY(B39,2)+1),E8:E39),0) -> 0 | P39: =IFERROR(SUMIF(B8:B39,">="&(B39-WEEKDAY(B39,2)+1),H8:H39),0) -> 0 | Q39: =IFERROR(O39-P39,0) -> 0
C40: =IF(B40="","",TEXT(B40,"DDD")) | D40: =IF(B40="","","Soft App") | G40: =IFERROR(E40/F40,0) -> 0 | H40: =IFERROR(SUMIF('💸 Expenses'!B9:B508,B40,'💸 Expenses'!F9:F508),0) -> 0 | I40: =IFERROR(E40-H40,0) -> 0 | J40: =IFERROR(I40/E40,0) -> 0 | L40: =IFERROR(L39+E40,0) -> 0 | M40: =IFERROR(M39+H40,0) -> 0 | N40: =IFERROR(L40-M40,0) -> 0 | O40: =IFERROR(SUMIF(B8:B40,">="&(B40-WEEKDAY(B40,2)+1),E8:E40),0) -> 0 | P40: =IFERROR(SUMIF(B8:B40,">="&(B40-WEEKDAY(B40,2)+1),H8:H40),0) -> 0 | Q40: =IFERROR(O40-P40,0) -> 0
C41: =IF(B41="","",TEXT(B41,"DDD")) | D41: =IF(B41="","","Soft App") | G41: =IFERROR(E41/F41,0) -> 0 | H41: =IFERROR(SUMIF('💸 Expenses'!B9:B508,B41,'💸 Expenses'!F9:F508),0) -> 0 | I41: =IFERROR(E41-H41,0) -> 0 | J41: =IFERROR(I41/E41,0) -> 0 | L41: =IFERROR(L40+E41,0) -> 0 | M41: =IFERROR(M40+H41,0) -> 0 | N41: =IFERROR(L41-M41,0) -> 0 | O41: =IFERROR(SUMIF(B8:B41,">="&(B41-WEEKDAY(B41,2)+1),E8:E41),0) -> 0 | P41: =IFERROR(SUMIF(B8:B41,">="&(B41-WEEKDAY(B41,2)+1),H8:H41),0) -> 0 | Q41: =IFERROR(O41-P41,0) -> 0
C42: =IF(B42="","",TEXT(B42,"DDD")) | D42: =IF(B42="","","Soft App") | G42: =IFERROR(E42/F42,0) -> 0 | H42: =IFERROR(SUMIF('💸 Expenses'!B9:B508,B42,'💸 Expenses'!F9:F508),0) -> 0 | I42: =IFERROR(E42-H42,0) -> 0 | J42: =IFERROR(I42/E42,0) -> 0 | L42: =IFERROR(L41+E42,0) -> 0 | M42: =IFERROR(M41+H42,0) -> 0 | N42: =IFERROR(L42-M42,0) -> 0 | O42: =IFERROR(SUMIF(B8:B42,">="&(B42-WEEKDAY(B42,2)+1),E8:E42),0) -> 0 | P42: =IFERROR(SUMIF(B8:B42,">="&(B42-WEEKDAY(B42,2)+1),H8:H42),0) -> 0 | Q42: =IFERROR(O42-P42,0) -> 0
C43: =IF(B43="","",TEXT(B43,"DDD")) | D43: =IF(B43="","","Soft App") | G43: =IFERROR(E43/F43,0) -> 0 | H43: =IFERROR(SUMIF('💸 Expenses'!B9:B508,B43,'💸 Expenses'!F9:F508),0) -> 0 | I43: =IFERROR(E43-H43,0) -> 0 | J43: =IFERROR(I43/E43,0) -> 0 | L43: =IFERROR(L42+E43,0) -> 0 | M43: =IFERROR(M42+H43,0) -> 0 | N43: =IFERROR(L43-M43,0) -> 0 | O43: =IFERROR(SUMIF(B8:B43,">="&(B43-WEEKDAY(B43,2)+1),E8:E43),0) -> 0 | P43: =IFERROR(SUMIF(B8:B43,">="&(B43-WEEKDAY(B43,2)+1),H8:H43),0) -> 0 | Q43: =IFERROR(O43-P43,0) -> 0
...

Sheet 💸 Expenses
A2: 💸 LOKA — EXPENSES TRACKER | E2: Log every cost: ingredients, staff, utilities, supplies…
B5: TODAY | C5: THIS WEEK | D5: THIS MONTH | E5: INGREDIENTS | F5: STAFF | G5: UTILITIES | H5: TODAY TOTAL | I5: WEEK TOTAL
B6: =SUMIF(B9:B508,TODAY(),F9:F508) -> 0 | C6: =SUMIF(B9:B508,">="&(TODAY()-WEEKDAY(TODAY(),2)+1),F9:F508) -> 10326.5 | D6: =SUMIFS(F9:F508,B9:B508,">="&DATE(YEAR(TODAY()),MONTH(TODAY()),1),B9:B508,"<="&TODAY()) -> 10326.5 | E6: =SUMIF(C9:C508,"Ingredients",F9:F508) -> 8291.5 | F6: =SUMIF(C9:C508,"Staff",F9:F508) -> 500 | G6: =SUMIF(C9:C508,"Utilities",F9:F508) -> 0 | H6: =SUMIF(B9:B508,TODAY(),F9:F508) -> 0 | I6: =SUMIF(B9:B508,">="&(TODAY()-WEEKDAY(TODAY(),2)+1),F9:F508) -> 10326.5
B8: 📌 Fill BLUE cells. Category dropdown provided. Date links to Daily Log automatically — expenses appear in Net Profit.
B9: Date | C9: Category | D9: Description / Item | E9: Supplier / Paid To | F9: Amount ($) | G9: Receipt # | H9: Paid By | I9: Notes
B10: 46160 | C10: Ingredients | D10: Vegetables | E10: MERCADO | F10: 90 | H10: Lohith Reddy
B11: 46160 | C11: Ingredients | D11: Carne | E11: MERCADO | F11: 420 | H11: Lohith Reddy
B12: 46160 | C12: Supplies | D12: Basicos | E12: ABASTOS | F12: 1068 | H12: Lohith Reddy
B13: 46160 | C13: Ingredients | D13: Real Pan Services | E13: ABASTOS | F13: 522 | H13: Lohith Reddy
B14: 46160 | C14: Ingredients | D14: Chedruai | F14: 129 | H14: Lohith Reddy
B15: 46160 | C15: Ingredients | D15: Vegetables | E15: ABASTOS | F15: 400 | H15: Restaurant
B16: 46161 | C16: Ingredients | D16: Arroz | E16: OXXO | F16: 30 | H16: Lohith Reddy
B17: 46162 | C17: Ingredients | D17: Arroz | E17: OXXO | F17: 90 | H17: Lohith Reddy
B18: 46162 | C18: Ingredients | D18: Lechuga | E18: MERCADO | F18: 65 | H18: Lohith Reddy
B19: 46162 | C19: Ingredients | D19: Tortillas | E19: MERCADO | F19: 26 | H19: Lohith Reddy
B20: 46162 | C20: Ingredients | D20: Jamon Mexicana | E20: SAN JUAN MERCADO | F20: 88 | H20: Lohith Reddy
B21: 46162 | C21: Ingredients | D21: Carne | E21: MERCADO | F21: 1104 | H21: Lohith Reddy
B22: 46162 | C22: Ingredients | D22: Salmon | E22: MERCADO | F22: 397 | H22: Lohith Reddy
B23: 46162 | C23: Ingredients | D23: Pollo | E23: Girigallo #ph | F23: 935 | H23: Lohith Reddy
B24: 46162 | C24: Ingredients | D24: Queso Gouda | E24: Bodega De Queso #Ph | F24: 272 | H24: Restaurant
B25: 46162 | C25: Ingredients | D25: Avia Reca | E25: Avia Reca #Ph | F25: 300 | H25: Restaurant
B26: 46162 | C26: Staff | D26: John | E26: Chef | F26: 500 | H26: Restaurant
B27: 46163 | C27: Ingredients | D27: Chuletas Carne | E27: MERCADO | F27: 213 | H27: Restaurant
B28: 46163 | C28: Ingredients | D28: Chedruai | F28: 232 | H28: Restaurant
B29: 46163 | C29: Ingredients | D29: Nutralat Milk | E29: OXXO | F29: 24 | H29: Restaurant
B30: 46163 | C30: Ingredients | D30: Crema y Queso | E30: CAQ | F30: 572 | H30: Restaurant
B31: 46163 | C31: Ingredients | D31: Pasta | F31: 82 | H31: Restaurant
B32: 46163 | C32: Ingredients | D32: Vegetables | E32: ABASTOS | F32: 148 | H32: Restaurant
B33: 46163 | C33: Ingredients | D33: Papas | E33: ABASTOS | F33: 130 | H33: Restaurant
B34: 46163 | C34: Ingredients | D34: Vegetables | E34: ABASTOS | F34: 207 | H34: Restaurant
B35: 46163 | C35: Ingredients | D35: Vegetables | E35: ABASTOS | F35: 185 | H35: Restaurant
B36: 46163 | C36: Ingredients | D36: Frutas | E36: ABASTOS | F36: 108 | H36: Restaurant
B37: 46163 | C37: Ingredients | D37: Panco | E37: MOLINO | F37: 196 | H37: Restaurant
B38: 46163 | C38: Beverages | D38: Drinks | E38: TIENDA 3B | F38: 337 | H38: Lohith Reddy
B39: 46164 | C39: Ingredients | D39: Nutralat Milk | E39: OXXO | F39: 24 | H39: Restaurant
B40: 46164 | C40: Ingredients | D40: Filete Mojarra | E40: BRISA DEL MAR | F40: 404.5 | H40: Restaurant
B41: 46164 | C41: Ingredients | D41: Aceite Vegetal | E41: OXXO | F41: 312 | H41: Restaurant
B42: 46164 | C42: Ingredients | D42: Aceite Vegetal | E42: OXXO | F42: 52 | H42: Restaurant
B43: 46164 | C43: Ingredients | D43: Leche Deslactosada | E43: OXXO | F43: 44 | H43: Restaurant
B44: 46164 | C44: Ingredients | D44: Panko x5 | E44: MOLINO LA CRUZ | F44: 490 | H44: Restaurant
...

Sheet 📦 Inventory
A2: 📦 LOKA — INVENTORY | F2: Update stock levels when you receive deliveries or do stock checks
B5: TOTAL ITEMS | D5: ⚠️ LOW STOCK | E5: LOW STOCK # | F5: 🚫 OUT OF STOCK | H5: ALERT COUNT | J5: LAST UPDATED
B6: =COUNTA(B9:B200) -> 59 | D6: =COUNTIF(J9:J200,"⚠️ LOW STOCK") -> 0 | E6: =COUNTIF(J9:J200,"⚠️ LOW STOCK")+COUNTIF(J9:J200,"🚫 OUT OF STOCK") -> 0 | F6: =COUNTIF(J9:J200,"🚫 OUT OF STOCK") -> 0 | H6: =COUNTIF(J9:J200,"⚠️ LOW STOCK")+COUNTIF(J9:J200,"🚫 OUT OF STOCK") -> 0 | J6: =TODAY() -> 46165
B8: 📌 Update the BLUE 'Current Stock' column when you receive deliveries or do a stock count. Status column updates automatically.
B9: Ingredient | C9: Category | D9: Unit | E9: Current Stock | F9: Min Level | G9: Cost/Unit ($) | H9: Reorder Qty | I9: Stock Value ($) | J9: Status | K9: Supplier / Notes
B10: Tortillas Blanco | C10: Grains | D10: pcs | E10: 200 | F10: 100 | G10: 1.5 | H10: 200 | I10: =E10*G10 -> 300 | J10: =IF(E10=0,"🚫 OUT OF STOCK",IF(E10<=F10,"⚠️ LOW STOCK","✅ OK")) -> ✅ OK
B11: Tortillas de Trigo | C11: Grains | D11: pcs | E11: 100 | F11: 50 | G11: 2 | H11: 100 | I11: =E11*G11 -> 200 | J11: =IF(E11=0,"🚫 OUT OF STOCK",IF(E11<=F11,"⚠️ LOW STOCK","✅ OK")) -> ✅ OK
B12: Pan Artesanal Masa Madre | C12: Bakery | D12: pcs | E12: 30 | F12: 15 | G12: 18 | H12: 30 | I12: =E12*G12 -> 540 | J12: =IF(E12=0,"🚫 OUT OF STOCK",IF(E12<=F12,"⚠️ LOW STOCK","✅ OK")) -> ✅ OK
B13: Pan Suave Hamburguesa | C13: Bakery | D13: pcs | E13: 40 | F13: 20 | G13: 8 | H13: 40 | I13: =E13*G13 -> 320 | J13: =IF(E13=0,"🚫 OUT OF STOCK",IF(E13<=F13,"⚠️ LOW STOCK","✅ OK")) -> ✅ OK
B14: Chapata Artesanal | C14: Bakery | D14: pcs | E14: 25 | F14: 10 | G14: 20 | H14: 25 | I14: =E14*G14 -> 500 | J14: =IF(E14=0,"🚫 OUT OF STOCK",IF(E14<=F14,"⚠️ LOW STOCK","✅ OK")) -> ✅ OK
B15: Hot Cake / Waffle Mix | C15: Bakery | D15: kg | E15: 3 | F15: 1 | G15: 45 | H15: 5 | I15: =E15*G15 -> 135 | J15: =IF(E15=0,"🚫 OUT OF STOCK",IF(E15<=F15,"⚠️ LOW STOCK","✅ OK")) -> ✅ OK
B16: Pechuga de Pollo | C16: Protein | D16: kg | E16: 8 | F16: 3 | G16: 85 | H16: 10 | I16: =E16*G16 -> 680 | J16: =IF(E16=0,"🚫 OUT OF STOCK",IF(E16<=F16,"⚠️ LOW STOCK","✅ OK")) -> ✅ OK
B17: Carne de Res (Hamburguesa) | C17: Protein | D17: kg | E17: 5 | F17: 2 | G17: 130 | H17: 8 | I17: =E17*G17 -> 650 | J17: =IF(E17=0,"🚫 OUT OF STOCK",IF(E17<=F17,"⚠️ LOW STOCK","✅ OK")) -> ✅ OK
B18: Arrachera | C18: Protein | D18: kg | E18: 3 | F18: 1 | G18: 160 | H18: 5 | I18: =E18*G18 -> 480 | J18: =IF(E18=0,"🚫 OUT OF STOCK",IF(E18<=F18,"⚠️ LOW STOCK","✅ OK")) -> ✅ OK
B19: Bistec de Res | C19: Protein | D19: kg | E19: 4 | F19: 2 | G19: 120 | H19: 6 | I19: =E19*G19 -> 480 | J19: =IF(E19=0,"🚫 OUT OF STOCK",IF(E19<=F19,"⚠️ LOW STOCK","✅ OK")) -> ✅ OK
B20: Tocino | C20: Protein | D20: kg | E20: 2 | F20: 1 | G20: 95 | H20: 3 | I20: =E20*G20 -> 190 | J20: =IF(E20=0,"🚫 OUT OF STOCK",IF(E20<=F20,"⚠️ LOW STOCK","✅ OK")) -> ✅ OK
B21: Jamon de Pavo | C21: Protein | D21: kg | E21: 2 | F21: 1 | G21: 80 | H21: 3 | I21: =E21*G21 -> 160 | J21: =IF(E21=0,"🚫 OUT OF STOCK",IF(E21<=F21,"⚠️ LOW STOCK","✅ OK")) -> ✅ OK
... B67: Arandanos Deshidratados | C67: Produce | D67: kg | E67: 0.3 | F67: 0.1 | G67: 220 | H67: 0.5 | I67: =E67*G67 -> 66 | J67: =IF(E67=0,"🚫 OUT OF STOCK",IF(E67<=F67,"⚠️ LOW STOCK","✅ OK")) -> ✅ OK

Sheet 👥 Staff & Payroll
A2: 👥 LOKA — STAFF & PAYROLL | G2: Weekly schedule + auto payroll calculation
B6: STAFF SCHEDULE — Week of: | E6: =TODAY()-WEEKDAY(TODAY(),2)+1 -> 46160
B7: Staff Name | C7: Role | D7: Daily Rate ($) | E7: Mon | F7: Tue | G7: Wed | H7: Thu | I7: Fri | J7: Sat | K7: Sun | L7: Days Worked | M7: Week Pay ($)
B8: John | C8: Head Chef | D8: 450 | E8: Full Day | F8: Full Day | G8: Full Day | H8: Full Day | I8: Full Day | J8: Full Day | K8: Day Off | L8: =COUNTIF(E8:K8,"Full Day")+COUNTIF(E8:K8,"Morning")*0.5+COUNTIF(E8:K8,"Afternoon")*0.5 -> 6 | M8: =COUNTIF(E8:K8,"Full Day")*D8+COUNTIF(E8:K8,"Morning")*D8*0.5+COUNTIF(E8:K8,"Afternoon")*D8*0.5 -> 2700
B9: Debi | C9: Cleaner | D9: 220 | E9: Full Day | F9: Full Day | G9: Full Day | H9: Full Day | I9: Full Day | J9: Full Day | K9: Day Off | L9: =COUNTIF(E9:K9,"Full Day")+COUNTIF(E9:K9,"Morning")*0.5+COUNTIF(E9:K9,"Afternoon")*0.5 -> 6 | M9: =COUNTIF(E9:K9,"Full Day")*D9+COUNTIF(E9:K9,"Morning")*D9*0.5+COUNTIF(E9:K9,"Afternoon")*D9*0.5 -> 1320
B10: Victor | C10: Waiter | D10: 333.33 | E10: Full Day | F10: Full Day | G10: Full Day | H10: Full Day | I10: Full Day | J10: Full Day | K10: Day Off | L10: =COUNTIF(E10:K10,"Full Day")+COUNTIF(E10:K10,"Morning")*0.5+COUNTIF(E10:K10,"Afternoon")*0.5 -> 6 | M10: =COUNTIF(E10:K10,"Full Day")*D10+COUNTIF(E10:K10,"Morning")*D10*0.5+COUNTIF(E10:K10,"Afternoon")*D10*0.5 -> 1999.98
B16: TOTAL WEEKLY PAYROLL | L16: =SUM(L8:L15) -> 18 | M16: =SUM(M8:M15) -> 6019.98
B19: MONTHLY PAYROLL PROJECTION
B20: Staff Name | C20: Role | D20: Week Pay ($) | E20: x Weeks/Month | F20: Monthly ($) | G20: IMSS / Benefits % | H20: Total Monthly Cost ($) | I20: Notes
B21: =B8 -> John | C21: Head Chef | D21: =M8 -> 2700 | E21: 4 | F21: =D21*E21 -> 10800 | G21: 0.08 | H21: =F21*(1+G21) -> 11664
B22: =B9 -> Debi | C22: Sous Chef | D22: =M9 -> 1320 | E22: 4 | F22: =D22*E22 -> 5280 | G22: 0.08 | H22: =F22*(1+G22) -> 5702.4
B23: =B10 -> Victor | C23: Waiter 1 | D23: =M10 -> 1999.98 | E23: 4 | F23: =D23*E23 -> 7999.92 | G23: 0.08 | H23: =F23*(1+G23) -> 8639.9136
B24: =B11 -> 0 | C24: Waiter 2 | D24: =M11 -> 0 | E24: 4 | F24: =D24*E24 -> 0 | G24: 0.08 | H24: =F24*(1+G24) -> 0
B25: =B12 -> 0 | C25: Barista | D25: =M12 -> 0 | E25: 4 | F25: =D25*E25 -> 0 | G25: 0.08 | H25: =F25*(1+G25) -> 0
B26: =B13 -> 0 | C26: Cashier | D26: =M13 -> 0 | E26: 4 | F26: =D26*E26 -> 0 | G26: 0.08 | H26: =F26*(1+G26) -> 0
B27: =B14 -> 0 | C27: Kitchen Helper | D27: =M14 -> 0 | E27: 4 | F27: =D27*E27 -> 0 | G27: 0.08 | H27: =F27*(1+G27) -> 0
B28: =B15 -> 0 | C28: Cleaner | D28: =M15 -> 0 | E28: 4 | F28: =D28*E28 -> 0 | G28: 0.08 | H28: =F28*(1+G28) -> 0
B29: TOTAL MONTHLY PAYROLL COST | H29: =SUM(H21:H28) -> 26006.314

Sheet 🚚 Suppliers
A2: 🚚 LOKA — SUPPLIER ORDERS | F2: Track purchase orders from suppliers
B5: TOTAL ORDERS | C5: PENDING | D5: IN TRANSIT | E5: RECEIVED | F5: MONTH SPEND | G5: PENDING VALUE | H5: PENDING COUNT
B6: =COUNTA(C9:C308)-1 -> 0 | C6: =COUNTIF(K9:K308,"Pending") -> 299 | D6: =COUNTIF(K9:K308,"In Transit") -> 0 | E6: =COUNTIF(K9:K308,"Received") -> 0 | F6: =SUMIF(K9:K308,"Received",J9:J308) -> 0 | G6: =SUMIF(K9:K308,"Pending",J9:J308) -> 0 | H6: =COUNTIF(K9:K308,"Pending")+COUNTIF(K9:K308,"In Transit") -> 299
B8: 📌 Log every supplier order here. Update Status as it progresses: Pending → Confirmed → In Transit → Received. Amount auto-calculates.
B9: Order Date | C9: Item / Ingredient | D9: Supplier | E9: Category | F9: Qty | G9: Unit | H9: Unit Price ($) | I9: Expected Date | J9: Total ($) | K9: Status
J10: =IFERROR(IF(F10*H10=0,"",F10*H10),"") | K10: Pending
J11: =IFERROR(IF(F11*H11=0,"",F11*H11),"") | K11: Pending
J12: =IFERROR(IF(F12*H12=0,"",F12*H12),"") | K12: Pending
J13: =IFERROR(IF(F13*H13=0,"",F13*H13),"") | K13: Pending
J14: =IFERROR(IF(F14*H14=0,"",F14*H14),"") | K14: Pending
J15: =IFERROR(IF(F15*H15=0,"",F15*H15),"") | K15: Pending
J16: =IFERROR(IF(F16*H16=0,"",F16*H16),"") | K16: Pending
J17: =IFERROR(IF(F17*H17=0,"",F17*H17),"") | K17: Pending
J18: =IFERROR(IF(F18*H18=0,"",F18*H18),"") | K18: Pending
J19: =IFERROR(IF(F19*H19=0,"",F19*H19),"") | K19: Pending
J20: =IFERROR(IF(F20*H20=0,"",F20*H20),"") | K20: Pending
J21: =IFERROR(IF(F21*H21=0,"",F21*H21),"") | K21: Pending
... J309: =IFERROR(IF(F309*H309=0,"",F309*H309),"") | K309: Pending

Sheet 📈 Monthly P&L
A2: 📈 LOKA — MONTHLY P&L | E2: Revenue & Expense summary — fill monthly totals from Daily Log & Expenses
B6: YEAR: | C6: 2025
C7: 2026
B8: P&L Line Item | C8: Jan | D8: Feb | E8: Mar | F8: Apr | G8: May | H8: Jun | I8: H1 TOTAL
B9: A. REVENUE
B10: Total Revenue (from Soft App) | C10: 0 | D10: 0 | E10: 0 | F10: 0 | G10: 0 | H10: 0 | I10: =SUM(C10:H10) -> 0
B11: B. COST OF GOODS (from Expenses)
B12: Ingredient / Food Cost | C12: 0 | D12: 0 | E12: 0 | F12: 0 | G12: 0 | H12: 0 | I12: =SUM(C12:H12) -> 0
B13: Other Supplies | C13: 0 | D13: 0 | E13: 0 | F13: 0 | G13: 0 | H13: 0 | I13: =SUM(C13:H13) -> 0
B14: TOTAL COGS | C14: =C12+C13 -> 0 | D14: =D12+D13 -> 0 | E14: =E12+E13 -> 0 | F14: =F12+F13 -> 0 | G14: =G12+G13 -> 0 | H14: =H12+H13 -> 0 | I14: =SUM(C14:H14) -> 0
B15: GROSS PROFIT | C15: =C10-C14 -> 0 | D15: =D10-D14 -> 0 | E15: =E10-E14 -> 0 | F15: =F10-F14 -> 0 | G15: =G10-G14 -> 0 | H15: =H10-H14 -> 0 | I15: =SUM(C15:H15) -> 0
B16: GROSS MARGIN % | C16: =IFERROR(C15/C10,0) -> 0 | D16: =IFERROR(D15/D10,0) -> 0 | E16: =IFERROR(E15/E10,0) -> 0 | F16: =IFERROR(F15/F10,0) -> 0 | G16: =IFERROR(G15/G10,0) -> 0 | H16: =IFERROR(H15/H10,0) -> 0 | I16: =IFERROR(AVERAGE(C16:H16),0) -> 0
B17: C. OPERATING EXPENSES
B18: Staff / Payroll | C18: 0 | D18: 0 | E18: 0 | F18: 0 | G18: 0 | H18: 0 | I18: =SUM(C18:H18) -> 0
B19: Rent | C19: 0 | D19: 0 | E19: 0 | F19: 0 | G19: 0 | H19: 0 | I19: =SUM(C19:H19) -> 0
B20: Utilities (Gas, Electric, Water) | C20: 0 | D20: 0 | E20: 0 | F20: 0 | G20: 0 | H20: 0 | I20: =SUM(C20:H20) -> 0
B21: Marketing | C21: 0 | D21: 0 | E21: 0 | F21: 0 | G21: 0 | H21: 0 | I21: =SUM(C21:H21) -> 0
B22: Maintenance & Other | C22: 0 | D22: 0 | E22: 0 | F22: 0 | G22: 0 | H22: 0 | I22: =SUM(C22:H22) -> 0
B23: TOTAL OPEX | C23: =SUM(C18:C22) -> 0 | D23: =SUM(D18:D22) -> 0 | E23: =SUM(E18:E22) -> 0 | F23: =SUM(F18:F22) -> 0 | G23: =SUM(G18:G22) -> 0 | H23: =SUM(H18:H22) -> 0 | I23: =SUM(C23:H23) -> 0
B24: EBITDA | C24: =C15-C23 -> 0 | D24: =D15-D23 -> 0 | E24: =E15-E23 -> 0 | F24: =F15-F23 -> 0 | G24: =G15-G23 -> 0 | H24: =H15-H23 -> 0 | I24: =SUM(C24:H24) -> 0
B25: EBITDA MARGIN % | C25: =IFERROR(C24/C10,0) -> 0 | D25: =IFERROR(D24/D10,0) -> 0 | E25: =IFERROR(E24/E10,0) -> 0 | F25: =IFERROR(F24/F10,0) -> 0 | G25: =IFERROR(G24/G10,0) -> 0 | H25: =IFERROR(H24/H10,0) -> 0 | I25: =IFERROR(AVERAGE(C25:H25),0) -> 0
B26: Depreciation | C26: 0 | D26: 0 | E26: 0 | F26: 0 | G26: 0 | H26: 0 | I26: =SUM(C26:H26) -> 0
B27: Taxes (ISR / IVA) | C27: 0 | D27: 0 | E27: 0 | F27: 0 | G27: 0 | H27: 0 | I27: =SUM(C27:H27) -> 0
B28: NET PROFIT | C28: =C24-C26-C27 -> 0 | D28: =D24-D26-D27 -> 0 | E28: =E24-E26-E27 -> 0 | F28: =F24-F26-F27 -> 0 | G28: =G24-G26-G27 -> 0 | H28: =H24-H26-H27 -> 0 | I28: =SUM(C28:H28) -> 0
B29: NET MARGIN % | C29: =IFERROR(C28/C10,0) -> 0 | D29: =IFERROR(D28/D10,0) -> 0 | E29: =IFERROR(E28/E10,0) -> 0 | F29: =IFERROR(F28/F10,0) -> 0 | G29: =IFERROR(G28/G10,0) -> 0 | H29: =IFERROR(H28/H10,0) -> 0 | I29: =IFERROR(AVERAGE(C29:H29),0) -> 0
B30: D. KEY METRICS
B31: Total Orders (from Soft) | C31: 0 | D31: 0 | E31: 0 | F31: 0 | G31: 0 | H31: 0 | I31: =SUM(C31:H31) -> 0
B32: Avg Ticket ($) | C32: =IFERROR(C10/C31,0) -> 0 | D32: =IFERROR(D10/D31,0) -> 0 | E32: =IFERROR(E10/E31,0) -> 0 | F32: =IFERROR(F10/F31,0) -> 0 | G32: =IFERROR(G10/G31,0) -> 0 | H32: =IFERROR(H10/H31,0) -> 0 | I32: =IFERROR(AVERAGE(C32:H32),0) -> 0
B33: Working Days | C33: 0 | D33: 0 | E33: 0 | F33: 0 | G33: 0 | H33: 0 | I33: =SUM(C33:H33) -> 0
B34: Revenue per Day ($) | C34: =IFERROR(C10/C33,0) -> 0 | D34: =IFERROR(D10/D33,0) -> 0 | E34: =IFERROR(E10/E33,0) -> 0 | F34: =IFERROR(F10/F33,0) -> 0 | G34: =IFERROR(G10/G33,0) -> 0 | H34: =IFERROR(H10/H33,0) -> 0 | I34: =IFERROR(AVERAGE(C34:H34),0) -> 0
B36: SECOND HALF (Jul – Dec)
B37: P&L Line Item | C37: Jul | D37: Aug | E37: Sep | F37: Oct | G37: Nov | H37: Dec | I37: H2 TOTAL
B38: Total Revenue (from Soft App) | C38: 0 | D38: 0 | E38: 0 | F38: 0 | G38: 0 | H38: 0 | I38: =SUM(C38:H38) -> 0
B39: Ingredient / Food Cost | C39: 0 | D39: 0 | E39: 0 | F39: 0 | G39: 0 | H39: 0 | I39: =SUM(C39:H39) -> 0
B40: Other Supplies | C40: 0 | D40: 0 | E40: 0 | F40: 0 | G40: 0 | H40: 0 | I40: =SUM(C40:H40) -> 0
B41: TOTAL COGS | C41: =C39+C40 -> 0 | D41: =D39+D40 -> 0 | E41: =E39+E40 -> 0 | F41: =F39+F40 -> 0 | G41: =G39+G40 -> 0 | H41: =H39+H40 -> 0 | I41: =SUM(C41:H41) -> 0
B42: GROSS PROFIT | C42: =C38-C41 -> 0 | D42: =D38-D41 -> 0 | E42: =E38-E41 -> 0 | F42: =F38-F41 -> 0 | G42: =G38-G41 -> 0 | H42: =H38-H41 -> 0 | I42: =SUM(C42:H42) -> 0
B43: GROSS MARGIN % | C43: =IFERROR(C42/C38,0) -> 0 | D43: =IFERROR(D42/D38,0) -> 0 | E43: =IFERROR(E42/E38,0) -> 0 | F43: =IFERROR(F42/F38,0) -> 0 | G43: =IFERROR(G42/G38,0) -> 0 | H43: =IFERROR(H42/H38,0) -> 0 | I43: =IFERROR(AVERAGE(C43:H43),0) -> 0
B44: Staff / Payroll | C44: 0 | D44: 0 | E44: 0 | F44: 0 | G44: 0 | H44: 0 | I44: =SUM(C44:H44) -> 0
B45: Rent | C45: 0 | D45: 0 | E45: 0 | F45: 0 | G45: 0 | H45: 0 | I45: =SUM(C45:H45) -> 0
...
