Workbook

Sheet Capital & Ownership
B1: LOKA — CAPITAL, OWNERSHIP & PRE-OPENING EXPENSES
B2: Last updated: 10 Jun 2026 | Capital, Acquisition, Pre-Opening & Renovation CapEx
B4: A. OWNERSHIP STRUCTURE
B5: Owner | C5: Share % | D5: Capital ($) | E5: Expenses ($) | F5: Remaining ($) | G5: Role / Notes
B6: Lohith Reddy | C6: 0.5 | D6: 300000 | E6: =D55 | F6: =D6-E6 | G6: 50% — Managing Partner
B7: Kashigoud Patil | C7: 0.3 | D7: 180000 | E7: =D42 | F7: =D7-E7 | G7: 30% — Partner
B8: Shashirekha Basavaraju | C8: 0.2 | D8: 120000 | E8: =D68 | F8: =D8-E8 | G8: 20% — Partner
B9: TOTAL | C9: =SUM(C6:C8) | D9: =SUM(D6:D8) | E9: =SUM(E6:E8) | F9: =SUM(F6:F8)
B11: B. RESTAURANT ACQUISITION — $390,000 TOTAL
B12: Description | C12: Date | D12: Amount ($) | E12: Paid By | F12: Status | G12: Notes
B13: TOTAL Purchase Price — Previous Owners | D13: 390000 | E13: All Partners | F13: ⚠️ PARTIALLY PAID — $134,500 remaining | G13: Full acquisition amount
B14: Advance Payment (paid by Lohith) | D14: 5000 | E14: Lohith Reddy | F14: ✅ PAID | G14: Advance to previous owners
B15: Payment to Previous Owners | C15: 46176 | D15: 95000 | E15: Lohith Reddy | F15: ✅ PAID | G15: Paid from restaurant operating balance — 3 Jun 2026
B16: Payment to Previous Owner — Account 1 | C16: 46177 | D16: 8000 | E16: Lohith Reddy | F16: ✅ PAID | G16: Capital payment — from main budget — transferred to different accounts
B17: Payment to Previous Owner — Account 2 | C17: 46177 | D17: 4500 | E17: Lohith Reddy | F17: ✅ PAID | G17: Capital payment — from main budget — transferred to different account
B18: Payment to Previous Owner — Account 3 | C18: 46177 | D18: 15000 | E18: Lohith Reddy | F18: ✅ PAID | G18: Capital payment — from main budget — transferred to different accounts
B19: Payment to Previous Owner — Account 4 | C19: 46177 | D19: 10000 | E19: Lohith Reddy | F19: ✅ PAID | G19: Capital payment — from main budget — transferred to different accounts
B20: Payment to Previous Owner — Account 5 | C20: 46177 | D20: 44000 | E20: Lohith Reddy | F20: ✅ PAID | G20: Capital payment — from main budget — transferred to different accounts
B21: Payment to Previous Owner — Account 6 | C21: 46177 | D21: 44000 | E21: Lohith Reddy | F21: ✅ PAID | G21: Capital payment — from main budget — transferred to different accounts
B22: Payment to Previous Owner — Jun 5 | C22: 46178 | D22: 30000 | E22: Lohith Reddy | F22: ✅ PAID | G22: Transfer — 5 Jun 2026
B23: Balance Remaining | D23: =D13-SUM(D14:D22) | E23: — | F23: ⏳ PENDING | G23: $390,000 − $255,500 paid = $134,500 remaining
B25: PAYMENT BREAKDOWN — How the $390,000 will be funded
B26: Source | C26: From | D26: Amount ($) | E26: Toward % | F26: Cumulative | G26: Notes
B27: Kashigoud Transfer to Lohith | C27: Kashigoud Patil | D27: 125000 | E27: =D27/390000 | F27: =D27 | G27: Full Kashi transfer
B28: Shashirekha Transfer to Lohith | C28: Shashirekha B. | D28: 100000 | E28: =D28/390000 | F28: =D27+D28 | G28: Full Shashi transfer
B29: Lohith Reddy (own funds) | C29: Lohith Reddy | D29: =390000-D27-D28 | E29: =D29/390000 | F29: =D27+D28+D29 | G29: Balance from Lohith
B30: Advance Already Paid | C30: Lohith Reddy | D30: 5000 | E30: =D30/390000 | F30: Paid ✅ | G30: Already paid
B32: C. PRE-OPENING EXPENSES — KASHIGOUD PATIL
B33: Description | C33: Date | D33: Amount ($) | E33: Paid To | F33: Category | G33: Notes
B34: Transfer to Lohith Reddy (capital allocation) | D34: 125000 | E34: Bank → Lohith | F34: Internal Transfer | G34: For acquisition & expenses
B35: Soft Restaurant License & Tools | D35: 15195 | E35: Soft App | F35: Software / License | G35: POS + mgmt tools
B36: Mercado Pago Terminal | D36: 500 | E36: Soft App / MP | F36: POS Hardware | G36: MP card reader terminal fee
B37: Camera Cloud Recording — 7 Day Continuous (28 May) | C37: 46170 | D37: 436.12 | E37: Kashigoud Patil (VISA ••••9193) | F37: Technology / Security | G37: Shenzhen Tange — cloud CCTV recording 1yr — US$23.90 = MXN $436.12
B38: Camera Cloud Recording — 7 Day Continuous (29 May) | C38: 46171 | D38: 437.22 | E38: Kashigoud Patil (VISA ••••9193) | F38: Technology / Security | G38: Shenzhen Tange — cloud CCTV recording 1yr — US$23.90 = MXN $437.22
B42: KASHIGOUD TOTAL | D42: =SUM(D34:D41)
B44: D. PRE-OPENING EXPENSES — LOHITH REDDY
B45: Description | C45: Date | D45: Amount ($) | E45: Paid To | F45: Category | G45: Notes
B46: Advance Payment to Previous Owners | D46: 5000 | E46: Previous Owners | F46: Acquisition | G46: 5k advance on 390k purchase
B47: Notary Fees | D47: 15797 | E47: Notary Office | F47: Legal | G47: Legal fees for restaurant acquisition
B48: Poliza Juridica (Legal Policy) | D48: 5150 | E48: Legal / Insurance | F48: Legal | G48: Poliza Juridica — legal insurance policy
...

Sheet 📊 Dashboard
A2: 🍽️ LOKA Cafe Restaurante | H2: Restaurant Manager — powered by Soft + Excel
B5: 📌 HOW TO USE: ① Each update, go to 📅 Daily Log → enter Date + Revenue + Orders from Soft App ② Fill 💸 Expenses for costs paid ③ Update 📦 Inventory when stock changes ④ This dashboard updates automatically
B7: 💰 REVENUE (auto-pulled from Daily Log)
B9: TODAY'S REVENUE | D9: WEEK REVENUE | F9: MONTH REVENUE | H9: TODAY'S EXPENSES | J9: TODAY'S NET PROFIT | L9: AVG TICKET
B10: ='📅 Daily Log'!F6 | D10: ='📅 Daily Log'!N6 | F10: ='📅 Daily Log'!O6 | H10: ='📅 Daily Log'!H6 | J10: ='📅 Daily Log'!I6 | L10: =IFERROR('📅 Daily Log'!F6/'📅 Daily Log'!G6,0)
B14: 📊 OPERATIONS
B16: TODAY'S ORDERS | D16: WEEK ORDERS | F16: PROFIT MARGIN % | H16: LOW STOCK ITEMS | J16: WEEK EXPENSES | L16: PENDING ORDERS
B17: ='📅 Daily Log'!G6 | D17: =IFERROR(SUMPRODUCT((ISNUMBER('📅 Daily Log'!$B$8:$B$500))*('📅 Daily Log'!$B$8:$B$500>=TODAY()-MOD(TODAY()-2,7))*('📅 Daily Log'!$B$8:$B$500<TODAY()-MOD(TODAY()-2,7)+7)*IF(ISNUMBER('📅 Daily Log'!$G$8:$G$500),'📅 Daily Log'!$G$8:$G$500,0)),0) | F17: =IFERROR('📅 Daily Log'!J6,0) | H17: ='📦 Inventory'!H5 | J17: ='📅 Daily Log'!P6 | L17: ='🚚 Suppliers'!H5
B21: 📅 LAST 10 DAYS (from Daily Log — updates automatically)
B22: Date | C22: Day | D22: Revenue ($) | E22: Orders | F22: Avg Ticket | G22: Expenses ($) | H22: Net Profit ($) | I22: Margin % | J22: Notes | K22: vs Prev Day
B23: ='📅 Daily Log'!B8 | C23: ='📅 Daily Log'!F8 | D23: ='📅 Daily Log'!G8 | E23: =IFERROR('📅 Daily Log'!F8/'📅 Daily Log'!G8,0) | F23: ='📅 Daily Log'!H8 | G23: ='📅 Daily Log'!I8 | H23: ='📅 Daily Log'!J8 | I23: ='📅 Daily Log'!K8 | J23: ='📅 Daily Log'!K8 | K23: —
B24: ='📅 Daily Log'!B9 | C24: ='📅 Daily Log'!F9 | D24: ='📅 Daily Log'!G9 | E24: =IFERROR('📅 Daily Log'!F9/'📅 Daily Log'!G9,0) | F24: ='📅 Daily Log'!H9 | G24: ='📅 Daily Log'!I9 | H24: ='📅 Daily Log'!J9 | I24: ='📅 Daily Log'!K9 | J24: ='📅 Daily Log'!K9 | K24: =IFERROR(IF(D24>D23,"▲ +"&TEXT(D24-D23,"$#,##0"),IF(D24<D23,"▼ "&TEXT(D24-D23,"$#,##0"),"— same")),"")
B25: ='📅 Daily Log'!B10 | C25: ='📅 Daily Log'!F10 | D25: ='📅 Daily Log'!G10 | E25: =IFERROR('📅 Daily Log'!F10/'📅 Daily Log'!G10,0) | F25: ='📅 Daily Log'!H10 | G25: ='📅 Daily Log'!I10 | H25: ='📅 Daily Log'!J10 | I25: ='📅 Daily Log'!K10 | J25: ='📅 Daily Log'!K10 | K25: =IFERROR(IF(D25>D24,"▲ +"&TEXT(D25-D24,"$#,##0"),IF(D25<D24,"▼ "&TEXT(D25-D24,"$#,##0"),"— same")),"")
B26: ='📅 Daily Log'!B11 | C26: ='📅 Daily Log'!F11 | D26: ='📅 Daily Log'!G11 | E26: =IFERROR('📅 Daily Log'!F11/'📅 Daily Log'!G11,0) | F26: ='📅 Daily Log'!H11 | G26: ='📅 Daily Log'!I11 | H26: ='📅 Daily Log'!J11 | I26: ='📅 Daily Log'!K11 | J26: ='📅 Daily Log'!K11 | K26: =IFERROR(IF(D26>D25,"▲ +"&TEXT(D26-D25,"$#,##0"),IF(D26<D25,"▼ "&TEXT(D26-D25,"$#,##0"),"— same")),"")
B27: ='📅 Daily Log'!B12 | C27: ='📅 Daily Log'!F12 | D27: ='📅 Daily Log'!G12 | E27: =IFERROR('📅 Daily Log'!F12/'📅 Daily Log'!G12,0) | F27: ='📅 Daily Log'!H12 | G27: ='📅 Daily Log'!I12 | H27: ='📅 Daily Log'!J12 | I27: ='📅 Daily Log'!K12 | J27: ='📅 Daily Log'!K12 | K27: =IFERROR(IF(D27>D26,"▲ +"&TEXT(D27-D26,"$#,##0"),IF(D27<D26,"▼ "&TEXT(D27-D26,"$#,##0"),"— same")),"")
B28: ='📅 Daily Log'!B13 | C28: ='📅 Daily Log'!F13 | D28: ='📅 Daily Log'!G13 | E28: =IFERROR('📅 Daily Log'!F13/'📅 Daily Log'!G13,0) | F28: ='📅 Daily Log'!H13 | G28: ='📅 Daily Log'!I13 | H28: ='📅 Daily Log'!J13 | I28: ='📅 Daily Log'!K13 | J28: ='📅 Daily Log'!K13 | K28: =IFERROR(IF(D28>D27,"▲ +"&TEXT(D28-D27,"$#,##0"),IF(D28<D27,"▼ "&TEXT(D28-D27,"$#,##0"),"— same")),"")
B29: ='📅 Daily Log'!B14 | C29: ='📅 Daily Log'!F14 | D29: ='📅 Daily Log'!G14 | E29: =IFERROR('📅 Daily Log'!F14/'📅 Daily Log'!G14,0) | F29: ='📅 Daily Log'!H14 | G29: ='📅 Daily Log'!I14 | H29: ='📅 Daily Log'!J14 | I29: ='📅 Daily Log'!K14 | J29: ='📅 Daily Log'!K14 | K29: =IFERROR(IF(D29>D28,"▲ +"&TEXT(D29-D28,"$#,##0"),IF(D29<D28,"▼ "&TEXT(D29-D28,"$#,##0"),"— same")),"")
B30: ='📅 Daily Log'!B15 | C30: ='📅 Daily Log'!F15 | D30: ='📅 Daily Log'!G15 | E30: =IFERROR('📅 Daily Log'!F15/'📅 Daily Log'!G15,0) | F30: ='📅 Daily Log'!H15 | G30: ='📅 Daily Log'!I15 | H30: ='📅 Daily Log'!J15 | I30: ='📅 Daily Log'!K15 | J30: ='📅 Daily Log'!K15 | K30: =IFERROR(IF(D30>D29,"▲ +"&TEXT(D30-D29,"$#,##0"),IF(D30<D29,"▼ "&TEXT(D30-D29,"$#,##0"),"— same")),"")
B31: ='📅 Daily Log'!B16 | C31: ='📅 Daily Log'!F16 | D31: ='📅 Daily Log'!G16 | E31: =IFERROR('📅 Daily Log'!F16/'📅 Daily Log'!G16,0) | F31: ='📅 Daily Log'!H16 | G31: ='📅 Daily Log'!I16 | H31: ='📅 Daily Log'!J16 | I31: ='📅 Daily Log'!K16 | J31: ='📅 Daily Log'!K16 | K31: =IFERROR(IF(D31>D30,"▲ +"&TEXT(D31-D30,"$#,##0"),IF(D31<D30,"▼ "&TEXT(D31-D30,"$#,##0"),"— same")),"")
B32: ='📅 Daily Log'!B17 | C32: ='📅 Daily Log'!F17 | D32: ='📅 Daily Log'!G17 | E32: =IFERROR('📅 Daily Log'!F17/'📅 Daily Log'!G17,0) | F32: ='📅 Daily Log'!H17 | G32: ='📅 Daily Log'!I17 | H32: ='📅 Daily Log'!J17 | I32: ='📅 Daily Log'!K17 | J32: ='📅 Daily Log'!K17 | K32: =IFERROR(IF(D32>D31,"▲ +"&TEXT(D32-D31,"$#,##0"),IF(D32<D31,"▼ "&TEXT(D32-D31,"$#,##0"),"— same")),"")
B34: ⚠️ INVENTORY ALERTS (from Inventory sheet)
B35: Ingredient | F35: Min Level | H35: Status | J35: Action Needed
B36: ='📦 Inventory'!B9 | E36: ='📦 Inventory'!E9 | G36: ='📦 Inventory'!F9 | I36: ='📦 Inventory'!J9 | K36: =IF('📦 Inventory'!E9=0,"🚫 Order immediately",IF('📦 Inventory'!E9<='📦 Inventory'!F9,"⚠️ Reorder soon","✅ OK"))
B37: ='📦 Inventory'!B10 | E37: ='📦 Inventory'!E10 | G37: ='📦 Inventory'!F10 | I37: ='📦 Inventory'!J10 | K37: =IF('📦 Inventory'!E10=0,"🚫 Order immediately",IF('📦 Inventory'!E10<='📦 Inventory'!F10,"⚠️ Reorder soon","✅ OK"))
B38: ='📦 Inventory'!B11 | E38: ='📦 Inventory'!E11 | G38: ='📦 Inventory'!F11 | I38: ='📦 Inventory'!J11 | K38: =IF('📦 Inventory'!E11=0,"🚫 Order immediately",IF('📦 Inventory'!E11<='📦 Inventory'!F11,"⚠️ Reorder soon","✅ OK"))
B39: ='📦 Inventory'!B12 | E39: ='📦 Inventory'!E12 | G39: ='📦 Inventory'!F12 | I39: ='📦 Inventory'!J12 | K39: =IF('📦 Inventory'!E12=0,"🚫 Order immediately",IF('📦 Inventory'!E12<='📦 Inventory'!F12,"⚠️ Reorder soon","✅ OK"))
B40: ='📦 Inventory'!B13 | E40: ='📦 Inventory'!E13 | G40: ='📦 Inventory'!F13 | I40: ='📦 Inventory'!J13 | K40: =IF('📦 Inventory'!E13=0,"🚫 Order immediately",IF('📦 Inventory'!E13<='📦 Inventory'!F13,"⚠️ Reorder soon","✅ OK"))
B42: 💼 CAPITAL & ACQUISITION STATUS — live from Capital & Ownership sheet
B44: TOTAL BUDGET | D44: TOTAL CASH OUT | F44: REMAINING BUDGET | H44: ACQUISITION PRICE | J44: ADVANCE PAID | L44: BALANCE PENDING
B45: ='Capital & Ownership'!C63 | D45: ='Capital & Ownership'!C72 | F45: ='Capital & Ownership'!C73 | H45: ='Capital & Ownership'!C64 | J45: ='Capital & Ownership'!C65 | L45: ='Capital & Ownership'!C66
B46: All 3 partners | D46: Excl. internal transfers | F46: Available for operations | H46: To previous owners | J46: ✅ Paid by Lohith | L46: ⏳ Outstanding
B48: 👥 OWNER CAPITAL SUMMARY
B49: OWNER | D49: SHARE % | F49: CAPITAL ($) | G49: ROLE | H49: EXPENSES ($) | J49: REMAINING ($) | L49: % SPENT
B50: ='Capital & Ownership'!B6 | D50: ='Capital & Ownership'!C6 | F50: ='Capital & Ownership'!D6 | G50: 50% — Managing Partner | H50: ='Capital & Ownership'!E6 | J50: ='Capital & Ownership'!F6 | L50: =IFERROR('Capital & Ownership'!E6/'Capital & Ownership'!D6,0)
B51: ='Capital & Ownership'!B7 | D51: ='Capital & Ownership'!C7 | F51: ='Capital & Ownership'!D7 | G51: 30% — Partner | H51: ='Capital & Ownership'!E7 | J51: ='Capital & Ownership'!F7 | L51: =IFERROR('Capital & Ownership'!E7/'Capital & Ownership'!D7,0)
B52: ='Capital & Ownership'!B8 | D52: ='Capital & Ownership'!C8 | F52: ='Capital & Ownership'!D8 | G52: 20% — Partner | H52: ='Capital & Ownership'!E8 | J52: ='Capital & Ownership'!F8 | L52: =IFERROR('Capital & Ownership'!E8/'Capital & Ownership'!D8,0)
B53: TOTAL | D53: ='Capital & Ownership'!C9 | F53: ='Capital & Ownership'!D9 | H53: ='Capital & Ownership'!E9 | J53: ='Capital & Ownership'!F9 | L53: =IFERROR('Capital & Ownership'!E9/'Capital & Ownership'!D9,0)
B55: 🧾 PRE-OPENING EXPENSES BREAKDOWN
B56: EXPENSE ITEM | E56: PAID BY | G56: AMOUNT ($) | I56: CATEGORY | K56: STATUS
B57: ='Capital & Ownership'!B13 | E57: All Partners | G57: ='Capital & Ownership'!D13 | I57: Acquisition | K57: ⚠️ Not Fully Paid
...

Sheet 📅 Daily Log
A2: 📅 LOKA — DAILY LOG | I2: Enter 2 values from Soft App each day → everything else calculates
B5: ✏️ INSTRUCTIONS: Each time you open this file, add a new row below. Fill only the BLUE cells: 📌 Date | 💰 Revenue (from Soft App end-of-day report) | 🛒 Orders (from Soft App) | 📝 Notes (optional). All other columns calculate automatically.
F6: =SUMIFS($D$8:$D$500,$B$8:$B$500,TODAY())+SUMIFS($E$8:$E$500,$B$8:$B$500,TODAY())+SUMIFS($G$8:$G$500,$B$8:$B$500,TODAY()) | G6: =SUMIFS($G$8:$G$500,$B$8:$B$500,TODAY()) | H6: =SUMIFS($H$8:$H$500,$B$8:$B$500,TODAY()) | I6: =F6-H6 | J6: =IFERROR(I6/F6,0) | M6: =SUMPRODUCT((ISNUMBER($B$8:$B$500))*($B$8:$B$500>=TODAY()-MOD(TODAY()-2,7))*($B$8:$B$500<TODAY()-MOD(TODAY()-2,7)+7)*IF(ISNUMBER($F$8:$F$500),$F$8:$F$500,0)) | N6: =SUMPRODUCT((ISNUMBER($B$8:$B$500))*($B$8:$B$500>=TODAY()-MOD(TODAY()-2,7))*($B$8:$B$500<TODAY()-MOD(TODAY()-2,7)+7)*IF(ISNUMBER($F$8:$F$500),$F$8:$F$500,0)) | O6: =SUMPRODUCT((ISNUMBER($B$8:$B$500))*(MONTH($B$8:$B$500)=MONTH(TODAY()))*(YEAR($B$8:$B$500)=YEAR(TODAY()))*IF(ISNUMBER($F$8:$F$500),$F$8:$F$500,0)) | P6: =SUMPRODUCT((ISNUMBER($B$8:$B$500))*($B$8:$B$500>=TODAY()-MOD(TODAY()-2,7))*($B$8:$B$500<TODAY()-MOD(TODAY()-2,7)+7)*IF(ISNUMBER($H$8:$H$500),$H$8:$H$500,0)) | Q6: =M6-P6
B7: Date | C7: Day | D7: Card / Mercado Pago ($) | E7: Cash ($) | F7: Total Revenue ($) | G7: Transfer ($) | H7: Expenses $ | I7: Net Profit $ | J7: Margin % | K7: Notes | L7: Source | M7: WEEK PROFIT | N7: CUMUL. REVENUE | O7: MONTH REVENUE | P7: Week Expenses | Q7: Week Profit
B8: 46160 | C8: Mon | D8: 2229 | E8: 1460 | F8: =IFERROR(D8+E8+G8,0) | H8: =SUMIFS('💸 Expenses'!$F$8:$F$500,'💸 Expenses'!$B$8:$B$500,">="&B8,'💸 Expenses'!$B$8:$B$500,"<"&(B8+1)) | I8: =IFERROR(F8-H8,0) | J8: =IFERROR(I8/F8,0) | L8: Manual Bills
B9: 46161 | C9: Tue | D9: 2125 | E9: 1729 | F9: =IFERROR(D9+E9+G9,0) | H9: =SUMIFS('💸 Expenses'!$F$8:$F$500,'💸 Expenses'!$B$8:$B$500,">="&B9,'💸 Expenses'!$B$8:$B$500,"<"&(B9+1)) | I9: =IFERROR(F9-H9,0) | J9: =IFERROR(I9/F9,0) | L9: Manual Bills
B10: 46162 | C10: Wed | D10: 1459 | E10: 2665 | F10: =IFERROR(D10+E10+G10,0) | H10: =SUMIFS('💸 Expenses'!$F$8:$F$500,'💸 Expenses'!$B$8:$B$500,">="&B10,'💸 Expenses'!$B$8:$B$500,"<"&(B10+1)) | I10: =IFERROR(F10-H10,0) | J10: =IFERROR(I10/F10,0) | L10: Manual Bills
B11: 46163 | C11: Thu | D11: 2570 | E11: 2163 | F11: =IFERROR(D11+E11+G11,0) | H11: =SUMIFS('💸 Expenses'!$F$8:$F$500,'💸 Expenses'!$B$8:$B$500,">="&B11,'💸 Expenses'!$B$8:$B$500,"<"&(B11+1)) | I11: =IFERROR(F11-H11,0) | J11: =IFERROR(I11/F11,0) | L11: Manual Bills
B12: 46164 | C12: Fri | D12: 1959 | E12: 2323 | F12: =IFERROR(D12+E12+G12,0) | H12: =SUMIFS('💸 Expenses'!$F$8:$F$500,'💸 Expenses'!$B$8:$B$500,">="&B12,'💸 Expenses'!$B$8:$B$500,"<"&(B12+1)) | I12: =IFERROR(F12-H12,0) | J12: =IFERROR(I12/F12,0) | L12: Manual Bills
B13: 46165 | C13: Sat | D13: 2044 | E13: 1758 | F13: =IFERROR(D13+E13+G13,0) | H13: =SUMIFS('💸 Expenses'!$F$8:$F$500,'💸 Expenses'!$B$8:$B$500,">="&B13,'💸 Expenses'!$B$8:$B$500,"<"&(B13+1)) | I13: =IFERROR(F13-H13,0) | J13: =IFERROR(I13/F13,0) | K13: Payroll week — John $3,250 + Debi $1,500 + Victor $666 + Tips $1,198 | L13: Manual Bills
B14: 46166 | C14: Sun | E14: 1198 | F14: =IFERROR(D14+E14+G14,0) | H14: =SUMIFS('💸 Expenses'!$F$8:$F$500,'💸 Expenses'!$B$8:$B$500,">="&B14,'💸 Expenses'!$B$8:$B$500,"<"&(B14+1)) | I14: =IFERROR(F14-H14,0) | J14: =IFERROR(I14/F14,0) | K14: 🔴 CLOSED — Sunday. Expenses are prep purchases for the week ahead. | L14: Manual Bills
B15: 46167 | C15: Mon | D15: 2106 | E15: 1624 | F15: =IFERROR(D15+E15+G15,0) | H15: =SUMIFS('💸 Expenses'!$F$8:$F$500,'💸 Expenses'!$B$8:$B$500,">="&B15,'💸 Expenses'!$B$8:$B$500,"<"&(B15+1)) | I15: =IFERROR(F15-H15,0) | J15: =IFERROR(I15/F15,0) | L15: Manual Bills
B16: 46168 | C16: Tue | D16: 1909 | E16: 2355 | F16: =IFERROR(D16+E16+G16,0) | H16: =SUMIFS('💸 Expenses'!$F$8:$F$500,'💸 Expenses'!$B$8:$B$500,">="&B16,'💸 Expenses'!$B$8:$B$500,"<"&(B16+1)) | I16: =IFERROR(F16-H16,0) | J16: =IFERROR(I16/F16,0) | L16: Manual Bills
B17: 46169 | C17: Wed | D17: 1956 | E17: 1665 | F17: =IFERROR(D17+E17+G17,0) | H17: =SUMIFS('💸 Expenses'!$F$8:$F$500,'💸 Expenses'!$B$8:$B$500,">="&B17,'💸 Expenses'!$B$8:$B$500,"<"&(B17+1)) | I17: =IFERROR(F17-H17,0) | J17: =IFERROR(I17/F17,0) | L17: Manual Bills
B18: 46170 | C18: Thu | D18: 1501 | E18: 2569 | F18: =IFERROR(D18+E18+G18,0) | H18: =SUMIFS('💸 Expenses'!$F$8:$F$500,'💸 Expenses'!$B$8:$B$500,">="&B18,'💸 Expenses'!$B$8:$B$500,"<"&(B18+1)) | I18: =IFERROR(F18-H18,0) | J18: =IFERROR(I18/F18,0) | L18: Manual Bills
B19: 46171 | C19: Fri | D19: 3369 | E19: 2717 | F19: =IFERROR(D19+E19+G19,0) | H19: =SUMIFS('💸 Expenses'!$F$8:$F$500,'💸 Expenses'!$B$8:$B$500,">="&B19,'💸 Expenses'!$B$8:$B$500,"<"&(B19+1)) | I19: =IFERROR(F19-H19,0) | J19: =IFERROR(I19/F19,0) | L19: Manual Bills
B20: 46172 | C20: Sat | D20: 3457 | E20: 1146 | F20: =IFERROR(D20+E20+G20,0) | H20: =SUMIFS('💸 Expenses'!$F$8:$F$500,'💸 Expenses'!$B$8:$B$500,">="&B20,'💸 Expenses'!$B$8:$B$500,"<"&(B20+1)) | I20: =IFERROR(F20-H20,0) | J20: =IFERROR(I20/F20,0) | L20: Manual Bills
B21: 46173 | C21: Sun | E21: 893 | F21: =IFERROR(D21+E21+G21,0) | H21: =SUMIFS('💸 Expenses'!$F$8:$F$500,'💸 Expenses'!$B$8:$B$500,">="&B21,'💸 Expenses'!$B$8:$B$500,"<"&(B21+1)) | I21: =IFERROR(F21-H21,0) | J21: =IFERROR(I21/F21,0) | L21: Manual Bills
B22: 46174 | C22: Mon | D22: 3433 | E22: 1276 | F22: =IFERROR(D22+E22+G22,0) | G22: 310 | H22: =SUMIFS('💸 Expenses'!$F$8:$F$500,'💸 Expenses'!$B$8:$B$500,">="&B22,'💸 Expenses'!$B$8:$B$500,"<"&(B22+1)) | I22: =IFERROR(F22-H22,0) | J22: =IFERROR(I22/F22,0) | L22: Manual Bills
B23: 46175 | C23: Tue | D23: 1240 | E23: 320 | F23: =IFERROR(D23+E23+G23,0) | G23: 283 | H23: =SUMIFS('💸 Expenses'!$F$8:$F$500,'💸 Expenses'!$B$8:$B$500,">="&B23,'💸 Expenses'!$B$8:$B$500,"<"&(B23+1)) | I23: =IFERROR(F23-H23,0) | J23: =IFERROR(I23/F23,0) | L23: Manual Bills
B24: 46176 | C24: Wed | D24: 1853 | E24: 1939 | F24: =IFERROR(D24+E24+G24,0) | G24: 120 | H24: =SUMIFS('💸 Expenses'!$F$8:$F$500,'💸 Expenses'!$B$8:$B$500,">="&B24,'💸 Expenses'!$B$8:$B$500,"<"&(B24+1)) | I24: =IFERROR(F24-H24,0) | J24: =IFERROR(I24/F24,0) | L24: Manual Bills
B25: 46177 | C25: Thu | D25: 2712 | E25: 1045 | F25: =IFERROR(D25+E25+G25,0) | H25: =SUMIFS('💸 Expenses'!$F$8:$F$500,'💸 Expenses'!$B$8:$B$500,">="&B25,'💸 Expenses'!$B$8:$B$500,"<"&(B25+1)) | I25: =IFERROR(F25-H25,0) | J25: =IFERROR(I25/F25,0) | L25: Manual Bills
B26: 46178 | C26: Fri | D26: 2495 | E26: 1778 | F26: =IFERROR(D26+E26+G26,0) | G26: 135 | H26: =SUMIFS('💸 Expenses'!$F$8:$F$500,'💸 Expenses'!$B$8:$B$500,">="&B26,'💸 Expenses'!$B$8:$B$500,"<"&(B26+1)) | I26: =IFERROR(F26-H26,0) | J26: =IFERROR(I26/F26,0) | L26: Manual Bills
B27: 46179 | C27: Sat | D27: 580 | E27: 1754 | F27: =IFERROR(D27+E27+G27,0) | H27: =SUMIFS('💸 Expenses'!$F$8:$F$500,'💸 Expenses'!$B$8:$B$500,">="&B27,'💸 Expenses'!$B$8:$B$500,"<"&(B27+1)) | I27: =IFERROR(F27-H27,0) | J27: =IFERROR(I27/F27,0) | L27: Manual Bills
B28: 46180 | C28: Sun | F28: =IFERROR(D28+E28+G28,0) | H28: =SUMIFS('💸 Expenses'!$F$8:$F$500,'💸 Expenses'!$B$8:$B$500,">="&B28,'💸 Expenses'!$B$8:$B$500,"<"&(B28+1)) | I28: =IFERROR(F28-H28,0) | L28: Manual Bills
B29: 46181 | C29: Mon | D29: 1778 | E29: 1850 | F29: =IFERROR(D29+E29+G29,0) | G29: 99 | H29: =SUMIFS('💸 Expenses'!$F$8:$F$500,'💸 Expenses'!$B$8:$B$500,">="&B29,'💸 Expenses'!$B$8:$B$500,"<"&(B29+1)) | I29: =IFERROR(F29-H29,0) | J29: =IFERROR(I29/F29,0) | L29: Manual Bills
B30: 46182 | C30: Tue | D30: 930 | E30: 4480 | F30: =IFERROR(D30+E30+G30,0) | H30: =SUMIFS('💸 Expenses'!$F$8:$F$500,'💸 Expenses'!$B$8:$B$500,">="&B30,'💸 Expenses'!$B$8:$B$500,"<"&(B30+1)) | I30: =IFERROR(F30-H30,0) | J30: =IFERROR(I30/F30,0) | L30: Manual Bills
B31: 46183 | C31: Wed | D31: 2506 | E31: 1759 | F31: =IFERROR(D31+E31+G31,0) | H31: =SUMIFS('💸 Expenses'!$F$8:$F$500,'💸 Expenses'!$B$8:$B$500,">="&B31,'💸 Expenses'!$B$8:$B$500,"<"&(B31+1)) | I31: =IFERROR(F31-H31,0) | J31: =IFERROR(I31/F31,0) | L31: Manual Bills
B32: 46184 | C32: Thu | D32: 2075 | E32: 2091 | F32: =IFERROR(D32+E32+G32,0) | G32: 0 | H32: =SUMIFS('💸 Expenses'!$F$8:$F$500,'💸 Expenses'!$B$8:$B$500,">="&B32,'💸 Expenses'!$B$8:$B$500,"<"&(B32+1)) | I32: =IFERROR(F32-H32,0) | J32: =IFERROR(I32/F32,0) | L32: Cierre 11 Jun + receipts
B33: 46185 | C33: Fri | D33: 2635 | E33: 3435 | F33: =IFERROR(D33+E33+G33,0) | G33: 0 | H33: =SUMIFS('💸 Expenses'!$F$8:$F$500,'💸 Expenses'!$B$8:$B$500,">="&B33,'💸 Expenses'!$B$8:$B$500,"<"&(B33+1)) | I33: =IFERROR(F33-H33,0) | J33: =IFERROR(I33/F33,0) | L33: Cierre 12 Jun + receipts
B34: 46186 | C34: Sat | D34: 1005 | E34: 806 | F34: =IFERROR(D34+E34+G34,0) | G34: 0 | H34: =SUMIFS('💸 Expenses'!$F$8:$F$500,'💸 Expenses'!$B$8:$B$500,">="&B34,'💸 Expenses'!$B$8:$B$500,"<"&(B34+1)) | I34: =IFERROR(F34-H34,0) | J34: =IFERROR(I34/F34,0) | L34: Receipts + Week 4 payroll paid Sat
B35: 46187 | C35: Sun | D35: 0 | E35: 0 | F35: =IFERROR(D35+E35+G35,0) | G35: 0 | H35: =SUMIFS('💸 Expenses'!$F$8:$F$500,'💸 Expenses'!$B$8:$B$500,">="&B35,'💸 Expenses'!$B$8:$B$500,"<"&(B35+1)) | I35: =IFERROR(F35-H35,0) | J35: =IFERROR(I35/F35,0) | L35: CLOSED (Sunday) — market/prep run, no revenue
B36: 46188 | C36: Mon | D36: 2075 | E36: 2348 | F36: =IFERROR(D36+E36+G36,0) | G36: 0 | H36: =SUMIFS('💸 Expenses'!$F$8:$F$500,'💸 Expenses'!$B$8:$B$500,">="&B36,'💸 Expenses'!$B$8:$B$500,"<"&(B36+1)) | I36: =IFERROR(F36-H36,0) | J36: =IFERROR(I36/F36,0) | L36: Cierre 15 Jun + receipts

Sheet 💸 Expenses
A2: 💸 LOKA — EXPENSES TRACKER | E2: Log every cost: ingredients, staff, utilities, supplies…
B5: TODAY | C5: THIS WEEK | D5: THIS MONTH | E5: INGREDIENTS | F5: STAFF | G5: UTILITIES | H5: TODAY TOTAL | I5: WEEK TOTAL
B6: =SUMIFS($F$8:$F$500,$B$8:$B$500,TODAY()) | C6: =SUMIFS($F$8:$F$500,$B$8:$B$500,">="&(TODAY()-WEEKDAY(TODAY(),2)+1),$B$8:$B$500,"<="&(TODAY()-WEEKDAY(TODAY(),2)+7)) | D6: =SUMIFS($F$8:$F$500,$B$8:$B$500,">="&DATE(YEAR(TODAY()),MONTH(TODAY()),1),$B$8:$B$500,"<"&DATE(YEAR(TODAY()),MONTH(TODAY())+1,1)) | E6: =SUMIF($E$8:$E$500,"Ingredients*",$F$8:$F$500) | F6: =SUMIF($E$8:$E$500,"Staff*",$F$8:$F$500) | G6: =SUMIF($E$8:$E$500,"Supplies*",$F$8:$F$500)+SUMIF($E$8:$E$500,"Utilities*",$F$8:$F$500) | H6: =SUMIFS($F$8:$F$500,$B$8:$B$500,TODAY()) | I6: =SUMIFS($F$8:$F$500,$B$8:$B$500,">="&(TODAY()-WEEKDAY(TODAY(),2)+1),$B$8:$B$500,"<="&(TODAY()-WEEKDAY(TODAY(),2)+7))
B7: Date | C7: Description | D7: Supplier | E7: Category | F7: Amount ($) | G7: Paid By | H7: Payment Method | I7: Status | J7: Notes
B8: 46160 | C8: Carne | D8: — | E8: Ingredients - Meat | F8: 420 | G8: Restaurant | H8: Cash | I8: ✅ Paid
B9: 46160 | C9: Basicos | D9: — | E9: Ingredients - Pantry | F9: 1068 | G9: Restaurant | H9: Cash | I9: ✅ Paid
B10: 46160 | C10: Real Pan Services | D10: Real Pan | E10: Ingredients - Bread | F10: 522 | G10: Restaurant | H10: Cash | I10: ✅ Paid
B11: 46160 | C11: Chedruai | D11: Chedraui | E11: Supermarket / General | F11: 129 | G11: Restaurant | H11: Cash | I11: ✅ Paid
B12: 46160 | C12: Vegetables | D12: Abastos | E12: Ingredients - Vegetables | F12: 400 | G12: Restaurant | H12: Cash | I12: ✅ Paid
B13: 46160 | C13: Vegetables | D13: — | E13: Ingredients - Vegetables | F13: 90 | G13: Restaurant | H13: Cash | I13: ✅ Paid
B14: 46161 | C14: Arroz | D14: — | E14: Ingredients - Pantry | F14: 30 | G14: Restaurant | H14: Cash | I14: ✅ Paid
B15: 46162 | C15: Lechuga | D15: — | E15: Ingredients - Vegetables | F15: 65 | G15: Restaurant | H15: Cash | I15: ✅ Paid
B16: 46162 | C16: Tortillas | D16: — | E16: Ingredients - Pantry | F16: 26 | G16: Restaurant | H16: Cash | I16: ✅ Paid
B17: 46162 | C17: Jamon Mexicana | D17: — | E17: Ingredients - Meat | F17: 88 | G17: Restaurant | H17: Cash | I17: ✅ Paid
B18: 46162 | C18: Carne | D18: — | E18: Ingredients - Meat | F18: 1104 | G18: Restaurant | H18: Cash | I18: ✅ Paid
B19: 46162 | C19: Salmon | D19: — | E19: Ingredients - Meat & Fish | F19: 397 | G19: Restaurant | H19: Cash | I19: ✅ Paid
... B46: 46165 | C46: Agua Natural | D46: — | E46: Supplies / Other | F46: 30 | G46: Restaurant | H46: Cash | I46: ✅ Paid
B47: 46165 | C47: John - Saldo Semana | D47: Nomina | E47: Staff - Salary | F47: 3250 | G47: Restaurant | H47: Cash | I47: ✅ Paid | J47: Head Chef — weekly salary Week 1
B48: 46165 | C48: Debi - Limpieza | D48: Nomina | E48: Staff - Salary | F48: 1500 | G48: Restaurant | H48: Cash | I48: ✅ Paid | J48: Cleaning staff — weekly salary Week 1
B49: 46165 | C49: Victor - Mesero (2 dias) | D49: Nomina | E49: Staff - Salary | F49: 666 | G49: Restaurant | H49: Cash | I49: ✅ Paid | J49: Waiter — 2 days salary Week 1
B50: 46165 | C50: Sal Fina (20 x 1 kg) | D50: Costco | E50: Ingredients - Pantry | F50: 408.17 | G50: Restaurant | H50: Card | I50: ✅ Paid | J50: Costco — Sal Fina 20/1KG
B51: 46165 | C51: Coca Cola (24 x 600ml) | D51: Costco | E51: Ingredients - Beverages | F51: 455.23 | G51: Restaurant | H51: Card | I51: ✅ Paid | J51: Costco — discount applied, total $844
B52: 46165 | C52: Leche Deslactosada (12 x 1LT) | D52: Sam's Club | E52: Ingredients - Dairy | F52: 317.13 | G52: Restaurant | H52: Card | I52: ✅ Paid | J52: Sam's Club — reimbursed to Shashirekha, settled
B53: 46165 | C53: Leche Alpura (12 x 1L) | D53: Sam's Club | E53: Ingredients - Dairy | F53: 317.13 | G53: Restaurant | H53: Card | I53: ✅ Paid | J53: Sam's Club — reimbursed to Shashirekha, settled
B54: 46165 | C54: Crema Ácida | D54: Sam's Club | E54: Ingredients - Dairy | F54: 250.63 | G54: Restaurant | H54: Card | I54: ✅ Paid | J54: Sam's Club — reimbursed to Shashirekha, settled
B55: 46165 | C55: Salsa / Tomate (12 x 600ml) | D55: Sam's Club | E55: Ingredients - Pantry | F55: 232.22 | G55: Restaurant | H55: Card | I55: ✅ Paid | J55: Sam's Club — reimbursed to Shashirekha, settled
B56: 46165 | C56: Champiñones (24 x 400ml) | D56: Sam's Club | E56: Ingredients - Vegetables | F56: 218.92 | G56: Restaurant | H56: Card | I56: ✅ Paid | J56: Sam's Club — reimbursed to Shashirekha, settled
B57: 46166 | C57: Guayabas Mediana | D57: Aviles Hernandez | E57: Ingredients - Fruit | F57: 120 | G57: Restaurant | H57: Cash | I57: ✅ Paid
B58: 46166 | C58: Jicamas + Pinas + Melon Chino | D58: El Matamoros | E58: Ingredients - Fruit | F58: 147 | G58: Restaurant | H58: Cash | I58: ✅ Paid
B59: 46166 | C59: Cilantro + Italiana | D59: Oscar Verduras | E59: Ingredients - Vegetables | F59: 100 | G59: Restaurant | H59: Cash | I59: ✅ Paid
B60: 46166 | C60: Habanero + Pepino | D60: Remision Formitec | E60: Ingredients - Vegetables | F60: 90 | G60: Restaurant | H60: Cash | I60: ✅ Paid
B61: 46166 | C61: Betabel (~1.9 kg) | D61: Nota Remision | E61: Ingredients - Vegetables | F61: 78 | G61: Restaurant | H61: Cash | I61: ✅ Paid
B62: 46166 | C62: Jitomate | D62: Brisia y Hermanos | E62: Ingredients - Vegetables | F62: 178 | G62: Restaurant | H62: Cash | I62: ✅ Paid
B63: 46166 | C63: Mango + Sandia | D63: Papayas Maradol | E63: Ingredients - Fruit | F63: 116 | G63: Restaurant | H63: Cash | I63: ✅ Paid
B64: 46166 | C64: Verduras variadas | D64: JP Verduras | E64: Ingredients - Vegetables | F64: 224 | G64: Restaurant | H64: Cash | I64: ✅ Paid
B65: 46166 | C65: Pimiento Morron | D65: Sin factura | E65: Ingredients - Vegetables | F65: 23 | G65: Restaurant | H65: Cash | I65: ✅ Paid | J65: No receipt — Sin factura
B66: 46167 | C66: Pan para Hamburguesa con Ajonjolí + Pan de Caja Arandano | D66: Real Abastos | E66: Ingredients - Bread | F66: 273 | G66: Restaurant | H66: Card | I66: ✅ Paid | J66: Real Sucursal Central de Abastos — 12 pcs hamburger buns + 3x900g bread
B67: 46167 | C67: Limonada / Naranjada / Tamarindo 1LT (18 pcs) | D67: Reca del Bajio | E67: Ingredients - Beverages | F67: 450 | G67: Restaurant | H67: Card | I67: ✅ Paid | J67: Mercado Pago — 6 Limonada + 6 Naranjada + 6 Tamarindo
B68: 46167 | C68: QsoCrema Lala 190g | D68: Chedraui Selecto | E68: Ingredients - Dairy | F68: 32 | G68: Restaurant | H68: Card | I68: ✅ Paid
B69: 46167 | C69: Tortillas Blanca (2.21 kg) | D69: Chedraui Selecto | E69: Ingredients - Pantry | F69: 28.73 | G69: Restaurant | H69: Card | I69: ✅ Paid
...

Sheet 📦 Inventory
A2: 📦 LOKA — INVENTORY | F2: Update stock levels when you receive deliveries or do stock checks
B5: TOTAL ITEMS | D5: ⚠️ LOW STOCK | E5: LOW STOCK # | F5: 🚫 OUT OF STOCK | H5: ALERT COUNT | J5: LAST UPDATED
B6: =COUNTA(B9:B200) | D6: =COUNTIF(J9:J200,"⚠️ LOW STOCK") | E6: =COUNTIF(J9:J200,"⚠️ LOW STOCK")+COUNTIF(J9:J200,"🚫 OUT OF STOCK") | F6: =COUNTIF(J9:J200,"🚫 OUT OF STOCK") | H6: =COUNTIF(J9:J200,"⚠️ LOW STOCK")+COUNTIF(J9:J200,"🚫 OUT OF STOCK") | J6: =TODAY()
B8: Item Name | Category | Unit | Min Stock | Current Stock | Last Ordered | Supplier | Status | Notes
B9: Carne de Res | C9: Ingredients - Meat | D9: kg | E9: 0 | J9: =IF(ISBLANK(F9),"—",IF(F9=0,"🚫 OUT OF STOCK",IF(F9<=E9,"⚠️ LOW STOCK","✅ OK")))
B10: Jamon Mexicano | C10: Ingredients - Meat | D10: kg | E10: 0 | J10: =IF(ISBLANK(F10),"—",IF(F10=0,"🚫 OUT OF STOCK",IF(F10<=E10,"⚠️ LOW STOCK","✅ OK")))
B11: Pollo | C11: Ingredients - Meat | D11: kg | E11: 0 | J11: =IF(ISBLANK(F11),"—",IF(F11=0,"🚫 OUT OF STOCK",IF(F11<=E11,"⚠️ LOW STOCK","✅ OK")))
B12: Chuletas de Carne | C12: Ingredients - Meat | D12: kg | E12: 0 | J12: =IF(ISBLANK(F12),"—",IF(F12=0,"🚫 OUT OF STOCK",IF(F12<=E12,"⚠️ LOW STOCK","✅ OK")))
B13: Costillas de Cerdo | C13: Ingredients - Meat | D13: kg | E13: 0 | J13: =IF(ISBLANK(F13),"—",IF(F13=0,"🚫 OUT OF STOCK",IF(F13<=E13,"⚠️ LOW STOCK","✅ OK")))
B14: Salmon | C14: Ingredients - Meat & Fish | D14: kg | E14: 0 | J14: =IF(ISBLANK(F14),"—",IF(F14=0,"🚫 OUT OF STOCK",IF(F14<=E14,"⚠️ LOW STOCK","✅ OK")))
B15: Filete de Mojarra | C15: Ingredients - Meat & Fish | D15: kg | E15: 0 | J15: =IF(ISBLANK(F15),"—",IF(F15=0,"🚫 OUT OF STOCK",IF(F15<=E15,"⚠️ LOW STOCK","✅ OK")))
B16: Papas | C16: Ingredients - Vegetables | D16: kg | E16: 0 | J16: =IF(ISBLANK(F16),"—",IF(F16=0,"🚫 OUT OF STOCK",IF(F16<=E16,"⚠️ LOW STOCK","✅ OK")))
B17: Lechuga | C17: Ingredients - Vegetables | D17: pcs | E17: 0 | J17: =IF(ISBLANK(F17),"—",IF(F17=0,"🚫 OUT OF STOCK",IF(F17<=E17,"⚠️ LOW STOCK","✅ OK")))
B18: Jitomate | C18: Ingredients - Vegetables | D18: kg | E18: 0 | J18: =IF(ISBLANK(F18),"—",IF(F18=0,"🚫 OUT OF STOCK",IF(F18<=E18,"⚠️ LOW STOCK","✅ OK")))
B19: Cilantro | C19: Ingredients - Vegetables | D19: pcs | E19: 0 | J19: =IF(ISBLANK(F19),"—",IF(F19=0,"🚫 OUT OF STOCK",IF(F19<=E19,"⚠️ LOW STOCK","✅ OK")))
B20: Italiana | C20: Ingredients - Vegetables | D20: pcs | E20: 0 | J20: =IF(ISBLANK(F20),"—",IF(F20=0,"🚫 OUT OF STOCK",IF(F20<=E20,"⚠️ LOW STOCK","✅ OK")))
... B73: Huevo Bachoco | C73: Ingredients - Pantry | D73: pcs | E73: 0 | J73: =IF(ISBLANK(F73),"—",IF(F73=0,"🚫 OUT OF STOCK",IF(F73<=E73,"⚠️ LOW STOCK","✅ OK")))

Sheet 👥 Staff & Payroll
A2: 👥 LOKA — STAFF & PAYROLL | D2: Weekly schedule + auto payroll calculation
A6: STAFF SCHEDULE — Week of: | D6: =TODAY()-WEEKDAY(TODAY(),2)+1
A7: Staff Name | B7: Role | C7: Daily Rate ($) | D7: Mon | E7: Tue | F7: Wed | G7: Thu | H7: Fri | I7: Sat | J7: Sun | K7: Days Worked | L7: Week Pay ($)
A8: John | B8: Head Chef | C8: 625 | D8: Full Day | E8: Full Day | F8: Full Day | G8: Full Day | H8: Full Day | I8: Full Day | J8: Day Off | K8: =COUNTIF(D8:J8,"Full Day") | L8: =K8*C8
A9: Debi | B9: Cleaner | C9: 250 | D9: Full Day | E9: Full Day | F9: Full Day | G9: Full Day | H9: Full Day | I9: Full Day | J9: Day Off | K9: =COUNTIF(D9:J9,"Full Day") | L9: =K9*C9
A10: Victor (INACTIVE) | B10: Mesero — Left after Week 1 | C10: 0 | D10: — | E10: — | F10: — | G10: — | H10: — | I10: — | J10: — | K10: 0 | L10: 0
A11: Judith (RESIGNED) | B11: Mesera — Resigned 7 Jun · paid in full 8 Jun | C11: 0 | D11: — | E11: — | F11: — | G11: — | H11: — | I11: — | J11: — | K11: 0 | L11: 0
A12: Cesar (RESIGNED) | B12: Mesero — Started Tue 9 Jun · Resigned · Week 4 paid in full (5 days) | C12: 0 | D12: — | E12: — | F12: — | G12: — | H12: — | I12: — | J12: — | K12: 0 | L12: 0
A13: Samu | B13: Ayudante / Support | C13: 160 | D13: Full Day | E13: Full Day | F13: Full Day | G13: Full Day | H13: Full Day | I13: Day Off | J13: Day Off | K13: =COUNTIF(D13:J13,"Full Day") | L13: =K13*C13
A20: MONTHLY PAYROLL PROJECTION
A21: Staff Name | B21: Role | C21: Week Pay ($) | D21: x Weeks/Month | E21: Monthly ($) | F21: IMSS / Benefits % | G21: Total Monthly Cost ($) | H21: Notes
A22: =A8 | B22: Head Chef | C22: =L8 | D22: 4 | E22: =C22*D22 | F22: 0.08 | G22: =E22*(1+F22)
A23: =A9 | B23: Cleaner / Limpieza | C23: =L9 | D23: 4 | E23: =C23*D23 | F23: 0.08 | G23: =E23*(1+F23)
A24: =A10 | B24: Mesero (left Wk1) | C24: =L10 | D24: 4 | E24: =C24*D24 | F24: 0.08 | G24: =E24*(1+F24)
A25: =A11 | B25: Mesera (resigned) | C25: =L11 | D25: 4 | E25: =C25*D25 | F25: 0.08 | G25: =E25*(1+F25)
A26: =A12 | B26: Mesero / Waiter | C26: =L12 | D26: 4 | E26: =C26*D26 | F26: 0.08 | G26: =E26*(1+F26)
A27: =A13 | B27: Ayudante / Support | C27: =L13 | D27: 4 | E27: =C27*D27 | F27: 0.08 | G27: =E27*(1+F27)
A28: =A14 | B28: Kitchen Helper | C28: =L14 | D28: 4 | E28: =C28*D28 | F28: 0.08 | G28: =E28*(1+F28)
A29: =A15 | E29: =C29*D29 | G29: =E29*(1+F29)
A30: TOTAL MONTHLY PAYROLL COST | G30: =SUM(G21:G28)
A33: ── WEEKLY FIXED COSTS & BREAK-EVEN TARGETS ──
A34: COST ITEM | B34: WEEKLY ($) | C34: MONTHLY EST. ($) | D34: NOTES
A35: John — Head Chef Salary | B35: 3750 | C35: 15000 | D35: Confirmed weekly rate
A36: Debi — Limpieza Salary | B36: 1500 | C36: 6000 | D36: Confirmed weekly rate
A37: Cesar — Mesero Salary (RESIGNED) | B37: 0 | C37: 0 | D37: Resigned — Week 4 paid in full · removed from forward fixed costs
A38: Samu — Ayudante Salary | B38: 800 | C38: 3200 | D38: Confirmed — $800/week | $160/day | 5 days Mon–Fri | Start 9 Jun 2026
A39: Rent + Maintenance (actual — $20,000/mo) | B39: 5000 | C39: 20000 | D39: Confirmed — $20,000/month actual
A40: Utilities — Electricity + Gas (estimated) | B40: 1000 | C40: 4000 | D40: ⏳ Approx — bills pending · electricity + gas
A41: TOTAL FIXED COSTS (current) | B41: =SUM(B35:B40) | C41: =SUM(C35:C40) | D41: Incl. rent + maintenance + utilities est.
A43: ── MESERO STATUS — ✅ CESAR + SAMU ACTIVE FROM 9 JUN 2026 ──
A44: Judith — Mesera Salary (historical — resigned 7 Jun) | B44: 2000 | C44: 8000 | D44: Confirmed — $2,000/week · $333.33/day · absent days deducted
A45: With Cesar + Samu (✅ ACTIVE from 9 Jun) | B45: 14050 | C45: 23750 | D45: 24550 | E45: 4092 | F45: ✅ NOW ACTIVE — current avg $4,011/day vs break-even $3,959/day | G45: ✅ Cesar $2,000 + Samu $800 — break-even $4,092/day
A47: ── BREAK-EVEN & WEEKLY REVENUE TARGETS ──
A48: SCENARIO | B48: Fixed Costs ($) | C48: Avg Variable Costs ($) | D48: MIN Weekly Revenue ($) | E48: MIN Daily Revenue ($) | F48: Current Avg/Day ($) | G48: STATUS
A49: Without Mesero (NOW) | B49: 11250 | C49: 10500 | D49: 21750 | E49: 3625 | F49: 4011 | G49: ✅ Above break-even — revised down from $3,792 → $3,625/day | H49: ✅ Current scenario — no mesero (Judith resigned 7 Jun)
A50: With Mesero (~$2,250) | B50: 13500 | C50: 10500 | D50: 24000 | E50: 4000 | F50: 4011 | G50: ⚠️ Still below — need +$-11/day when mesero hired | H50: ⏳ Will update when 2 new staff details confirmed (9 Jun)
A51: Safety buffer (+15%) | B51: 11250 | C51: 10500 | D51: 25012 | E51: 4169 | F51: 4011 | G51: Target for healthy buffer: $4,169/day
A53: NOTES:
A54: Variable costs = avg ingredients + supplies per week based on Weeks 1-2 actual data (~$10,500)
A55: Break-even revised: Rent+Maintenance confirmed $20,000/mo · Utilities est. $4,000/mo → Total overhead $24,000/mo
...

Sheet 🚚 Suppliers
A2: 🚚 LOKA — SUPPLIER ORDERS | F2: Track purchase orders from suppliers
B5: TOTAL ORDERS | C5: PENDING | D5: IN TRANSIT | E5: RECEIVED | F5: MONTH SPEND | G5: PENDING VALUE | H5: PENDING COUNT
B6: =COUNTA(C9:C308)-1 | C6: =COUNTIF(K9:K308,"Pending") | D6: =COUNTIF(K9:K308,"In Transit") | E6: =COUNTIF(K9:K308,"Received") | F6: =SUMIF(K9:K308,"Received",J9:J308) | G6: =SUMIF(K9:K308,"Pending",J9:J308) | H6: =COUNTIF(K9:K308,"Pending")+COUNTIF(K9:K308,"In Transit")

Sheet 📋 Supplier Directory
B2: 📋 LOKA — SUPPLIER DIRECTORY
B3: Contact list for all regular suppliers
B6: Supplier Name | C6: Contact / Phone | D6: Products Supplied | E6: Location / Address | F6: Notes
B7: Girigallo | C7: 442-249-4707 | D7: Pollo | E7: Islas Aleutianas 134, Loma Linda, C.P 76070
B8: Alico | C8: 442-796-8876 | D8: Carne de hamburguesa, Papas, Boneless | E8: Cerro de las Campanas 173, Col. Las Americas
B9: Reca (Repartidor) | C9: 442-679-6651 | D9: Aguas Avia / Bebidas | E9: — | F9: Delivery supplier
B10: Toluco | C10: — | D10: Desechables (Plasticos) | E10: Plásticos Desechables el Toluco, C/ 15 de Mayo 189, La Santa Cruz, Centro, 76020 Santiago de Querétaro
B11: Bodega del Queso | C11: 442-114-0827 | D11: Queso, Jamon, Crema | E11: Avenida Universidad 119, Los Cedros, 76165 Santiago de Querétaro, Qro.
B12: Panadería Real | C12: 442-379-1880 | D12: Pan hamburguesa, Mayonesa, Arrachera, Sandwhich | E12: Plaza Capuchinas 149, Central de Abasto, Querétaro | F12: Also supplies at Brisa del Mar area
B13: Etrusca | C13: 442-234-5077 | D13: Sabores de Frappe, Matcha, Taro | E13: Café Etrusca Querétaro, Av. Tecnológico 10-Sur, Niños Héroes, 76010 Santiago de Querétaro
B16: Note: Additional suppliers recorded in expenses — Brisa del Mar, Chedraui, Costco, Real Abastos, OXXO, Pescadería El Faro

Sheet 📈 Monthly P&L
A2: 📈 LOKA — MONTHLY P&L | E2: Revenue & Expense summary — fill monthly totals from Daily Log & Expenses
B6: YEAR: | C6: 2025
C7: 2026

Sheet 📥 Pending Income
B2: LOKA CAFE RESTAURANTE — PENDING INCOME / RECEIVABLES | C2: LOKA CAFE RESTAURANTE — PENDING INCOME / RECEIVABLES | D2: LOKA CAFE RESTAURANTE — PENDING INCOME / RECEIVABLES | E2: LOKA CAFE RESTAURANTE — PENDING INCOME / RECEIVABLES | F2: LOKA CAFE RESTAURANTE — PENDING INCOME / RECEIVABLES | G2: LOKA CAFE RESTAURANTE — PENDING INCOME / RECEIVABLES | H2: LOKA CAFE RESTAURANTE — PENDING INCOME / RECEIVABLES | I2: LOKA CAFE RESTAURANTE — PENDING INCOME / RECEIVABLES
B4: Date Served | C4: Client | D4: Description | E4: Qty | F4: Unit Price ($) | G4: Total Amount ($) | H4: Status | I4: Notes
B5: 21-May-2026 | C5: Government Finances Dept. | D5: Catering order — 25 plates | E5: 25 | F5: 140 | G5: 3500 | H5: ⏳ NOT YET PAID | I5: Awaiting payment — follow up with client
B7: TOTAL PENDING | G7: 3500

Sheet 📊 Weekly Closing
B2: 📊 LOKA — WEEKLY CLOSING & PROPINAS
B3: Every Sunday night: enter closing balances to calculate propinas pool for the week
B6: ── WEEK 1 CLOSING SUMMARY (Sunday 25 May 2026) ──
B7: METRIC | D7: VALUE ($) | F7: NOTES
B8: Total Week Revenue (18–23 May) | D8: 24484 | F8: Card $12,386 + Cash $12,098
B9: Total Week Expenses (incl. propinas) | D9: 18157 | F9: All costs 18–24 May
B10: → Propinas Distributed | D10: 1030 | F10: John $515 + Debi $515
B11: → Propinas Pending | D11: 168 | F11: Victor $168 — yet to pay
B12: → Total Propinas | D12: 1198 | F12: To be paid from closing balance
B13: Total Expenses EXCL. Propinas | D13: 16959 | F13: Operating costs only
B14: Net Income (excl. propinas) | D14: 7525 | F14: =Revenue - Expenses excl. propinas
B16: ── SUNDAY NIGHT CLOSING BALANCE ──
B17: Mercado Pago Balance | D17: 5553 | F17: Incl. MP commission already deducted
B18: Cash in Hand | D18: 3170 | F18: Physical cash end of week
B19: Total Closing Balance | D19: 8723 | F19: MP + Cash
B21: ── PROPINAS CALCULATION ──
B22: Propinas Pool | D22: 1198 | F22: =Closing Balance - Net (excl. propinas)
B24: ── PROPINAS DISTRIBUTION ──
B25: Staff Name | C25: Role | D25: Days Worked | F25: Propinas Amount ($) | G25: Paid?
B26: John | C26: Head Chef | D26: 6 | F26: 515 | G26: ✅ Paid
B27: Debi | C27: Limpieza | D27: 6 | F27: 515 | G27: ✅ Paid
B28: Victor | C28: Mesero | D28: 2 | F28: 168 | G28: ⏳ PENDING
B29: TOTAL PROPINAS | F29: 1198
B30: Remaining after distribution | F30: 0 | G30: ← Should be 0 or rolled to next week
B34: ── WEEK 2 CLOSING SUMMARY (Sunday 31 May 2026) ──
B35: METRIC | C35: VALUE ($) | D35: NOTES
B36: Total Week Revenue (25–30 May) | D36: Fill from Daily Log
B37: Total Week Expenses (incl. propinas)
B38: → Propinas Distributed
B39: → Propinas Pending
B40: → Total Propinas
B41: Total Expenses EXCL. Propinas
B42: Net Income (excl. propinas)
B44: ── SUNDAY NIGHT CLOSING BALANCE ──
B45: Mercado Pago Balance | D45: Enter Sunday night amount
B46: Cash in Hand | D46: Enter Sunday night amount
B47: Total Closing Balance | D47: =MP + Cash
B49: ── PROPINAS CALCULATION ──
B50: Propinas Pool | D50: =Closing Balance - Net (excl. propinas)
B52: ── PROPINAS DISTRIBUTION ──
...
