Workbook

Sheet Capital & Ownership
B1: LOKA — CAPITAL, OWNERSHIP & PRE-OPENING EXPENSES
B2: Last updated: 18 Sep 2026 | Capital, Acquisition, Pre-Opening, Renovation CapEx & Operations↔Capital
B4: A. OWNERSHIP STRUCTURE
B5: Owner | C5: Share % | D5: Capital ($) | E5: Expenses ($) | F5: Remaining ($) | G5: Role / Notes
B6: Lohith Reddy | C6: 0.5 | D6: 300000 | E6: =D67 | F6: =D6-E6 | G6: 50% — Managing Partner
B7: Kashigoud Patil | C7: 0.3 | D7: 180000 | E7: =D52 | F7: =D7-E7 | G7: 30% — Partner
B8: Shashirekha Basavaraju | C8: 0.2 | D8: 120000 | E8: =D82 | F8: =D8-E8 | G8: 20% — Partner
B9: TOTAL | C9: =SUM(C6:C8) | D9: =SUM(D6:D8) | E9: =SUM(E6:E8) | F9: =SUM(F6:F8)
B11: B. RESTAURANT ACQUISITION — $390,000 TOTAL
B12: Description | C12: Date | D12: Amount ($) | E12: Paid By | F12: Status | G12: Notes
B13: TOTAL Purchase Price — Previous Owners | D13: 390000 | E13: All Partners | F13: ⚠️ PARTIALLY PAID — $2,235 remaining | G13: Full acquisition amount
B14: Advance Payment (paid by Lohith) | D14: 5000 | E14: Lohith Reddy | F14: ✅ PAID | G14: Advance to previous owners
B15: Payment to Previous Owners | C15: 46176 | D15: 95000 | E15: Lohith Reddy | F15: ✅ PAID | G15: Paid from restaurant operating balance — 3 Jun 2026
B16: Payment to Previous Owner — Account 1 | C16: 46177 | D16: 8000 | E16: Lohith Reddy | F16: ✅ PAID | G16: Capital payment — from main budget — transferred to different accounts
B17: Payment to Previous Owner — Account 2 | C17: 46177 | D17: 4500 | E17: Lohith Reddy | F17: ✅ PAID | G17: Capital payment — from main budget — transferred to different account
B18: Payment to Previous Owner — Account 3 | C18: 46177 | D18: 15000 | E18: Lohith Reddy | F18: ✅ PAID | G18: Capital payment — from main budget — transferred to different accounts
B19: Payment to Previous Owner — Account 4 | C19: 46177 | D19: 10000 | E19: Lohith Reddy | F19: ✅ PAID | G19: Capital payment — from main budget — transferred to different accounts
B20: Payment to Previous Owner — Account 5 | C20: 46177 | D20: 44000 | E20: Lohith Reddy | F20: ✅ PAID | G20: Capital payment — from main budget — transferred to different accounts
B21: Payment to Previous Owner — Account 6 | C21: 46177 | D21: 44000 | E21: Lohith Reddy | F21: ✅ PAID | G21: Capital payment — from main budget — transferred to different accounts
B22: Payment to Previous Owner — Jun 5 | C22: 46178 | D22: 30000 | E22: Lohith Reddy | F22: ✅ PAID | G22: Transfer — 5 Jun 2026
B23: Payment to Previous Owners — Jun 19 (a) | C23: 46192 | D23: 30000 | E23: Lohith Reddy | F23: ✅ PAID | G23: Capital payment to previous owners — 19 Jun 2026
B24: Payment to Previous Owners — Jun 19 (b) | C24: 46192 | D24: 20735 | E24: Lohith Reddy | F24: ✅ PAID | G24: Capital payment to previous owners — 19 Jun 2026
B25: Electricity Bill (Mar–May CFE) — paid by Lohith for Previous Owners | C25: 46190 | D25: 15530 | E25: Lohith Reddy | F25: ✅ OFFSET vs balance | G25: Prev owners’ liability (pre-handover). Deducted from acquisition balance owed to them.
B26: Payment to Previous Owners — Jun 22 | C26: 46195 | D26: 60000 | E26: Lohith Reddy | F26: ✅ PAID | G26: Capital payment to previous owners — 22 Jun 2026
B27: Additional Payment to Previous Owners — Jun 30 | C27: 46203 | D27: 6000 | E27: Lohith Reddy | F27: ✅ PAID | G27: Additional capital payment to previous owners — 30 Jun 2026 (part of $16k transfer; rent portion logged separately)
B31: Balance Remaining | D31: =D13-SUM(D14:D30) | E31: — | F31: ⏳ PENDING | G31: $390,000 − $372,235 paid (Jun 3–30) − $15,530 electricity offset = $2,235 remaining
B33: PAYMENT BREAKDOWN — How the $390,000 will be funded
B34: Source | C34: From | D34: Amount ($) | E34: Toward % | F34: Cumulative | G34: Notes
B35: Kashigoud Transfer to Lohith | C35: Kashigoud Patil | D35: 125000 | E35: =D35/390000 | F35: =D35 | G35: Full Kashi transfer
B36: Shashirekha Transfer to Lohith | C36: Shashirekha B. | D36: 100000 | E36: =D36/390000 | F36: =D35+D36 | G36: Full Shashi transfer
B37: Lohith Reddy (own funds) | C37: Lohith Reddy | D37: =390000-D35-D36 | E37: =D37/390000 | F37: =D35+D36+D37 | G37: Balance from Lohith
B38: Advance Already Paid | C38: Lohith Reddy | D38: 5000 | E38: =D38/390000 | F38: Paid ✅ | G38: Already paid
B40: C. PRE-OPENING EXPENSES — KASHIGOUD PATIL
B41: Description | C41: Date | D41: Amount ($) | E41: Paid To | F41: Category | G41: Notes
B42: Transfer to Lohith Reddy (capital allocation) | D42: 145000 | E42: Bank → Lohith | F42: Internal Transfer | G42: For acquisition & expenses; $125,000 initial + $20,000 transferred 29 Jun 2026 = $145,000
B43: Soft Restaurant License & Tools | D43: 15195 | E43: Soft App | F43: Software / License | G43: POS + mgmt tools
B44: Mercado Pago Terminal | D44: 500 | E44: Soft App / MP | F44: POS Hardware | G44: MP card reader terminal fee
B45: Camera Cloud Recording — 7 Day Continuous (28 May) | C45: 46170 | D45: 436.12 | E45: Kashigoud Patil (VISA ••••9193) | F45: Technology / Security | G45: Shenzhen Tange — cloud CCTV recording 1yr — US$23.90 = MXN $436.12
B46: Camera Cloud Recording — 7 Day Continuous (29 May) | C46: 46171 | D46: 437.22 | E46: Kashigoud Patil (VISA ••••9193) | F46: Technology / Security | G46: Shenzhen Tange — cloud CCTV recording 1yr — US$23.90 = MXN $437.22
B52: KASHIGOUD TOTAL | D52: =SUM(D42:D51)
...

Sheet 📊 Dashboard
A2: 🍽️ LOKA Cafe Restaurante | H2: Restaurant Manager — powered by Soft + Excel
B5: 📌 HOW TO USE: ① Each update, go to 📅 Daily Log → enter Date + Revenue + Orders from Soft App ② Fill 💸 Expenses for costs paid ③ Update 📦 Inventory when stock changes ④ This dashboard updates automatically
B7: 💰 REVENUE (auto-pulled from Daily Log)
B9: TODAY'S REVENUE | D9: WEEK REVENUE | F9: MONTH REVENUE | H9: TODAY'S EXPENSES | J9: TODAY'S NET PROFIT | L9: AVG TICKET
B10: ='📅 Daily Log'!F6 | D10: ='📅 Daily Log'!N6 | F10: ='📅 Daily Log'!O6 | H10: ='📅 Daily Log'!H6 | J10: ='📅 Daily Log'!I6 | L10: =IFERROR('📅 Daily Log'!F6/'📅 Daily Log'!G6,0)
B14: 📊 OPERATIONS
B16: TODAY'S ORDERS | D16: WEEK ORDERS | F16: PROFIT MARGIN % | H16: LOW STOCK ITEMS | J16: WEEK EXPENSES | L16: PENDING ORDERS
B17: ='📅 Daily Log'!G6 | D17: =IFERROR(SUMPRODUCT((ISNUMBER('📅 Daily Log'!$B$8:$B$5000))*('📅 Daily Log'!$B$8:$B$5000>=TODAY()-MOD(TODAY()-2,7))*('📅 Daily Log'!$B$8:$B$5000<TODAY()-MOD(TODAY()-2,7)+7)*IF(ISNUMBER('📅 Daily Log'!$G$8:$G$5000),'📅 Daily Log'!$G$8:$G$5000,0)),0) | F17: =IFERROR('📅 Daily Log'!J6,0) | H17: ='📦 Inventory'!H5 | J17: ='📅 Daily Log'!P6 | L17: ='🚚 Suppliers'!H5
B21: 📅 LAST 10 DAYS (from Daily Log — updates automatically)
B22: Date | C22: Day | D22: Revenue ($) | E22: Orders | F22: Avg Ticket | G22: Expenses ($) | H22: Net Profit ($) | I22: Margin % | J22: Notes | K22: vs Prev Day
B23: ='📅 Daily Log'!B8 | C23: ='📅 Daily Log'!F8 | D23: ='📅 Daily Log'!G8 | E23: =IFERROR('📅 Daily Log'!F8/'📅 Daily Log'!G8,0) | F23: ='📅 Daily Log'!H8 | G23: ='📅 Daily Log'!I8 | H23: ='📅 Daily Log'!J8 | I23: ='📅 Daily Log'!K8 | J23: ='📅 Daily Log'!K8 | K23: —
B24: ='📅 Daily Log'!B9 | C24: ='📅 Daily Log'!F9 | D24: ='📅 Daily Log'!G9 | E24: =IFERROR('📅 Daily Log'!F9/'📅 Daily Log'!G9,0) | F24: ='📅 Daily Log'!H9 | G24: ='📅 Daily Log'!I9 | H24: ='📅 Daily Log'!J9 | I24: ='📅 Daily Log'!K9 | J24: ='📅 Daily Log'!K9 | K24: =IFERROR(IF(D24>D23,"▲ +"&TEXT(D24-D23,"$#,##0"),IF(D24<D23,"▼ "&TEXT(D24-D23,"$#,##0"),"— same")),"")
B25: ='📅 Daily Log'!B10 | C25: ='📅 Daily Log'!F10 | D25: ='📅 Daily Log'!G10 | E25: =IFERROR('📅 Daily Log'!F10/'📅 Daily Log'!G10,0) | F25: ='📅 Daily Log'!H10 | G25: ='📅 Daily Log'!I10 | H25: ='📅 Daily Log'!J10 | I25: ='📅 Daily Log'!K10 | J25: ='📅 Daily Log'!K10 | K25: =IFERROR(IF(D25>D24,"▲ +"&TEXT(D25-D24,"$#,##0"),IF(D25<D24,"▼ "&TEXT(D25-D24,"$#,##0"),"— same")),"")
B26: ='📅 Daily Log'!B11 | C26: ='📅 Daily Log'!F11 | D26: ='📅 Daily Log'!G11 | E26: =IFERROR('📅 Daily Log'!F11/'📅 Daily Log'!G11,0) | F26: ='📅 Daily Log'!H11 | G26: ='📅 Daily Log'!I11 | H26: ='📅 Daily Log'!J11 | I26: ='📅 Daily Log'!K11 | J26: ='📅 Daily Log'!K11 | K26: =IFERROR(IF(D26>D25,"▲ +"&TEXT(D26-D25,"$#,##0"),IF(D26<D25,"▼ "&TEXT(D26-D25,"$#,##0"),"— same")),"")
B27: ='📅 Daily Log'!B12 | C27: ='📅 Daily Log'!F12 | D27: ='📅 Daily Log'!G12 | E27: =IFERROR('📅 Daily Log'!F12/'📅 Daily Log'!G12,0) | F27: ='📅 Daily Log'!H12 | G27: ='📅 Daily Log'!I12 | H27: ='📅 Daily Log'!J12 | I27: ='📅 Daily Log'!K12 | J27: ='📅 Daily Log'!K12 | K27: =IFERROR(IF(D27>D26,"▲ +"&TEXT(D27-D26,"$#,##0"),IF(D27<D26,"▼ "&TEXT(D27-D26,"$#,##0"),"— same")),"")
B28: ='📅 Daily Log'!B13 | C28: ='📅 Daily Log'!F13 | D28: ='📅 Daily Log'!G13 | E28: =IFERROR('📅 Daily Log'!F13/'📅 Daily Log'!G13,0) | F28: ='📅 Daily Log'!H13 | G28: ='📅 Daily Log'!I13 | H28: ='📅 Daily Log'!J13 | I28: ='📅 Daily Log'!K13 | J28: ='📅 Daily Log'!K13 | K28: =IFERROR(IF(D28>D27,"▲ +"&TEXT(D28-D27,"$#,##0"),IF(D28<D27,"▼ "&TEXT(D28-D27,"$#,##0"),"— same")),"")
B29: ='📅 Daily Log'!B14 | C29: ='📅 Daily Log'!F14 | D29: ='📅 Daily Log'!G14 | E29: =IFERROR('📅 Daily Log'!F14/'📅 Daily Log'!G14,0) | F29: ='📅 Daily Log'!H14 | G29: ='📅 Daily Log'!I14 | H29: ='📅 Daily Log'!J14 | I29: ='📅 Daily Log'!K14 | J29: ='📅 Daily Log'!K14 | K29: =IFERROR(IF(D29>D28,"▲ +"&TEXT(D29-D28,"$#,##0"),IF(D29<D28,"▼ "&TEXT(D29-D28,"$#,##0"),"— same")),"")
B30: ='📅 Daily Log'!B15 | C30: ='📅 Daily Log'!F15 | D30: ='📅 Daily Log'!G15 | E30: =IFERROR('📅 Daily Log'!F15/'📅 Daily Log'!G15,0) | F30: ='📅 Daily Log'!H15 | G30: ='📅 Daily Log'!I15 | H30: ='📅 Daily Log'!J15 | I30: ='📅 Daily Log'!K15 | J30: ='📅 Daily Log'!K15 | K30: =IFERROR(IF(D30>D29,"▲ +"&TEXT(D30-D29,"$#,##0"),IF(D30<D29,"▼ "&TEXT(D30-D29,"$#,##0"),"— same")),"")
B31: ='📅 Daily Log'!B16 | C31: ='📅 Daily Log'!F16 | D31: ='📅 Daily Log'!G16 | E31: =IFERROR('📅 Daily Log'!F16/'📅 Daily Log'!G16,0) | F31: ='📅 Daily Log'!H16 | G31: ='📅 Daily Log'!I16 | H31: ='📅 Daily Log'!J16 | I31: ='📅 Daily Log'!K16 | J31: ='📅 Daily Log'!K16 | K31: =IFERROR(IF(D31>D30,"▲ +"&TEXT(D31-D30,"$#,##0"),IF(D31<D30,"▼ "&TEXT(D31-D30,"$#,##0"),"— same")),"")
B32: ='📅 Daily Log'!B17 | C32: ='📅 Daily Log'!F17 | D32: ='📅 Daily Log'!G17 | E32: =IFERROR('📅 Daily Log'!F17/'📅 Daily Log'!G17,0) | F32: ='📅 Daily Log'!H17 | G32: ='📅 Daily Log'!I17 | H32: ='📅 Daily Log'!J17 | I32: ='📅 Daily Log'!K17 | J32: ='📅 Daily Log'!K17 | K32: =IFERROR(IF(D32>D31,"▲ +"&TEXT(D32-D31,"$#,##0"),IF(D32<D31,"▼ "&TEXT(D32-D31,"$#,##0"),"— same")),"")
B34: ⚠️ INVENTORY ALERTS (from Inventory sheet)
B35: Ingredient | F35: Min Level | H35: Status | J35: Action Needed
B36: ='📦 Inventory'!B9 | E36: ='📦 Inventory'!E9 | G36: ='📦 Inventory'!F9 | I36: ='📦 Inventory'!J9 | K36: =IF('📦 Inventory'!E9=0,"🚫 Order immediately",IF('📦 Inventory'!E9<='📦 Inventory'!F9,"⚠️ Reorder soon","✅ OK"))
B37: ='📦 Inventory'!B10 | E37: ='📦 Inventory'!E10 | G37: ='📦 Inventory'!F10 | I37: ='📦 Inventory'!J10 | K37: =IF('📦 Inventory'!E10=0,"🚫 Order immediately",IF('📦 Inventory'!E10<='📦 Inventory'!F10,"⚠️ Reorder soon","✅ OK"))
B38: ='📦 Inventory'!B11 | E38: ='📦 Inventory'!E11 | G38: ='📦 Inventory'!F11 | I38: ='📦 Inventory'!J11 | K38: =IF('📦 Inventory'!E11=0,"🚫 Order immediately",IF('📦 Inventory'!E11<='📦 Inventory'!F11,"⚠️ Reorder soon","✅ OK"))
B39: ='📦 Inventory'!B12 | E39: ='📦 Inventory'!E12 | G39: ='📦 Inventory'!F12 | I39: ='📦 Inventory'!J12 | K39: =IF('📦 Inventory'!E12=0,"🚫 Order immediately",IF('📦 Inventory'!E12<='📦 Inventory'!F12,"⚠️ Reorder soon","✅ OK"))
B40: ='📦 Inventory'!B13 | E40: ='📦 Inventory'!E13 | G40: ='📦 Inventory'!F13 | I40: ='📦 Inventory'!J13 | K40: =IF('📦 Inventory'!E13=0,"🚫 Order immediately",IF('📦 Inventory'!E13<='📦 Inventory'!F13,"⚠️ Reorder soon","✅ OK"))
B42: 💼 CAPITAL & ACQUISITION STATUS — live from Capital & Ownership sheet
B44: TOTAL BUDGET | D44: TOTAL CASH OUT | F44: REMAINING BUDGET | H44: ACQUISITION PRICE | J44: ADVANCE PAID | L44: BALANCE PENDING
B45: ='Capital & Ownership'!C75 | D45: ='Capital & Ownership'!C86 | F45: ='Capital & Ownership'!C87 | H45: ='Capital & Ownership'!C76 | J45: ='Capital & Ownership'!C77 | L45: ='Capital & Ownership'!C78
B46: All 3 partners | D46: Excl. internal transfers | F46: Available for operations | H46: To previous owners | J46: ✅ Paid by Lohith | L46: ⏳ Outstanding
B48: 👥 OWNER CAPITAL SUMMARY
B49: OWNER | D49: SHARE % | F49: CAPITAL ($) | G49: ROLE | H49: EXPENSES ($) | J49: REMAINING ($) | L49: % SPENT
B50: ='Capital & Ownership'!B6 | D50: ='Capital & Ownership'!C6 | F50: ='Capital & Ownership'!D6 | G50: 50% — Managing Partner | H50: ='Capital & Ownership'!E6 | J50: ='Capital & Ownership'!F6 | L50: =IFERROR('Capital & Ownership'!E6/'Capital & Ownership'!D6,0)
B51: ='Capital & Ownership'!B7 | D51: ='Capital & Ownership'!C7 | F51: ='Capital & Ownership'!D7 | G51: 30% — Partner | H51: ='Capital & Ownership'!E7 | J51: ='Capital & Ownership'!F7 | L51: =IFERROR('Capital & Ownership'!E7/'Capital & Ownership'!D7,0)
B52: ='Capital & Ownership'!B8 | D52: ='Capital & Ownership'!C8 | F52: ='Capital & Ownership'!D8 | G52: 20% — Partner | H52: ='Capital & Ownership'!E8 | J52: ='Capital & Ownership'!F8 | L52: =IFERROR('Capital & Ownership'!E8/'Capital & Ownership'!D8,0)
B53: TOTAL | D53: ='Capital & Ownership'!C9 | F53: ='Capital & Ownership'!D9 | H53: ='Capital & Ownership'!E9 | J53: ='Capital & Ownership'!F9 | L53: =IFERROR('Capital & Ownership'!E9/'Capital & Ownership'!D9,0)
B55: 🧾 PRE-OPENING EXPENSES BREAKDOWN
B56: EXPENSE ITEM | E56: PAID BY | G56: AMOUNT ($) | I56: CATEGORY | K56: STATUS
B57: ='Capital & Ownership'!B13 | E57: All Partners | G57: ='Capital & Ownership'!D13 | I57: Acquisition | K57: ⚠️ Not Fully Paid
...

Sheet 📅 Daily Log
A2: 📅 LOKA — DAILY LOG | I2: Enter 2 values from Soft App each day → everything else calculates
B5: ✏️ INSTRUCTIONS: Each time you open this file, add a new row below. Fill only the BLUE cells: 📌 Date | 💰 Revenue (from Soft App end-of-day report) | 🛒 Orders (from Soft App) | 📝 Notes (optional). All other columns calculate automatically.
F6: =SUMIFS($D$8:$D$5000,$B$8:$B$5000,TODAY())+SUMIFS($E$8:$E$5000,$B$8:$B$5000,TODAY())+SUMIFS($G$8:$G$5000,$B$8:$B$5000,TODAY())+SUMIFS($U$8:$U$5000,$B$8:$B$5000,TODAY())+SUMIFS($Y$8:$Y$5000,$B$8:$B$5000,TODAY()) -> 2325 | G6: =SUMIFS($G$8:$G$5000,$B$8:$B$5000,TODAY()) -> 0 | H6: =SUMIFS($H$8:$H$5000,$B$8:$B$5000,TODAY()) -> 1979 | I6: =F6-H6 -> 346 | J6: =IFERROR(I6/F6,0) -> 0.148817 | M6: =SUMIFS($F$8:$F$5000,$B$8:$B$5000,">="&(TODAY()-WEEKDAY(TODAY(),2)+1),$B$8:$B$5000,"<"&(TODAY()-WEEKDAY(TODAY(),2)+8)) -> 26526 | N6: =SUMIFS($F$8:$F$5000,$B$8:$B$5000,">="&(TODAY()-WEEKDAY(TODAY(),2)+1),$B$8:$B$5000,"<"&(TODAY()-WEEKDAY(TODAY(),2)+8)) -> 26526 | O6: =SUMIFS($F$8:$F$5000,$B$8:$B$5000,">="&DATE(YEAR(TODAY()),MONTH(TODAY()),1),$B$8:$B$5000,"<"&DATE(YEAR(TODAY()),MONTH(TODAY())+1,1)) -> 71620 | P6: =SUMIFS('💸 Expenses'!$F$8:$F$5000,'💸 Expenses'!$B$8:$B$5000,">="&(TODAY()-WEEKDAY(TODAY(),2)+1),'💸 Expenses'!$B$8:$B$5000,"<"&(TODAY()-WEEKDAY(TODAY(),2)+8)) -> 5433 | Q6: =M6-P6 -> 21093
B7: Date | C7: Day | D7: Card / Mercado Pago ($) | E7: Cash ($) | F7: Total Revenue ($) | G7: Transfer ($) | H7: Expenses $ | I7: Net Profit $ | J7: Margin % | K7: Notes | L7: Source | M7: WEEK PROFIT | N7: CUMUL. REVENUE | O7: MONTH REVENUE | P7: Week Expenses | Q7: Week Profit | R7: MP Comm $ | S7: MP Rate | T7: 0.0406 | U7: Soft Rest Card $ | V7: Soft Comm $ | W7: Soft Rate | X7: 0.0205 | Y7: BBVA Card $ | Z7: BBVA Comm $ | AA7: BBVA Rate | AB7: 0.019
B8: 46160 | C8: Mon | D8: 2229 | E8: 1460 | F8: =IFERROR(D8+E8+G8+U8+Y8,0) -> 3689 | H8: =SUMIFS('💸 Expenses'!$F$8:$F$5000,'💸 Expenses'!$B$8:$B$5000,">="&B8,'💸 Expenses'!$B$8:$B$5000,"<"&(B8+1)) -> 2629 | I8: =IFERROR(F8-H8,0) -> 1060 | J8: =IFERROR(I8/F8,0) -> 0.287341 | L8: Manual Bills | R8: =IFERROR(D8*$T$7,0) -> 90.5
B9: 46161 | C9: Tue | D9: 2125 | E9: 1729 | F9: =IFERROR(D9+E9+G9+U9+Y9,0) -> 3854 | H9: =SUMIFS('💸 Expenses'!$F$8:$F$5000,'💸 Expenses'!$B$8:$B$5000,">="&B9,'💸 Expenses'!$B$8:$B$5000,"<"&(B9+1)) -> 30 | I9: =IFERROR(F9-H9,0) -> 3824 | J9: =IFERROR(I9/F9,0) -> 0.992216 | L9: Manual Bills | R9: =IFERROR(D9*$T$7,0) -> 86.27
B10: 46162 | C10: Wed | D10: 1459 | E10: 2665 | F10: =IFERROR(D10+E10+G10+U10+Y10,0) -> 4124 | H10: =SUMIFS('💸 Expenses'!$F$8:$F$5000,'💸 Expenses'!$B$8:$B$5000,">="&B10,'💸 Expenses'!$B$8:$B$5000,"<"&(B10+1)) -> 3777 | I10: =IFERROR(F10-H10,0) -> 347 | J10: =IFERROR(I10/F10,0) -> 0.084142 | L10: Manual Bills | R10: =IFERROR(D10*$T$7,0) -> 59.24
B11: 46163 | C11: Thu | D11: 2570 | E11: 2163 | F11: =IFERROR(D11+E11+G11+U11+Y11,0) -> 4733 | H11: =SUMIFS('💸 Expenses'!$F$8:$F$5000,'💸 Expenses'!$B$8:$B$5000,">="&B11,'💸 Expenses'!$B$8:$B$5000,"<"&(B11+1)) -> 2434 | I11: =IFERROR(F11-H11,0) -> 2299 | J11: =IFERROR(I11/F11,0) -> 0.485738 | L11: Manual Bills | R11: =IFERROR(D11*$T$7,0) -> 104.34
B12: 46164 | C12: Fri | D12: 1959 | E12: 2323 | F12: =IFERROR(D12+E12+G12+U12+Y12,0) -> 4282 | H12: =SUMIFS('💸 Expenses'!$F$8:$F$5000,'💸 Expenses'!$B$8:$B$5000,">="&B12,'💸 Expenses'!$B$8:$B$5000,"<"&(B12+1)) -> 1457 | I12: =IFERROR(F12-H12,0) -> 2825 | J12: =IFERROR(I12/F12,0) -> 0.659738 | L12: Manual Bills | R12: =IFERROR(D12*$T$7,0) -> 79.54
B13: 46165 | C13: Sat | D13: 2044 | E13: 1758 | F13: =IFERROR(D13+E13+G13+U13+Y13,0) -> 3802 | H13: =SUMIFS('💸 Expenses'!$F$8:$F$5000,'💸 Expenses'!$B$8:$B$5000,">="&B13,'💸 Expenses'!$B$8:$B$5000,"<"&(B13+1)) -> 7755.43 | I13: =IFERROR(F13-H13,0) -> -3953.43 | J13: =IFERROR(I13/F13,0) -> -1.039829 | K13: Payroll week — John $3,250 + Debi $1,500 + Victor $666 + Tips $1,198 | L13: Manual Bills | R13: =IFERROR(D13*$T$7,0) -> 82.99
B14: 46166 | C14: Sun | E14: 1198 | F14: =IFERROR(D14+E14+G14+U14+Y14,0) -> 1198 | H14: =SUMIFS('💸 Expenses'!$F$8:$F$5000,'💸 Expenses'!$B$8:$B$5000,">="&B14,'💸 Expenses'!$B$8:$B$5000,"<"&(B14+1)) -> 1076 | I14: =IFERROR(F14-H14,0) -> 122 | J14: =IFERROR(I14/F14,0) -> 0.101836 | K14: 🔴 CLOSED — Sunday. Expenses are prep purchases for the week ahead. | L14: Manual Bills | R14: =IFERROR(D14*$T$7,0) -> 0
B15: 46167 | C15: Mon | D15: 2106 | E15: 1624 | F15: =IFERROR(D15+E15+G15+U15+Y15,0) -> 3730 | H15: =SUMIFS('💸 Expenses'!$F$8:$F$5000,'💸 Expenses'!$B$8:$B$5000,">="&B15,'💸 Expenses'!$B$8:$B$5000,"<"&(B15+1)) -> 3021.45 | I15: =IFERROR(F15-H15,0) -> 708.55 | J15: =IFERROR(I15/F15,0) -> 0.18996 | L15: Manual Bills | R15: =IFERROR(D15*$T$7,0) -> 85.5
B16: 46168 | C16: Tue | D16: 1909 | E16: 2355 | F16: =IFERROR(D16+E16+G16+U16+Y16,0) -> 4264 | H16: =SUMIFS('💸 Expenses'!$F$8:$F$5000,'💸 Expenses'!$B$8:$B$5000,">="&B16,'💸 Expenses'!$B$8:$B$5000,"<"&(B16+1)) -> 1191.6 | I16: =IFERROR(F16-H16,0) -> 3072.4 | J16: =IFERROR(I16/F16,0) -> 0.720544 | L16: Manual Bills | R16: =IFERROR(D16*$T$7,0) -> 77.51
B17: 46169 | C17: Wed | D17: 1956 | E17: 1665 | F17: =IFERROR(D17+E17+G17+U17+Y17,0) -> 3621 | H17: =SUMIFS('💸 Expenses'!$F$8:$F$5000,'💸 Expenses'!$B$8:$B$5000,">="&B17,'💸 Expenses'!$B$8:$B$5000,"<"&(B17+1)) -> 1073.22 | I17: =IFERROR(F17-H17,0) -> 2547.78 | J17: =IFERROR(I17/F17,0) -> 0.703612 | L17: Manual Bills | R17: =IFERROR(D17*$T$7,0) -> 79.41
B18: 46170 | C18: Thu | D18: 1501 | E18: 2569 | F18: =IFERROR(D18+E18+G18+U18+Y18,0) -> 4070 | H18: =SUMIFS('💸 Expenses'!$F$8:$F$5000,'💸 Expenses'!$B$8:$B$5000,">="&B18,'💸 Expenses'!$B$8:$B$5000,"<"&(B18+1)) -> 1931.34 | I18: =IFERROR(F18-H18,0) -> 2138.66 | J18: =IFERROR(I18/F18,0) -> 0.525469 | L18: Manual Bills | R18: =IFERROR(D18*$T$7,0) -> 60.94
B19: 46171 | C19: Fri | D19: 3369 | E19: 2717 | F19: =IFERROR(D19+E19+G19+U19+Y19,0) -> 6086 | H19: =SUMIFS('💸 Expenses'!$F$8:$F$5000,'💸 Expenses'!$B$8:$B$5000,">="&B19,'💸 Expenses'!$B$8:$B$5000,"<"&(B19+1)) -> 257.29 | I19: =IFERROR(F19-H19,0) -> 5828.71 | J19: =IFERROR(I19/F19,0) -> 0.957724 | L19: Manual Bills | R19: =IFERROR(D19*$T$7,0) -> 136.78
B20: 46172 | C20: Sat | D20: 3457 | E20: 1146 | F20: =IFERROR(D20+E20+G20+U20+Y20,0) -> 4603 | H20: =SUMIFS('💸 Expenses'!$F$8:$F$5000,'💸 Expenses'!$B$8:$B$5000,">="&B20,'💸 Expenses'!$B$8:$B$5000,"<"&(B20+1)) -> 5974.3 | I20: =IFERROR(F20-H20,0) -> -1371.3 | J20: =IFERROR(I20/F20,0) -> -0.297914 | L20: Manual Bills | R20: =IFERROR(D20*$T$7,0) -> 140.35
B21: 46173 | C21: Sun | E21: 893 | F21: =IFERROR(D21+E21+G21+U21+Y21,0) -> 893 | H21: =SUMIFS('💸 Expenses'!$F$8:$F$5000,'💸 Expenses'!$B$8:$B$5000,">="&B21,'💸 Expenses'!$B$8:$B$5000,"<"&(B21+1)) -> 10312 | I21: =IFERROR(F21-H21,0) -> -9419 | J21: =IFERROR(I21/F21,0) -> -10.547592 | L21: Manual Bills | R21: =IFERROR(D21*$T$7,0) -> 0
B22: 46174 | C22: Mon | D22: 3433 | E22: 1276 | F22: =IFERROR(D22+E22+G22+U22+Y22,0) -> 5019 | G22: 310 | H22: =SUMIFS('💸 Expenses'!$F$8:$F$5000,'💸 Expenses'!$B$8:$B$5000,">="&B22,'💸 Expenses'!$B$8:$B$5000,"<"&(B22+1)) -> 5329.64 | I22: =IFERROR(F22-H22,0) -> -310.64 | J22: =IFERROR(I22/F22,0) -> -0.061893 | L22: Manual Bills | R22: =IFERROR(D22*$T$7,0) -> 139.38
B23: 46175 | C23: Tue | D23: 1240 | E23: 320 | F23: =IFERROR(D23+E23+G23+U23+Y23,0) -> 1843 | G23: 283 | H23: =SUMIFS('💸 Expenses'!$F$8:$F$5000,'💸 Expenses'!$B$8:$B$5000,">="&B23,'💸 Expenses'!$B$8:$B$5000,"<"&(B23+1)) -> 2379.11 | I23: =IFERROR(F23-H23,0) -> -536.11 | J23: =IFERROR(I23/F23,0) -> -0.29089 | L23: Manual Bills | R23: =IFERROR(D23*$T$7,0) -> 50.34
B24: 46176 | C24: Wed | D24: 1853 | E24: 1939 | F24: =IFERROR(D24+E24+G24+U24+Y24,0) -> 3912 | G24: 120 | H24: =SUMIFS('💸 Expenses'!$F$8:$F$5000,'💸 Expenses'!$B$8:$B$5000,">="&B24,'💸 Expenses'!$B$8:$B$5000,"<"&(B24+1)) -> 4211.86 | I24: =IFERROR(F24-H24,0) -> -299.86 | J24: =IFERROR(I24/F24,0) -> -0.076651 | L24: Manual Bills | R24: =IFERROR(D24*$T$7,0) -> 75.23
B25: 46177 | C25: Thu | D25: 2712 | E25: 1045 | F25: =IFERROR(D25+E25+G25+U25+Y25,0) -> 3757 | H25: =SUMIFS('💸 Expenses'!$F$8:$F$5000,'💸 Expenses'!$B$8:$B$5000,">="&B25,'💸 Expenses'!$B$8:$B$5000,"<"&(B25+1)) -> 20959.96 | I25: =IFERROR(F25-H25,0) -> -17202.96 | J25: =IFERROR(I25/F25,0) -> -4.578909 | L25: Manual Bills | R25: =IFERROR(D25*$T$7,0) -> 110.11
B26: 46178 | C26: Fri | D26: 2495 | E26: 1778 | F26: =IFERROR(D26+E26+G26+U26+Y26,0) -> 4408 | G26: 135 | H26: =SUMIFS('💸 Expenses'!$F$8:$F$5000,'💸 Expenses'!$B$8:$B$5000,">="&B26,'💸 Expenses'!$B$8:$B$5000,"<"&(B26+1)) -> 878.06 | I26: =IFERROR(F26-H26,0) -> 3529.94 | J26: =IFERROR(I26/F26,0) -> 0.800803 | L26: Manual Bills | R26: =IFERROR(D26*$T$7,0) -> 101.3
B27: 46179 | C27: Sat | D27: 580 | E27: 1754 | F27: =IFERROR(D27+E27+G27+U27+Y27,0) -> 2334 | H27: =SUMIFS('💸 Expenses'!$F$8:$F$5000,'💸 Expenses'!$B$8:$B$5000,">="&B27,'💸 Expenses'!$B$8:$B$5000,"<"&(B27+1)) -> 5414 | I27: =IFERROR(F27-H27,0) -> -3080 | J27: =IFERROR(I27/F27,0) -> -1.319623 | L27: Manual Bills | R27: =IFERROR(D27*$T$7,0) -> 23.55
B28: 46180 | C28: Sun | F28: =IFERROR(D28+E28+G28+U28+Y28,0) -> 0 | H28: =SUMIFS('💸 Expenses'!$F$8:$F$5000,'💸 Expenses'!$B$8:$B$5000,">="&B28,'💸 Expenses'!$B$8:$B$5000,"<"&(B28+1)) -> 1671 | I28: =IFERROR(F28-H28,0) -> -1671 | J28: =IFERROR(I28/F28,0) -> 0 | L28: Manual Bills | R28: =IFERROR(D28*$T$7,0) -> 0
B29: 46181 | C29: Mon | D29: 1778 | E29: 1850 | F29: =IFERROR(D29+E29+G29+U29+Y29,0) -> 3727 | G29: 99 | H29: =SUMIFS('💸 Expenses'!$F$8:$F$5000,'💸 Expenses'!$B$8:$B$5000,">="&B29,'💸 Expenses'!$B$8:$B$5000,"<"&(B29+1)) -> 3187.11 | I29: =IFERROR(F29-H29,0) -> 539.89 | J29: =IFERROR(I29/F29,0) -> 0.144859 | L29: Manual Bills | R29: =IFERROR(D29*$T$7,0) -> 72.19
B30: 46182 | C30: Tue | D30: 930 | E30: 4480 | F30: =IFERROR(D30+E30+G30+U30+Y30,0) -> 5410 | H30: =SUMIFS('💸 Expenses'!$F$8:$F$5000,'💸 Expenses'!$B$8:$B$5000,">="&B30,'💸 Expenses'!$B$8:$B$5000,"<"&(B30+1)) -> 6623.98 | I30: =IFERROR(F30-H30,0) -> -1213.98 | J30: =IFERROR(I30/F30,0) -> -0.224396 | L30: Manual Bills | R30: =IFERROR(D30*$T$7,0) -> 37.76
B31: 46183 | C31: Wed | D31: 2506 | E31: 1759 | F31: =IFERROR(D31+E31+G31+U31+Y31,0) -> 4265 | H31: =SUMIFS('💸 Expenses'!$F$8:$F$5000,'💸 Expenses'!$B$8:$B$5000,">="&B31,'💸 Expenses'!$B$8:$B$5000,"<"&(B31+1)) -> 1341.81 | I31: =IFERROR(F31-H31,0) -> 2923.19 | J31: =IFERROR(I31/F31,0) -> 0.68539 | L31: Manual Bills | R31: =IFERROR(D31*$T$7,0) -> 101.74
B32: 46184 | C32: Thu | D32: 2075 | E32: 2091 | F32: =IFERROR(D32+E32+G32+U32+Y32,0) -> 4166 | G32: 0 | H32: =SUMIFS('💸 Expenses'!$F$8:$F$5000,'💸 Expenses'!$B$8:$B$5000,">="&B32,'💸 Expenses'!$B$8:$B$5000,"<"&(B32+1)) -> 4044 | I32: =IFERROR(F32-H32,0) -> 122 | J32: =IFERROR(I32/F32,0) -> 0.029285 | L32: Cierre 11 Jun + receipts | R32: =IFERROR(D32*$T$7,0) -> 84.24
B33: 46185 | C33: Fri | D33: 2635 | E33: 3435 | F33: =IFERROR(D33+E33+G33+U33+Y33,0) -> 6070 | G33: 0 | H33: =SUMIFS('💸 Expenses'!$F$8:$F$5000,'💸 Expenses'!$B$8:$B$5000,">="&B33,'💸 Expenses'!$B$8:$B$5000,"<"&(B33+1)) -> 901.8 | I33: =IFERROR(F33-H33,0) -> 5168.2 | J33: =IFERROR(I33/F33,0) -> 0.851433 | L33: Cierre 12 Jun + receipts | R33: =IFERROR(D33*$T$7,0) -> 106.98
B34: 46186 | C34: Sat | D34: 1005 | E34: 806 | F34: =IFERROR(D34+E34+G34+U34+Y34,0) -> 1811 | G34: 0 | H34: =SUMIFS('💸 Expenses'!$F$8:$F$5000,'💸 Expenses'!$B$8:$B$5000,">="&B34,'💸 Expenses'!$B$8:$B$5000,"<"&(B34+1)) -> 8084.16 | I34: =IFERROR(F34-H34,0) -> -6273.16 | J34: =IFERROR(I34/F34,0) -> -3.46392 | L34: Receipts + Week 4 payroll paid Sat | R34: =IFERROR(D34*$T$7,0) -> 40.8
B35: 46187 | C35: Sun | D35: 0 | E35: 0 | F35: =IFERROR(D35+E35+G35+U35+Y35,0) -> 0 | G35: 0 | H35: =SUMIFS('💸 Expenses'!$F$8:$F$5000,'💸 Expenses'!$B$8:$B$5000,">="&B35,'💸 Expenses'!$B$8:$B$5000,"<"&(B35+1)) -> 1526.18 | I35: =IFERROR(F35-H35,0) -> -1526.18 | J35: =IFERROR(I35/F35,0) -> 0 | L35: CLOSED (Sunday) — market/prep run, no revenue | R35: =IFERROR(D35*$T$7,0) -> 0
B36: 46188 | C36: Mon | D36: 2075 | E36: 2348 | F36: =IFERROR(D36+E36+G36+U36+Y36,0) -> 4423 | G36: 0 | H36: =SUMIFS('💸 Expenses'!$F$8:$F$5000,'💸 Expenses'!$B$8:$B$5000,">="&B36,'💸 Expenses'!$B$8:$B$5000,"<"&(B36+1)) -> 2858.08 | I36: =IFERROR(F36-H36,0) -> 1564.92 | J36: =IFERROR(I36/F36,0) -> 0.353814 | L36: Cierre 15 Jun + receipts | R36: =IFERROR(D36*$T$7,0) -> 84.24
B37: 46189 | C37: Tue | D37: 1841 | E37: 945 | F37: =IFERROR(D37+E37+G37+U37+Y37,0) -> 2786 | G37: 0 | H37: =SUMIFS('💸 Expenses'!$F$8:$F$5000,'💸 Expenses'!$B$8:$B$5000,">="&B37,'💸 Expenses'!$B$8:$B$5000,"<"&(B37+1)) -> 2541.9 | I37: =IFERROR(F37-H37,0) -> 244.1 | J37: =IFERROR(I37/F37,0) -> 0.087617 | L37: Cierre 16 Jun + receipts | R37: =IFERROR(D37*$T$7,0) -> 74.74
B38: 46190 | C38: Wed | D38: 2123 | E38: 2281 | F38: =IFERROR(D38+E38+G38+U38+Y38,0) -> 4404 | G38: 0 | H38: =SUMIFS('💸 Expenses'!$F$8:$F$5000,'💸 Expenses'!$B$8:$B$5000,">="&B38,'💸 Expenses'!$B$8:$B$5000,"<"&(B38+1)) -> 2353 | I38: =IFERROR(F38-H38,0) -> 2051 | J38: =IFERROR(I38/F38,0) -> 0.465713 | L38: Cierre 17 Jun + receipts | R38: =IFERROR(D38*$T$7,0) -> 86.19
B39: 46191 | C39: Thu | D39: 2211 | E39: 1554 | F39: =IFERROR(D39+E39+G39+U39+Y39,0) -> 4165 | G39: 400 | H39: =SUMIFS('💸 Expenses'!$F$8:$F$5000,'💸 Expenses'!$B$8:$B$5000,">="&B39,'💸 Expenses'!$B$8:$B$5000,"<"&(B39+1)) -> 2958.83 | I39: =IFERROR(F39-H39,0) -> 1206.17 | J39: =IFERROR(I39/F39,0) -> 0.289597 | L39: Cierre 18 Jun + receipts | R39: =IFERROR(D39*$T$7,0) -> 89.77
B40: 46192 | C40: Fri | D40: 4179 | E40: 2505 | F40: =IFERROR(D40+E40+G40+U40+Y40,0) -> 6804 | G40: 120 | H40: =SUMIFS('💸 Expenses'!$F$8:$F$5000,'💸 Expenses'!$B$8:$B$5000,">="&B40,'💸 Expenses'!$B$8:$B$5000,"<"&(B40+1)) -> 1483 | I40: =IFERROR(F40-H40,0) -> 5321 | J40: =IFERROR(I40/F40,0) -> 0.78204 | L40: Cierre via loka.py | R40: =IFERROR(D40*$T$7,0) -> 169.67
B41: 46193 | C41: Sat | D41: 1172 | E41: 1079 | F41: =IFERROR(D41+E41+G41+U41+Y41,0) -> 2251 | G41: 0 | H41: =SUMIFS('💸 Expenses'!$F$8:$F$5000,'💸 Expenses'!$B$8:$B$5000,">="&B41,'💸 Expenses'!$B$8:$B$5000,"<"&(B41+1)) -> 9320.81 | I41: =IFERROR(F41-H41,0) -> -7069.81 | J41: =IFERROR(I41/F41,0) -> -3.140742 | L41: Cierre via loka.py | R41: =IFERROR(D41*$T$7,0) -> 47.58
B42: 46194 | C42: Sun | D42: 0 | E42: 0 | F42: =IFERROR(D42+E42+G42+U42+Y42,0) -> 0 | G42: 0 | H42: =SUMIFS('💸 Expenses'!$F$8:$F$5000,'💸 Expenses'!$B$8:$B$5000,">="&B42,'💸 Expenses'!$B$8:$B$5000,"<"&(B42+1)) -> 2065.85 | I42: =IFERROR(F42-H42,0) -> -2065.85 | J42: =IFERROR(I42/F42,0) -> 0 | L42: Cierre via loka.py | R42: =IFERROR(D42*$T$7,0) -> 0
B43: 46195 | C43: Mon | D43: 2459 | E43: 1800 | F43: =IFERROR(D43+E43+G43+U43+Y43,0) -> 4259 | G43: 0 | H43: =SUMIFS('💸 Expenses'!$F$8:$F$5000,'💸 Expenses'!$B$8:$B$5000,">="&B43,'💸 Expenses'!$B$8:$B$5000,"<"&(B43+1)) -> 1451 | I43: =IFERROR(F43-H43,0) -> 2808 | J43: =IFERROR(I43/F43,0) -> 0.65931 | L43: Cierre via loka.py | R43: =IFERROR(D43*$T$7,0) -> 99.84
...

Sheet 💸 Expenses
A2: 💸 LOKA — EXPENSES TRACKER | E2: Log every cost: ingredients, staff, utilities, supplies…
B5: TODAY | C5: THIS WEEK | D5: THIS MONTH | E5: INGREDIENTS | F5: STAFF | G5: UTILITIES | H5: TODAY TOTAL | I5: WEEK TOTAL
B6: =SUMIFS($F$8:$F$5000,$B$8:$B$5000,TODAY()) | C6: =SUMIFS($F$8:$F$5000,$B$8:$B$5000,">="&(TODAY()-WEEKDAY(TODAY(),2)+1),$B$8:$B$5000,"<="&(TODAY()-WEEKDAY(TODAY(),2)+7)) | D6: =SUMIFS($F$8:$F$5000,$B$8:$B$5000,">="&DATE(YEAR(TODAY()),MONTH(TODAY()),1),$B$8:$B$5000,"<"&DATE(YEAR(TODAY()),MONTH(TODAY())+1,1)) | E6: =SUMIF($E$8:$E$5000,"Ingredients*",$F$8:$F$5000) | F6: =SUMIF($E$8:$E$5000,"Staff*",$F$8:$F$5000) | G6: =SUMIF($E$8:$E$5000,"Supplies*",$F$8:$F$5000)+SUMIF($E$8:$E$5000,"Utilities*",$F$8:$F$5000) | H6: =SUMIFS($F$8:$F$5000,$B$8:$B$5000,TODAY()) | I6: =SUMIFS($F$8:$F$5000,$B$8:$B$5000,">="&(TODAY()-WEEKDAY(TODAY(),2)+1),$B$8:$B$5000,"<="&(TODAY()-WEEKDAY(TODAY(),2)+7))
B7: Date | C7: Description | D7: Supplier | E7: Category | F7: Amount ($) | G7: Paid By | H7: Payment Method | I7: Status | J7: Notes
B8: 46160 | C8: Carne | D8: — | E8: Ingredients - Meat | F8: 420 | G8: Restaurant | H8: Cash | I8: ✅ Paid
B9: 46160 | C9: Basicos | D9: — | E9: Ingredients - Pantry | F9: 1068 | G9: Restaurant | H9: Cash | I9: ✅ Paid
B10: 46160 | C10: Real Pan Services | D10: Real Pan | E10: Ingredients - Bread | F10: 522 | G10: Restaurant | H10: Cash | I10: ✅ Paid
B11: 46160 | C11: Chedruai | D11: Chedraui | E11: Supermarket/General | F11: 129 | G11: Restaurant | H11: Cash | I11: ✅ Paid
B12: 46160 | C12: Vegetables | D12: Abastos | E12: Ingredients - Vegetables | F12: 400 | G12: Restaurant | H12: Cash | I12: ✅ Paid
B13: 46160 | C13: Vegetables | D13: — | E13: Ingredients - Vegetables | F13: 90 | G13: Restaurant | H13: Cash | I13: ✅ Paid
B14: 46161 | C14: Arroz | D14: — | E14: Ingredients - Pantry | F14: 30 | G14: Restaurant | H14: Cash | I14: ✅ Paid
B15: 46162 | C15: Lechuga | D15: — | E15: Ingredients - Vegetables | F15: 65 | G15: Restaurant | H15: Cash | I15: ✅ Paid
B16: 46162 | C16: Tortillas | D16: — | E16: Ingredients - Pantry | F16: 26 | G16: Restaurant | H16: Cash | I16: ✅ Paid
B17: 46162 | C17: Jamon Mexicana | D17: — | E17: Ingredients - Meat | F17: 88 | G17: Restaurant | H17: Cash | I17: ✅ Paid
B18: 46162 | C18: Carne | D18: — | E18: Ingredients - Meat | F18: 1104 | G18: Restaurant | H18: Cash | I18: ✅ Paid
B19: 46162 | C19: Salmon | D19: — | E19: Ingredients - Meat & Fish | F19: 397 | G19: Restaurant | H19: Cash | I19: ✅ Paid
... B46: 46165 | C46: Agua Natural | D46: — | E46: Supplies/Other | F46: 30 | G46: Restaurant | H46: Cash | I46: ✅ Paid
B47: 46165 | C47: John - Saldo Semana | D47: Nomina | E47: Staff - Salary | F47: 3250 | G47: Restaurant | H47: Cash | I47: ✅ Paid | J47: Head Chef — weekly salary Week 1
B48: 46165 | C48: Debi - Limpieza | D48: Nomina | E48: Staff - Salary | F48: 1500 | G48: Restaurant | H48: Cash | I48: ✅ Paid | J48: Cleaning staff — weekly salary Week 1
B49: 46165 | C49: Victor - Mesero (2 dias) | D49: Nomina | E49: Staff - Salary | F49: 666 | G49: Restaurant | H49: Cash | I49: ✅ Paid | J49: Waiter — 2 days salary Week 1
B50: 46165 | C50: Sal Fina (20 x 1 kg) | D50: Costco | E50: Ingredients - Pantry | F50: 408.17 | G50: Restaurant | H50: Card | I50: ✅ Paid | J50: Costco — Sal Fina 20/1KG
B51: 46165 | C51: Coca Cola (24 x 600ml) | D51: Costco | E51: Ingredients - Beverages | F51: 455.23 | G51: Restaurant | H51: Card | I51: ✅ Paid | J51: Costco — discount applied, total $844
B52: 46165 | C52: Leche Deslactosada (12 x 1LT) | D52: Sam's Club | E52: Ingredients - Dairy | F52: 317.13 | G52: Restaurant | H52: Card | I52: ✅ Paid | J52: Sam's Club — reimbursed to Shashirekha, settled
B53: 46165 | C53: Leche Alpura (12 x 1L) | D53: Sam's Club | E53: Ingredients - Dairy | F53: 317.13 | G53: Restaurant | H53: Card | I53: ✅ Paid | J53: Sam's Club — reimbursed to Shashirekha, settled
B54: 46165 | C54: Crema Ácida | D54: Sam's Club | E54: Ingredients - Dairy | F54: 250.63 | G54: Restaurant | H54: Card | I54: ✅ Paid | J54: Sam's Club — reimbursed to Shashirekha, settled
B55: 46165 | C55: Salsa / Tomate (12 x 600ml) | D55: Sam's Club | E55: Ingredients - Pantry | F55: 232.22 | G55: Restaurant | H55: Card | I55: ✅ Paid | J55: Sam's Club — reimbursed to Shashirekha, settled
B56: 46165 | C56: Champiñones (24 x 400ml) | D56: Sam's Club | E56: Ingredients - Vegetables | F56: 218.92 | G56: Restaurant | H56: Card | I56: ✅ Paid | J56: Sam's Club — reimbursed to Shashirekha, settled
B57: 46166 | C57: Guayabas Mediana | D57: Aviles Hernandez | E57: Ingredients - Fruit | F57: 120 | G57: Restaurant | H57: Cash | I57: ✅ Paid
B58: 46166 | C58: Jicamas + Pinas + Melon Chino | D58: El Matamoros | E58: Ingredients - Fruit | F58: 147 | G58: Restaurant | H58: Cash | I58: ✅ Paid
B59: 46166 | C59: Cilantro + Italiana | D59: Oscar Verduras | E59: Ingredients - Vegetables | F59: 100 | G59: Restaurant | H59: Cash | I59: ✅ Paid
B60: 46166 | C60: Habanero + Pepino | D60: Remision Formitec | E60: Ingredients - Vegetables | F60: 90 | G60: Restaurant | H60: Cash | I60: ✅ Paid
B61: 46166 | C61: Betabel (~1.9 kg) | D61: Nota Remision | E61: Ingredients - Vegetables | F61: 78 | G61: Restaurant | H61: Cash | I61: ✅ Paid
B62: 46166 | C62: Jitomate | D62: Brisia y Hermanos | E62: Ingredients - Vegetables | F62: 178 | G62: Restaurant | H62: Cash | I62: ✅ Paid
B63: 46166 | C63: Mango + Sandia | D63: Papayas Maradol | E63: Ingredients - Fruit | F63: 116 | G63: Restaurant | H63: Cash | I63: ✅ Paid
B64: 46166 | C64: Verduras variadas | D64: JP Verduras | E64: Ingredients - Vegetables | F64: 224 | G64: Restaurant | H64: Cash | I64: ✅ Paid
B65: 46166 | C65: Pimiento Morron | D65: Sin factura | E65: Ingredients - Vegetables | F65: 23 | G65: Restaurant | H65: Cash | I65: ✅ Paid | J65: No receipt — Sin factura
B66: 46167 | C66: Pan para Hamburguesa con Ajonjolí + Pan de Caja Arandano | D66: Real Abastos | E66: Ingredients - Bread | F66: 273 | G66: Restaurant | H66: Card | I66: ✅ Paid | J66: Real Sucursal Central de Abastos — 12 pcs hamburger buns + 3x900g bread
B67: 46167 | C67: Limonada / Naranjada / Tamarindo 1LT (18 pcs) | D67: Reca del Bajio | E67: Ingredients - Beverages | F67: 450 | G67: Restaurant | H67: Card | I67: ✅ Paid | J67: Mercado Pago — 6 Limonada + 6 Naranjada + 6 Tamarindo
B68: 46167 | C68: QsoCrema Lala 190g | D68: Chedraui Selecto | E68: Ingredients - Dairy | F68: 32 | G68: Restaurant | H68: Card | I68: ✅ Paid
B69: 46167 | C69: Tortillas Blanca (2.21 kg) | D69: Chedraui Selecto | E69: Ingredients - Pantry | F69: 28.73 | G69: Restaurant | H69: Card | I69: ✅ Paid
...

Sheet 📦 Inventory
A2: 📦 LOKA — INVENTORY | F2: Update stock levels when you receive deliveries or do stock checks
B5: TOTAL ITEMS | D5: ⚠️ LOW STOCK | E5: LOW STOCK # | F5: 🚫 OUT OF STOCK | H5: ALERT COUNT | J5: LAST UPDATED
B6: =COUNTA(B9:B2000) | D6: =COUNTIF(J9:J2000,"⚠️ LOW STOCK") | E6: =COUNTIF(J9:J2000,"⚠️ LOW STOCK")+COUNTIF(J9:J2000,"🚫 OUT OF STOCK") | F6: =COUNTIF(J9:J2000,"🚫 OUT OF STOCK") | H6: =COUNTIF(J9:J2000,"⚠️ LOW STOCK")+COUNTIF(J9:J2000,"🚫 OUT OF STOCK") | J6: =TODAY()
B8: Item Name | Category | Unit | Min Stock | Current Stock | Last Ordered | Supplier | Status | Notes
B9: Carne de Res | C9: Ingredients - Meat | D9: kg | E9: 0 | J9: =IF(ISBLANK(F9),"—",IF(F9=0,"🚫 OUT OF STOCK",IF(F9<=E9,"⚠️ LOW STOCK","✅ OK")))
B10: Jamon Mexicano | C10: Ingredients - Meat | D10: kg | E10: 0 | J10: =IF(ISBLANK(F10),"—",IF(F10=0,"🚫 OUT OF STOCK",IF(F10<=E10,"⚠️ LOW STOCK","✅ OK")))
B11: Pollo | C11: Ingredients - Meat | D11: kg | E11: 0 | J11: =IF(ISBLANK(F11),"—",IF(F11=0,"🚫 OUT OF STOCK",IF(F11<=E11,"⚠️ LOW STOCK","✅ OK")))
B12: Chuletas de Carne | C12: Ingredients - Meat | D12: kg | E12: 0 | J12: =IF(ISBLANK(F12),"—",IF(F12=0,"🚫 OUT OF STOCK",IF(F12<=E12,"⚠️ LOW STOCK","✅ OK")))
B13: Costillas de Cerdo | C13: Ingredients - Meat | D13: kg | E13: 0 | J13: =IF(ISBLANK(F13),"—",IF(F13=0,"🚫 OUT OF STOCK",IF(F13<=E13,"⚠️ LOW STOCK","✅ OK")))
B14: Salmon | C14: Ingredients - Meat & Fish | D14: kg | E14: 0 | J14: =IF(ISBLANK(F14),"—",IF(F14=0,"🚫 OUT OF STOCK",IF(F14<=E14,"⚠️ LOW STOCK","✅ OK")))
B15: Filete de Mojarra | C15: Ingredients - Meat & Fish | D15: kg | E15: 0 | J15: =IF(ISBLANK(F15),"—",IF(F15=0,"🚫 OUT OF STOCK",IF(F15<=E15,"⚠️ LOW STOCK","✅ OK")))
B16: Papas | C16: Ingredients - Vegetables | D16: kg | E16: 0 | J16: =IF(ISBLANK(F16),"—",IF(F16=0,"🚫 OUT OF STOCK",IF(F16<=E16,"⚠️ LOW STOCK","✅ OK")))
B17: Lechuga | C17: Ingredients - Vegetables | D17: pcs | E17: 0 | J17: =IF(ISBLANK(F17),"—",IF(F17=0,"🚫 OUT OF STOCK",IF(F17<=E17,"⚠️ LOW STOCK","✅ OK")))
B18: Jitomate | C18: Ingredients - Vegetables | D18: kg | E18: 0 | J18: =IF(ISBLANK(F18),"—",IF(F18=0,"🚫 OUT OF STOCK",IF(F18<=E18,"⚠️ LOW STOCK","✅ OK")))
B19: Cilantro | C19: Ingredients - Vegetables | D19: pcs | E19: 0 | J19: =IF(ISBLANK(F19),"—",IF(F19=0,"🚫 OUT OF STOCK",IF(F19<=E19,"⚠️ LOW STOCK","✅ OK")))
B20: Italiana | C20: Ingredients - Vegetables | D20: pcs | E20: 0 | J20: =IF(ISBLANK(F20),"—",IF(F20=0,"🚫 OUT OF STOCK",IF(F20<=E20,"⚠️ LOW STOCK","✅ OK")))
... B73: Huevo Bachoco | C73: Ingredients - Pantry | D73: pcs | E73: 0 | J73: =IF(ISBLANK(F73),"—",IF(F73=0,"🚫 OUT OF STOCK",IF(F73<=E73,"⚠️ LOW STOCK","✅ OK")))

Sheet 👥 Staff & Payroll
A2: 👥 LOKA — STAFF & PAYROLL | D2: Weekly schedule + auto payroll calculation
A6: STAFF SCHEDULE — Week of: | D6: =TODAY()-WEEKDAY(TODAY(),2)+1
A7: Staff Name | B7: Role | C7: Daily Rate ($) | D7: Mon | E7: Tue | F7: Wed | G7: Thu | H7: Fri | I7: Sat | J7: Sun | K7: Days Worked | L7: Week Pay ($)
A8: John | B8: Head Chef | C8: 625 | D8: Full Day | E8: Full Day | F8: Full Day | G8: Full Day | H8: Full Day | I8: Full Day | J8: Day Off | K8: =COUNTIF(D8:J8,"Full Day") | L8: =K8*C8
A9: Debi | B9: Cleaner | C9: 250 | D9: Full Day | E9: Full Day | F9: Full Day | G9: Full Day | H9: Full Day | I9: Full Day | J9: Day Off | K9: =COUNTIF(D9:J9,"Full Day") | L9: =K9*C9
A10: Victor (INACTIVE) | B10: Mesero — Left after Week 1 | C10: 0 | D10: — | E10: — | F10: — | G10: — | H10: — | I10: — | J10: — | K10: 0 | L10: 0
A11: Judith (RESIGNED) | B11: Mesera — Resigned 7 Jun · paid in full 8 Jun | C11: 0 | D11: — | E11: — | F11: — | G11: — | H11: — | I11: — | J11: — | K11: 0 | L11: 0
A12: Cesar (RESIGNED) | B12: Mesero — Started Tue 9 Jun · Resigned · Week 4 paid in full (5 days) | C12: 0 | D12: — | E12: — | F12: — | G12: — | H12: — | I12: — | J12: — | K12: 0 | L12: 0
A13: Samu (INACTIVE) | B13: Ayudante / Support — left Aug 2026 · final week paid 14 Aug ($1,200) | C13: 0 | D13: — | E13: — | F13: — | G13: — | H13: — | I13: — | J13: — | K13: 0 | L13: 0
A14: Armando | B14: Ayudante / Support | C14: 370 | D14: Full Day | E14: Full Day | F14: Full Day | G14: Full Day | H14: Full Day | I14: Day Off | J14: Day Off | K14: =COUNTIF(D14:J14,"Full Day") | L14: =K14*C14
A20: MONTHLY PAYROLL PROJECTION
A21: Staff Name | B21: Role | C21: Week Pay ($) | D21: x Weeks/Month | E21: Monthly ($) | F21: IMSS / Benefits % | G21: Total Monthly Cost ($) | H21: Notes
A22: =A8 | B22: Head Chef | C22: =L8 | D22: 4 | E22: =C22*D22 | F22: 0.08 | G22: =E22*(1+F22)
A23: =A9 | B23: Cleaner / Limpieza | C23: =L9 | D23: 4 | E23: =C23*D23 | F23: 0.08 | G23: =E23*(1+F23)
A24: =A10 | B24: Mesero (left Wk1) | C24: =L10 | D24: 4 | E24: =C24*D24 | F24: 0.08 | G24: =E24*(1+F24)
A25: =A11 | B25: Mesera (resigned) | C25: =L11 | D25: 4 | E25: =C25*D25 | F25: 0.08 | G25: =E25*(1+F25)
A26: =A12 | B26: Mesero / Waiter | C26: =L12 | D26: 4 | E26: =C26*D26 | F26: 0.08 | G26: =E26*(1+F26)
A27: =A13 | B27: Ayudante / Support | C27: =L13 | D27: 4 | E27: =C27*D27 | F27: 0.08 | G27: =E27*(1+F27)
A28: =A14 | B28: Kitchen Helper | C28: =L14 | D28: 4 | E28: =C28*D28 | F28: 0.08 | G28: =E28*(1+F28)
A29: =A15 | E29: =C29*D29 | G29: =E29*(1+F29)
A30: TOTAL MONTHLY PAYROLL COST | G30: =SUM(G21:G28)
A33: ── WEEKLY FIXED COSTS & BREAK-EVEN TARGETS ──
A34: COST ITEM | B34: WEEKLY ($) | C34: MONTHLY EST. ($) | D34: NOTES
A35: John — Head Chef Salary | B35: 3750 | C35: 15000 | D35: Confirmed weekly rate
A36: Debi — Limpieza Salary | B36: 1500 | C36: 6000 | D36: Confirmed weekly rate
A37: Armando — Ayudante Salary | B37: 1850 | C37: 7400 | D37: $370/day · 5 days Mon–Fri · Sat not available · started 13 Aug 2026 (first payment $740 = 2 days on 14 Aug). Replaces Samu.
A38: Samu — Ayudante Salary (INACTIVE) | B38: 0 | C38: 0 | D38: Left Aug 2026 — final week paid 14 Aug · removed from forward fixed costs
A39: Rent + Maintenance (actual — $20,000/mo) | B39: 5000 | C39: 20000 | D39: Confirmed — $20,000/month actual
A40: Utilities — Electricity + Gas (estimated) | B40: 1000 | C40: 4000 | D40: ⏳ Approx — bills pending · electricity + gas
A41: TOTAL FIXED COSTS (current) | B41: =SUM(B35:B40) | C41: =SUM(C35:C40) | D41: Incl. rent + maintenance + utilities est.
A43: ── STAFF STATUS — ✅ JOHN + DEBI + ARMANDO ACTIVE (Samu left Aug 2026) ──
A44: Judith — Mesera Salary (historical — resigned 7 Jun) | B44: 2000 | C44: 8000 | D44: Confirmed — $2,000/week · $333.33/day · absent days deducted
A45: Current roster: John + Debi + Armando | B45: 12050 | C45: 23750 | D45: 24550 | E45: 3758 | F45: Samu left Aug 2026 — replaced by Armando ($1,850/wk vs $1,200/wk) | G45: Break-even ≈ $3,758/day (fixed $12,050 + variable $10,500, ÷6 days)
A47: ── BREAK-EVEN & WEEKLY REVENUE TARGETS ──
A48: SCENARIO | B48: Fixed Costs ($) | C48: Avg Variable Costs ($) | D48: MIN Weekly Revenue ($) | E48: MIN Daily Revenue ($) | F48: Current Avg/Day ($) | G48: STATUS
A49: Without Mesero (NOW) | B49: 11250 | C49: 10500 | D49: 21750 | E49: 3625 | F49: 4011 | G49: ✅ Above break-even — revised down from $3,792 → $3,625/day | H49: ✅ Current scenario — no mesero (Judith resigned 7 Jun)
A50: With Mesero (~$2,250) | B50: 13500 | C50: 10500 | D50: 24000 | E50: 4000 | F50: 4011 | G50: ⚠️ Still below — need +$-11/day when mesero hired | H50: ⏳ Will update when 2 new staff details confirmed (9 Jun)
A51: Safety buffer (+15%) | B51: 11250 | C51: 10500 | D51: 25012 | E51: 4169 | F51: 4011 | G51: Target for healthy buffer: $4,169/day
A53: NOTES:
A54: Variable costs = avg ingredients + supplies per week based on Weeks 1-2 actual data (~$10,500)
...

Sheet 🚚 Suppliers
A2: 🚚 LOKA — SUPPLIER ORDERS | F2: Track purchase orders from suppliers
B5: TOTAL ORDERS | C5: PENDING | D5: IN TRANSIT | E5: RECEIVED | F5: MONTH SPEND | G5: PENDING VALUE | H5: PENDING COUNT
B6: =COUNTA(C9:C3000)-1 | C6: =COUNTIF(K9:K3000,"Pending") | D6: =COUNTIF(K9:K3000,"In Transit") | E6: =COUNTIF(K9:K3000,"Received") | F6: =SUMIF(K9:K3000,"Received",J9:J3000) | G6: =SUMIF(K9:K3000,"Pending",J9:J3000) | H6: =COUNTIF(K9:K3000,"Pending")+COUNTIF(K9:K3000,"In Transit")

Sheet 📋 Supplier Directory
B2: 📋 LOKA — SUPPLIER DIRECTORY
B3: Contact list for all regular suppliers
B6: Supplier Name | C6: Contact / Phone | D6: Products Supplied | E6: Location / Address | F6: Notes
B7: Girigallo | C7: 442-249-4707 | D7: Pollo | E7: Islas Aleutianas 134, Loma Linda, C.P 76070
B8: Alico | C8: 442-796-8876 | D8: Carne de hamburguesa, Papas, Boneless | E8: Cerro de las Campanas 173, Col. Las Americas
B9: Reca (Repartidor) | C9: 442-679-6651 | D9: Aguas Avia / Bebidas | E9: — | F9: Delivery supplier
B10: Toluco | C10: — | D10: Desechables (Plasticos) | E10: Plásticos Desechables el Toluco, C/ 15 de Mayo 189, La Santa Cruz, Centro, 76020 Santiago de Querétaro
B11: Bodega del Queso | C11: 442-114-0827 | D11: Queso, Jamon, Crema | E11: Avenida Universidad 119, Los Cedros, 76165 Santiago de Querétaro, Qro.
B12: Panadería Real | C12: 442-379-1880 | D12: Pan hamburguesa, Mayonesa, Arrachera, Sandwhich | E12: Plaza Capuchinas 149, Central de Abasto, Querétaro | F12: Also supplies at Brisa del Mar area
B13: Etrusca | C13: 442-234-5077 | D13: Sabores de Frappe, Matcha, Taro | E13: Café Etrusca Querétaro, Av. Tecnológico 10-Sur, Niños Héroes, 76010 Santiago de Querétaro
B16: Note: Additional suppliers recorded in expenses — Brisa del Mar, Chedraui, Costco, Real Abastos, OXXO, Pescadería El Faro

Sheet 📈 Monthly P&L
A1: LOKA — MONTHLY P&L (live formulas — auto-updates from Daily Log & Expenses)
A3: SUMMARY | B3: May 2026 | C3: Jun 2026 | D3: Jul 2026 | E3: Aug 2026 | F3: Sep 2026
A4: Total Income | B4: =SUMIFS('📅 Daily Log'!$F$8:$F$5000,'📅 Daily Log'!$B$8:$B$5000,">="&DATE(2026,5,1),'📅 Daily Log'!$B$8:$B$5000,"<"&DATE(2026,6,1)) | C4: =SUMIFS('📅 Daily Log'!$F$8:$F$5000,'📅 Daily Log'!$B$8:$B$5000,">="&DATE(2026,6,1),'📅 Daily Log'!$B$8:$B$5000,"<"&DATE(2026,7,1)) | D4: =SUMIFS('📅 Daily Log'!$F$8:$F$5000,'📅 Daily Log'!$B$8:$B$5000,">="&DATE(2026,7,1),'📅 Daily Log'!$B$8:$B$5000,"<"&DATE(2026,8,1)) | E4: =SUMIFS('📅 Daily Log'!$F$8:$F$5000,'📅 Daily Log'!$B$8:$B$5000,">="&DATE(2026,8,1),'📅 Daily Log'!$B$8:$B$5000,"<"&DATE(2026,9,1)) | F4: =SUMIFS('📅 Daily Log'!$F$8:$F$5000,'📅 Daily Log'!$B$8:$B$5000,">="&DATE(2026,9,1),'📅 Daily Log'!$B$8:$B$5000,"<"&DATE(2026,10,1))
A5: Total Expenses | B5: =SUMIFS('💸 Expenses'!$F$8:$F$5000,'💸 Expenses'!$B$8:$B$5000,">="&DATE(2026,5,1),'💸 Expenses'!$B$8:$B$5000,"<"&DATE(2026,6,1)) | C5: =SUMIFS('💸 Expenses'!$F$8:$F$5000,'💸 Expenses'!$B$8:$B$5000,">="&DATE(2026,6,1),'💸 Expenses'!$B$8:$B$5000,"<"&DATE(2026,7,1)) | D5: =SUMIFS('💸 Expenses'!$F$8:$F$5000,'💸 Expenses'!$B$8:$B$5000,">="&DATE(2026,7,1),'💸 Expenses'!$B$8:$B$5000,"<"&DATE(2026,8,1)) | E5: =SUMIFS('💸 Expenses'!$F$8:$F$5000,'💸 Expenses'!$B$8:$B$5000,">="&DATE(2026,8,1),'💸 Expenses'!$B$8:$B$5000,"<"&DATE(2026,9,1)) | F5: =SUMIFS('💸 Expenses'!$F$8:$F$5000,'💸 Expenses'!$B$8:$B$5000,">="&DATE(2026,9,1),'💸 Expenses'!$B$8:$B$5000,"<"&DATE(2026,10,1))
A6: NET PROFIT / LOSS | B6: =B4-B5 | C6: =C4-C5 | D6: =D4-D5 | E6: =E4-E5 | F6: =F4-F5
A7: Trading Days | B7: =COUNTIFS('📅 Daily Log'!$F$8:$F$5000,">0",'📅 Daily Log'!$B$8:$B$5000,">="&DATE(2026,5,1),'📅 Daily Log'!$B$8:$B$5000,"<"&DATE(2026,6,1)) | C7: =COUNTIFS('📅 Daily Log'!$F$8:$F$5000,">0",'📅 Daily Log'!$B$8:$B$5000,">="&DATE(2026,6,1),'📅 Daily Log'!$B$8:$B$5000,"<"&DATE(2026,7,1)) | D7: =COUNTIFS('📅 Daily Log'!$F$8:$F$5000,">0",'📅 Daily Log'!$B$8:$B$5000,">="&DATE(2026,7,1),'📅 Daily Log'!$B$8:$B$5000,"<"&DATE(2026,8,1)) | E7: =COUNTIFS('📅 Daily Log'!$F$8:$F$5000,">0",'📅 Daily Log'!$B$8:$B$5000,">="&DATE(2026,8,1),'📅 Daily Log'!$B$8:$B$5000,"<"&DATE(2026,9,1)) | F7: =COUNTIFS('📅 Daily Log'!$F$8:$F$5000,">0",'📅 Daily Log'!$B$8:$B$5000,">="&DATE(2026,9,1),'📅 Daily Log'!$B$8:$B$5000,"<"&DATE(2026,10,1))
A8: Avg Income / Day | B8: =IFERROR(B4/B7,0) | C8: =IFERROR(C4/C7,0) | D8: =IFERROR(D4/D7,0) | E8: =IFERROR(E4/E7,0) | F8: =IFERROR(F4/F7,0)
A10: INCOME BY TYPE | B10: May 2026 | C10: Jun 2026 | D10: Jul 2026 | E10: Aug 2026 | F10: Sep 2026
A11: Card (MP + Soft + BBVA) | B11: =SUMIFS('📅 Daily Log'!$D$8:$D$5000,'📅 Daily Log'!$B$8:$B$5000,">="&DATE(2026,5,1),'📅 Daily Log'!$B$8:$B$5000,"<"&DATE(2026,6,1))+SUMIFS('📅 Daily Log'!$U$8:$U$5000,'📅 Daily Log'!$B$8:$B$5000,">="&DATE(2026,5,1),'📅 Daily Log'!$B$8:$B$5000,"<"&DATE(2026,6,1))+SUMIFS('📅 Daily Log'!$Y$8:$Y$5000,'📅 Daily Log'!$B$8:$B$5000,">="&DATE(2026,5,1),'📅 Daily Log'!$B$8:$B$5000,"<"&DATE(2026,6,1)) | C11: =SUMIFS('📅 Daily Log'!$D$8:$D$5000,'📅 Daily Log'!$B$8:$B$5000,">="&DATE(2026,6,1),'📅 Daily Log'!$B$8:$B$5000,"<"&DATE(2026,7,1))+SUMIFS('📅 Daily Log'!$U$8:$U$5000,'📅 Daily Log'!$B$8:$B$5000,">="&DATE(2026,6,1),'📅 Daily Log'!$B$8:$B$5000,"<"&DATE(2026,7,1))+SUMIFS('📅 Daily Log'!$Y$8:$Y$5000,'📅 Daily Log'!$B$8:$B$5000,">="&DATE(2026,6,1),'📅 Daily Log'!$B$8:$B$5000,"<"&DATE(2026,7,1)) | D11: =SUMIFS('📅 Daily Log'!$D$8:$D$5000,'📅 Daily Log'!$B$8:$B$5000,">="&DATE(2026,7,1),'📅 Daily Log'!$B$8:$B$5000,"<"&DATE(2026,8,1))+SUMIFS('📅 Daily Log'!$U$8:$U$5000,'📅 Daily Log'!$B$8:$B$5000,">="&DATE(2026,7,1),'📅 Daily Log'!$B$8:$B$5000,"<"&DATE(2026,8,1))+SUMIFS('📅 Daily Log'!$Y$8:$Y$5000,'📅 Daily Log'!$B$8:$B$5000,">="&DATE(2026,7,1),'📅 Daily Log'!$B$8:$B$5000,"<"&DATE(2026,8,1)) | E11: =SUMIFS('📅 Daily Log'!$D$8:$D$5000,'📅 Daily Log'!$B$8:$B$5000,">="&DATE(2026,8,1),'📅 Daily Log'!$B$8:$B$5000,"<"&DATE(2026,9,1))+SUMIFS('📅 Daily Log'!$U$8:$U$5000,'📅 Daily Log'!$B$8:$B$5000,">="&DATE(2026,8,1),'📅 Daily Log'!$B$8:$B$5000,"<"&DATE(2026,9,1))+SUMIFS('📅 Daily Log'!$Y$8:$Y$5000,'📅 Daily Log'!$B$8:$B$5000,">="&DATE(2026,8,1),'📅 Daily Log'!$B$8:$B$5000,"<"&DATE(2026,9,1)) | F11: =SUMIFS('📅 Daily Log'!$D$8:$D$5000,'📅 Daily Log'!$B$8:$B$5000,">="&DATE(2026,9,1),'📅 Daily Log'!$B$8:$B$5000,"<"&DATE(2026,10,1))+SUMIFS('📅 Daily Log'!$U$8:$U$5000,'📅 Daily Log'!$B$8:$B$5000,">="&DATE(2026,9,1),'📅 Daily Log'!$B$8:$B$5000,"<"&DATE(2026,10,1))+SUMIFS('📅 Daily Log'!$Y$8:$Y$5000,'📅 Daily Log'!$B$8:$B$5000,">="&DATE(2026,9,1),'📅 Daily Log'!$B$8:$B$5000,"<"&DATE(2026,10,1))
A12: Cash | B12: =SUMIFS('📅 Daily Log'!$E$8:$E$5000,'📅 Daily Log'!$B$8:$B$5000,">="&DATE(2026,5,1),'📅 Daily Log'!$B$8:$B$5000,"<"&DATE(2026,6,1)) | C12: =SUMIFS('📅 Daily Log'!$E$8:$E$5000,'📅 Daily Log'!$B$8:$B$5000,">="&DATE(2026,6,1),'📅 Daily Log'!$B$8:$B$5000,"<"&DATE(2026,7,1)) | D12: =SUMIFS('📅 Daily Log'!$E$8:$E$5000,'📅 Daily Log'!$B$8:$B$5000,">="&DATE(2026,7,1),'📅 Daily Log'!$B$8:$B$5000,"<"&DATE(2026,8,1)) | E12: =SUMIFS('📅 Daily Log'!$E$8:$E$5000,'📅 Daily Log'!$B$8:$B$5000,">="&DATE(2026,8,1),'📅 Daily Log'!$B$8:$B$5000,"<"&DATE(2026,9,1)) | F12: =SUMIFS('📅 Daily Log'!$E$8:$E$5000,'📅 Daily Log'!$B$8:$B$5000,">="&DATE(2026,9,1),'📅 Daily Log'!$B$8:$B$5000,"<"&DATE(2026,10,1))
A13: Transfer | B13: =SUMIFS('📅 Daily Log'!$G$8:$G$5000,'📅 Daily Log'!$B$8:$B$5000,">="&DATE(2026,5,1),'📅 Daily Log'!$B$8:$B$5000,"<"&DATE(2026,6,1)) | C13: =SUMIFS('📅 Daily Log'!$G$8:$G$5000,'📅 Daily Log'!$B$8:$B$5000,">="&DATE(2026,6,1),'📅 Daily Log'!$B$8:$B$5000,"<"&DATE(2026,7,1)) | D13: =SUMIFS('📅 Daily Log'!$G$8:$G$5000,'📅 Daily Log'!$B$8:$B$5000,">="&DATE(2026,7,1),'📅 Daily Log'!$B$8:$B$5000,"<"&DATE(2026,8,1)) | E13: =SUMIFS('📅 Daily Log'!$G$8:$G$5000,'📅 Daily Log'!$B$8:$B$5000,">="&DATE(2026,8,1),'📅 Daily Log'!$B$8:$B$5000,"<"&DATE(2026,9,1)) | F13: =SUMIFS('📅 Daily Log'!$G$8:$G$5000,'📅 Daily Log'!$B$8:$B$5000,">="&DATE(2026,9,1),'📅 Daily Log'!$B$8:$B$5000,"<"&DATE(2026,10,1))
A14: Total Income | B14: =B11+B12+B13 | C14: =C11+C12+C13 | D14: =D11+D12+D13 | E14: =E11+E12+E13 | F14: =F11+F12+F13
A16: EXPENSES BY CATEGORY (high → low) | B16: May 2026 | C16: Jun 2026 | D16: Jul 2026 | E16: Aug 2026 | F16: Sep 2026
A17: Staff - Salary | B17: =SUMIFS('💸 Expenses'!$F$8:$F$5000,'💸 Expenses'!$E$8:$E$5000,$A17,'💸 Expenses'!$B$8:$B$5000,">="&DATE(2026,5,1),'💸 Expenses'!$B$8:$B$5000,"<"&DATE(2026,6,1)) | C17: =SUMIFS('💸 Expenses'!$F$8:$F$5000,'💸 Expenses'!$E$8:$E$5000,$A17,'💸 Expenses'!$B$8:$B$5000,">="&DATE(2026,6,1),'💸 Expenses'!$B$8:$B$5000,"<"&DATE(2026,7,1)) | D17: =SUMIFS('💸 Expenses'!$F$8:$F$5000,'💸 Expenses'!$E$8:$E$5000,$A17,'💸 Expenses'!$B$8:$B$5000,">="&DATE(2026,7,1),'💸 Expenses'!$B$8:$B$5000,"<"&DATE(2026,8,1)) | E17: =SUMIFS('💸 Expenses'!$F$8:$F$5000,'💸 Expenses'!$E$8:$E$5000,$A17,'💸 Expenses'!$B$8:$B$5000,">="&DATE(2026,8,1),'💸 Expenses'!$B$8:$B$5000,"<"&DATE(2026,9,1)) | F17: =SUMIFS('💸 Expenses'!$F$8:$F$5000,'💸 Expenses'!$E$8:$E$5000,$A17,'💸 Expenses'!$B$8:$B$5000,">="&DATE(2026,9,1),'💸 Expenses'!$B$8:$B$5000,"<"&DATE(2026,10,1))
A18: Rent | B18: =SUMIFS('💸 Expenses'!$F$8:$F$5000,'💸 Expenses'!$E$8:$E$5000,$A18,'💸 Expenses'!$B$8:$B$5000,">="&DATE(2026,5,1),'💸 Expenses'!$B$8:$B$5000,"<"&DATE(2026,6,1)) | C18: =SUMIFS('💸 Expenses'!$F$8:$F$5000,'💸 Expenses'!$E$8:$E$5000,$A18,'💸 Expenses'!$B$8:$B$5000,">="&DATE(2026,6,1),'💸 Expenses'!$B$8:$B$5000,"<"&DATE(2026,7,1)) | D18: =SUMIFS('💸 Expenses'!$F$8:$F$5000,'💸 Expenses'!$E$8:$E$5000,$A18,'💸 Expenses'!$B$8:$B$5000,">="&DATE(2026,7,1),'💸 Expenses'!$B$8:$B$5000,"<"&DATE(2026,8,1)) | E18: =SUMIFS('💸 Expenses'!$F$8:$F$5000,'💸 Expenses'!$E$8:$E$5000,$A18,'💸 Expenses'!$B$8:$B$5000,">="&DATE(2026,8,1),'💸 Expenses'!$B$8:$B$5000,"<"&DATE(2026,9,1)) | F18: =SUMIFS('💸 Expenses'!$F$8:$F$5000,'💸 Expenses'!$E$8:$E$5000,$A18,'💸 Expenses'!$B$8:$B$5000,">="&DATE(2026,9,1),'💸 Expenses'!$B$8:$B$5000,"<"&DATE(2026,10,1))
A19: Ingredients - Meat | B19: =SUMIFS('💸 Expenses'!$F$8:$F$5000,'💸 Expenses'!$E$8:$E$5000,$A19,'💸 Expenses'!$B$8:$B$5000,">="&DATE(2026,5,1),'💸 Expenses'!$B$8:$B$5000,"<"&DATE(2026,6,1)) | C19: =SUMIFS('💸 Expenses'!$F$8:$F$5000,'💸 Expenses'!$E$8:$E$5000,$A19,'💸 Expenses'!$B$8:$B$5000,">="&DATE(2026,6,1),'💸 Expenses'!$B$8:$B$5000,"<"&DATE(2026,7,1)) | D19: =SUMIFS('💸 Expenses'!$F$8:$F$5000,'💸 Expenses'!$E$8:$E$5000,$A19,'💸 Expenses'!$B$8:$B$5000,">="&DATE(2026,7,1),'💸 Expenses'!$B$8:$B$5000,"<"&DATE(2026,8,1)) | E19: =SUMIFS('💸 Expenses'!$F$8:$F$5000,'💸 Expenses'!$E$8:$E$5000,$A19,'💸 Expenses'!$B$8:$B$5000,">="&DATE(2026,8,1),'💸 Expenses'!$B$8:$B$5000,"<"&DATE(2026,9,1)) | F19: =SUMIFS('💸 Expenses'!$F$8:$F$5000,'💸 Expenses'!$E$8:$E$5000,$A19,'💸 Expenses'!$B$8:$B$5000,">="&DATE(2026,9,1),'💸 Expenses'!$B$8:$B$5000,"<"&DATE(2026,10,1))
A20: Supermarket/General | B20: =SUMIFS('💸 Expenses'!$F$8:$F$5000,'💸 Expenses'!$E$8:$E$5000,$A20,'💸 Expenses'!$B$8:$B$5000,">="&DATE(2026,5,1),'💸 Expenses'!$B$8:$B$5000,"<"&DATE(2026,6,1)) | C20: =SUMIFS('💸 Expenses'!$F$8:$F$5000,'💸 Expenses'!$E$8:$E$5000,$A20,'💸 Expenses'!$B$8:$B$5000,">="&DATE(2026,6,1),'💸 Expenses'!$B$8:$B$5000,"<"&DATE(2026,7,1)) | D20: =SUMIFS('💸 Expenses'!$F$8:$F$5000,'💸 Expenses'!$E$8:$E$5000,$A20,'💸 Expenses'!$B$8:$B$5000,">="&DATE(2026,7,1),'💸 Expenses'!$B$8:$B$5000,"<"&DATE(2026,8,1)) | E20: =SUMIFS('💸 Expenses'!$F$8:$F$5000,'💸 Expenses'!$E$8:$E$5000,$A20,'💸 Expenses'!$B$8:$B$5000,">="&DATE(2026,8,1),'💸 Expenses'!$B$8:$B$5000,"<"&DATE(2026,9,1)) | F20: =SUMIFS('💸 Expenses'!$F$8:$F$5000,'💸 Expenses'!$E$8:$E$5000,$A20,'💸 Expenses'!$B$8:$B$5000,">="&DATE(2026,9,1),'💸 Expenses'!$B$8:$B$5000,"<"&DATE(2026,10,1))
A21: Ingredients - Vegetables | B21: =SUMIFS('💸 Expenses'!$F$8:$F$5000,'💸 Expenses'!$E$8:$E$5000,$A21,'💸 Expenses'!$B$8:$B$5000,">="&DATE(2026,5,1),'💸 Expenses'!$B$8:$B$5000,"<"&DATE(2026,6,1)) | C21: =SUMIFS('💸 Expenses'!$F$8:$F$5000,'💸 Expenses'!$E$8:$E$5000,$A21,'💸 Expenses'!$B$8:$B$5000,">="&DATE(2026,6,1),'💸 Expenses'!$B$8:$B$5000,"<"&DATE(2026,7,1)) | D21: =SUMIFS('💸 Expenses'!$F$8:$F$5000,'💸 Expenses'!$E$8:$E$5000,$A21,'💸 Expenses'!$B$8:$B$5000,">="&DATE(2026,7,1),'💸 Expenses'!$B$8:$B$5000,"<"&DATE(2026,8,1)) | E21: =SUMIFS('💸 Expenses'!$F$8:$F$5000,'💸 Expenses'!$E$8:$E$5000,$A21,'💸 Expenses'!$B$8:$B$5000,">="&DATE(2026,8,1),'💸 Expenses'!$B$8:$B$5000,"<"&DATE(2026,9,1)) | F21: =SUMIFS('💸 Expenses'!$F$8:$F$5000,'💸 Expenses'!$E$8:$E$5000,$A21,'💸 Expenses'!$B$8:$B$5000,">="&DATE(2026,9,1),'💸 Expenses'!$B$8:$B$5000,"<"&DATE(2026,10,1))
A22: Ingredients - Pantry | B22: =SUMIFS('💸 Expenses'!$F$8:$F$5000,'💸 Expenses'!$E$8:$E$5000,$A22,'💸 Expenses'!$B$8:$B$5000,">="&DATE(2026,5,1),'💸 Expenses'!$B$8:$B$5000,"<"&DATE(2026,6,1)) | C22: =SUMIFS('💸 Expenses'!$F$8:$F$5000,'💸 Expenses'!$E$8:$E$5000,$A22,'💸 Expenses'!$B$8:$B$5000,">="&DATE(2026,6,1),'💸 Expenses'!$B$8:$B$5000,"<"&DATE(2026,7,1)) | D22: =SUMIFS('💸 Expenses'!$F$8:$F$5000,'💸 Expenses'!$E$8:$E$5000,$A22,'💸 Expenses'!$B$8:$B$5000,">="&DATE(2026,7,1),'💸 Expenses'!$B$8:$B$5000,"<"&DATE(2026,8,1)) | E22: =SUMIFS('💸 Expenses'!$F$8:$F$5000,'💸 Expenses'!$E$8:$E$5000,$A22,'💸 Expenses'!$B$8:$B$5000,">="&DATE(2026,8,1),'💸 Expenses'!$B$8:$B$5000,"<"&DATE(2026,9,1)) | F22: =SUMIFS('💸 Expenses'!$F$8:$F$5000,'💸 Expenses'!$E$8:$E$5000,$A22,'💸 Expenses'!$B$8:$B$5000,">="&DATE(2026,9,1),'💸 Expenses'!$B$8:$B$5000,"<"&DATE(2026,10,1))
A23: Ingredients - Beverages | B23: =SUMIFS('💸 Expenses'!$F$8:$F$5000,'💸 Expenses'!$E$8:$E$5000,$A23,'💸 Expenses'!$B$8:$B$5000,">="&DATE(2026,5,1),'💸 Expenses'!$B$8:$B$5000,"<"&DATE(2026,6,1)) | C23: =SUMIFS('💸 Expenses'!$F$8:$F$5000,'💸 Expenses'!$E$8:$E$5000,$A23,'💸 Expenses'!$B$8:$B$5000,">="&DATE(2026,6,1),'💸 Expenses'!$B$8:$B$5000,"<"&DATE(2026,7,1)) | D23: =SUMIFS('💸 Expenses'!$F$8:$F$5000,'💸 Expenses'!$E$8:$E$5000,$A23,'💸 Expenses'!$B$8:$B$5000,">="&DATE(2026,7,1),'💸 Expenses'!$B$8:$B$5000,"<"&DATE(2026,8,1)) | E23: =SUMIFS('💸 Expenses'!$F$8:$F$5000,'💸 Expenses'!$E$8:$E$5000,$A23,'💸 Expenses'!$B$8:$B$5000,">="&DATE(2026,8,1),'💸 Expenses'!$B$8:$B$5000,"<"&DATE(2026,9,1)) | F23: =SUMIFS('💸 Expenses'!$F$8:$F$5000,'💸 Expenses'!$E$8:$E$5000,$A23,'💸 Expenses'!$B$8:$B$5000,">="&DATE(2026,9,1),'💸 Expenses'!$B$8:$B$5000,"<"&DATE(2026,10,1))
A24: Ingredients - Dairy | B24: =SUMIFS('💸 Expenses'!$F$8:$F$5000,'💸 Expenses'!$E$8:$E$5000,$A24,'💸 Expenses'!$B$8:$B$5000,">="&DATE(2026,5,1),'💸 Expenses'!$B$8:$B$5000,"<"&DATE(2026,6,1)) | C24: =SUMIFS('💸 Expenses'!$F$8:$F$5000,'💸 Expenses'!$E$8:$E$5000,$A24,'💸 Expenses'!$B$8:$B$5000,">="&DATE(2026,6,1),'💸 Expenses'!$B$8:$B$5000,"<"&DATE(2026,7,1)) | D24: =SUMIFS('💸 Expenses'!$F$8:$F$5000,'💸 Expenses'!$E$8:$E$5000,$A24,'💸 Expenses'!$B$8:$B$5000,">="&DATE(2026,7,1),'💸 Expenses'!$B$8:$B$5000,"<"&DATE(2026,8,1)) | E24: =SUMIFS('💸 Expenses'!$F$8:$F$5000,'💸 Expenses'!$E$8:$E$5000,$A24,'💸 Expenses'!$B$8:$B$5000,">="&DATE(2026,8,1),'💸 Expenses'!$B$8:$B$5000,"<"&DATE(2026,9,1)) | F24: =SUMIFS('💸 Expenses'!$F$8:$F$5000,'💸 Expenses'!$E$8:$E$5000,$A24,'💸 Expenses'!$B$8:$B$5000,">="&DATE(2026,9,1),'💸 Expenses'!$B$8:$B$5000,"<"&DATE(2026,10,1))
A25: Ingredients - Bread | B25: =SUMIFS('💸 Expenses'!$F$8:$F$5000,'💸 Expenses'!$E$8:$E$5000,$A25,'💸 Expenses'!$B$8:$B$5000,">="&DATE(2026,5,1),'💸 Expenses'!$B$8:$B$5000,"<"&DATE(2026,6,1)) | C25: =SUMIFS('💸 Expenses'!$F$8:$F$5000,'💸 Expenses'!$E$8:$E$5000,$A25,'💸 Expenses'!$B$8:$B$5000,">="&DATE(2026,6,1),'💸 Expenses'!$B$8:$B$5000,"<"&DATE(2026,7,1)) | D25: =SUMIFS('💸 Expenses'!$F$8:$F$5000,'💸 Expenses'!$E$8:$E$5000,$A25,'💸 Expenses'!$B$8:$B$5000,">="&DATE(2026,7,1),'💸 Expenses'!$B$8:$B$5000,"<"&DATE(2026,8,1)) | E25: =SUMIFS('💸 Expenses'!$F$8:$F$5000,'💸 Expenses'!$E$8:$E$5000,$A25,'💸 Expenses'!$B$8:$B$5000,">="&DATE(2026,8,1),'💸 Expenses'!$B$8:$B$5000,"<"&DATE(2026,9,1)) | F25: =SUMIFS('💸 Expenses'!$F$8:$F$5000,'💸 Expenses'!$E$8:$E$5000,$A25,'💸 Expenses'!$B$8:$B$5000,">="&DATE(2026,9,1),'💸 Expenses'!$B$8:$B$5000,"<"&DATE(2026,10,1))
A26: Utilities/Electricity | B26: =SUMIFS('💸 Expenses'!$F$8:$F$5000,'💸 Expenses'!$E$8:$E$5000,$A26,'💸 Expenses'!$B$8:$B$5000,">="&DATE(2026,5,1),'💸 Expenses'!$B$8:$B$5000,"<"&DATE(2026,6,1)) | C26: =SUMIFS('💸 Expenses'!$F$8:$F$5000,'💸 Expenses'!$E$8:$E$5000,$A26,'💸 Expenses'!$B$8:$B$5000,">="&DATE(2026,6,1),'💸 Expenses'!$B$8:$B$5000,"<"&DATE(2026,7,1)) | D26: =SUMIFS('💸 Expenses'!$F$8:$F$5000,'💸 Expenses'!$E$8:$E$5000,$A26,'💸 Expenses'!$B$8:$B$5000,">="&DATE(2026,7,1),'💸 Expenses'!$B$8:$B$5000,"<"&DATE(2026,8,1)) | E26: =SUMIFS('💸 Expenses'!$F$8:$F$5000,'💸 Expenses'!$E$8:$E$5000,$A26,'💸 Expenses'!$B$8:$B$5000,">="&DATE(2026,8,1),'💸 Expenses'!$B$8:$B$5000,"<"&DATE(2026,9,1)) | F26: =SUMIFS('💸 Expenses'!$F$8:$F$5000,'💸 Expenses'!$E$8:$E$5000,$A26,'💸 Expenses'!$B$8:$B$5000,">="&DATE(2026,9,1),'💸 Expenses'!$B$8:$B$5000,"<"&DATE(2026,10,1))
A27: Ingredients - Meat & Fish | B27: =SUMIFS('💸 Expenses'!$F$8:$F$5000,'💸 Expenses'!$E$8:$E$5000,$A27,'💸 Expenses'!$B$8:$B$5000,">="&DATE(2026,5,1),'💸 Expenses'!$B$8:$B$5000,"<"&DATE(2026,6,1)) | C27: =SUMIFS('💸 Expenses'!$F$8:$F$5000,'💸 Expenses'!$E$8:$E$5000,$A27,'💸 Expenses'!$B$8:$B$5000,">="&DATE(2026,6,1),'💸 Expenses'!$B$8:$B$5000,"<"&DATE(2026,7,1)) | D27: =SUMIFS('💸 Expenses'!$F$8:$F$5000,'💸 Expenses'!$E$8:$E$5000,$A27,'💸 Expenses'!$B$8:$B$5000,">="&DATE(2026,7,1),'💸 Expenses'!$B$8:$B$5000,"<"&DATE(2026,8,1)) | E27: =SUMIFS('💸 Expenses'!$F$8:$F$5000,'💸 Expenses'!$E$8:$E$5000,$A27,'💸 Expenses'!$B$8:$B$5000,">="&DATE(2026,8,1),'💸 Expenses'!$B$8:$B$5000,"<"&DATE(2026,9,1)) | F27: =SUMIFS('💸 Expenses'!$F$8:$F$5000,'💸 Expenses'!$E$8:$E$5000,$A27,'💸 Expenses'!$B$8:$B$5000,">="&DATE(2026,9,1),'💸 Expenses'!$B$8:$B$5000,"<"&DATE(2026,10,1))
