Workbook

Sheet Capital & Ownership
B1: LOKA — CAPITAL, OWNERSHIP & PRE-OPENING EXPENSES
B2: Last updated: 6 Jun 2026 | Capital, Acquisition & Pre-Opening Expenses
B4: A. OWNERSHIP STRUCTURE
B5: Owner | C5: Share % | D5: Capital ($) | E5: Expenses ($) | F5: Remaining ($) | G5: Role / Notes
B6: Lohith Reddy | C6: 0.5 | D6: 300000 | E6: =D55 -> 28947 | F6: =D6-E6 -> 271053 | G6: 50% — Managing Partner
B7: Kashigoud Patil | C7: 0.3 | D7: 180000 | E7: =D42 -> 141568.34 | F7: =D7-E7 -> 38431.66 | G7: 30% — Partner
B8: Shashirekha Basavaraju | C8: 0.2 | D8: 120000 | E8: =D68 -> 106895 | F8: =D8-E8 -> 13105 | G8: 20% — Partner
B9: TOTAL | C9: =SUM(C6:C8) -> 1 | D9: =SUM(D6:D8) -> 600000 | E9: =SUM(E6:E8) -> 277410.34 | F9: =SUM(F6:F8) -> 322589.66
B11: B. RESTAURANT ACQUISITION — $390,000 TOTAL
B12: Description | C12: Date | D12: Amount ($) | E12: Paid By | F12: Status | G12: Notes
B13: TOTAL Purchase Price — Previous Owners | D13: 390000 | E13: All Partners | F13: ⚠️ PARTIALLY PAID — $134,500 remaining | G13: Full acquisition amount
B14: Advance Payment (paid by Lohith) | D14: 5000 | E14: Lohith Reddy | F14: ✅ PAID | G14: Advance to previous owners
B15: Payment to Previous Owners | C15: 46176 | D15: 95000 | E15: Lohith Reddy | F15: ✅ PAID | G15: Paid from restaurant operating balance — 3 Jun 2026
B16: Payment to Previous Owner — Account 1 | C16: 46177 | D16: 8000 | E16: Lohith Reddy | F16: ✅ PAID | G16: Capital payment — from main budget — transferred to different accounts
B17: Payment to Previous Owner — Account 2 | C17: 46177 | D17: 4500 | E17: Lohith Reddy | F17: ✅ PAID | G17: Capital payment — from main budget — transferred to different account
B18: Payment to Previous Owner — Account 3 | C18: 46177 | D18: 15000 | E18: Lohith Reddy | F18: ✅ PAID | G18: Capital payment — from main budget — transferred to different accounts
B19: Payment to Previous Owner — Account 4 | C19: 46177 | D19: 10000 | E19: Lohith Reddy | F19: ✅ PAID | G19: Capital payment — from main budget — transferred to different accounts
B20: Payment to Previous Owner — Account 5 | C20: 46177 | D20: 44000 | E20: Lohith Reddy | F20: ✅ PAID | G20: Capital payment — from main budget — transferred to different accounts
B21: Payment to Previous Owner — Account 6 | C21: 46177 | D21: 44000 | E21: Lohith Reddy | F21: ✅ PAID | G21: Capital payment — from main budget — transferred to different accounts
B22: Payment to Previous Owner — Jun 5 | C22: 46178 | D22: 30000 | E22: Lohith Reddy | F22: ✅ PAID | G22: Transfer — 5 Jun 2026
B23: Balance Remaining | D23: =D13-SUM(D14:D22) -> 134500 | E23: — | F23: ⏳ PENDING | G23: $390,000 − $255,500 paid = $134,500 remaining
B25: PAYMENT BREAKDOWN — How the $390,000 will be funded
B26: Source | C26: From | D26: Amount ($) | E26: Toward % | F26: Cumulative | G26: Notes
B27: Kashigoud Transfer to Lohith | C27: Kashigoud Patil | D27: 125000 | E27: =D27/390000 -> 0.32051282 | F27: =D27 -> 125000 | G27: Full Kashi transfer
B28: Shashirekha Transfer to Lohith | C28: Shashirekha B. | D28: 100000 | E28: =D28/390000 -> 0.25641026 | F28: =D27+D28 -> 225000 | G28: Full Shashi transfer
B29: Lohith Reddy (own funds) | C29: Lohith Reddy | D29: =390000-D27-D28 -> 165000 | E29: =D29/390000 -> 0.42307692 | F29: =D27+D28+D29 -> 390000 | G29: Balance from Lohith
B30: Advance Already Paid | C30: Lohith Reddy | D30: 5000 | E30: =D30/390000 -> 0.012820513 | F30: Paid ✅ | G30: Already paid
B32: C. PRE-OPENING EXPENSES — KASHIGOUD PATIL
B33: Description | C33: Date | D33: Amount ($) | E33: Paid To | F33: Category | G33: Notes
B34: Transfer to Lohith Reddy (capital allocation) | D34: 125000 | E34: Bank → Lohith | F34: Internal Transfer | G34: For acquisition & expenses
B35: Soft Restaurant License & Tools | D35: 15195 | E35: Soft App | F35: Software / License | G35: POS + mgmt tools
B36: Mercado Pago Terminal | D36: 500 | E36: Soft App / MP | F36: POS Hardware | G36: MP card reader terminal fee
B37: Camera Cloud Recording — 7 Day Continuous (28 May) | C37: 46170 | D37: 436.12 | E37: Kashigoud Patil (VISA ••••9193) | F37: Technology / Security | G37: Shenzhen Tange — cloud CCTV recording 1yr — US$23.90 = MXN $436.12
B38: Camera Cloud Recording — 7 Day Continuous (29 May) | C38: 46171 | D38: 437.22 | E38: Kashigoud Patil (VISA ••••9193) | F38: Technology / Security | G38: Shenzhen Tange — cloud CCTV recording 1yr — US$23.90 = MXN $437.22
B42: KASHIGOUD TOTAL | D42: =SUM(D34:D41) -> 141568.34
B44: D. PRE-OPENING EXPENSES — LOHITH REDDY
B45: Description | C45: Date | D45: Amount ($) | E45: Paid To | F45: Category | G45: Notes
B46: Advance Payment to Previous Owners | D46: 5000 | E46: Previous Owners | F46: Acquisition | G46: 5k advance on 390k purchase
B47: Notary Fees | D47: 15797 | E47: Notary Office | F47: Legal | G47: Legal fees for restaurant acquisition
B48: Poliza Juridica (Legal Policy) | D48: 5150 | E48: Legal / Insurance | F48: Legal | G48: Poliza Juridica — legal insurance policy
...

Sheet 📊 Dashboard
A2: 🍽️ LOKA Cafe Restaurante | H2: Restaurant Manager — powered by Soft + Excel
B5: 📌 HOW TO USE: ① Each update, go to 📅 Daily Log → enter Date + Revenue + Orders from Soft App ② Fill 💸 Expenses for costs paid ③ Update 📦 Inventory when stock changes ④ This dashboard updates automatically
B7: 💰 REVENUE (auto-pulled from Daily Log)
B9: TODAY'S REVENUE | D9: WEEK REVENUE | F9: MONTH REVENUE | H9: TODAY'S EXPENSES | J9: TODAY'S NET PROFIT | L9: AVG TICKET
B10: ='📅 Daily Log'!F6 -> 3727 | D10: ='📅 Daily Log'!N6 -> 0 | F10: ='📅 Daily Log'!O6 -> 0 | H10: ='📅 Daily Log'!H6 -> 3187.11 | J10: ='📅 Daily Log'!I6 -> 539.89 | L10: =IFERROR('📅 Daily Log'!F6/'📅 Daily Log'!G6,0) -> 37.646465
B14: 📊 OPERATIONS
B16: TODAY'S ORDERS | D16: WEEK ORDERS | F16: PROFIT MARGIN % | H16: LOW STOCK ITEMS | J16: WEEK EXPENSES | L16: PENDING ORDERS
B17: ='📅 Daily Log'!G6 -> 99 | D17: =IFERROR(SUMPRODUCT((ISNUMBER('📅 Daily Log'!$B$8:$B$500))*('📅 Daily Log'!$B$8:$B$500>=TODAY()-MOD(TODAY()-2,7))*('📅 Daily Log'!$B$8:$B$500<TODAY()-MOD(TODAY()-2,7)+7)*IF(ISNUMBER('📅 Daily Log'!$G$8:$G$500),'📅 Daily Log'!$G$8:$G$500,0)),0) -> 0 | F17: =IFERROR('📅 Daily Log'!J6,0) -> 0.14485914 | H17: ='📦 Inventory'!H5 -> ALERT COUNT | J17: ='📅 Daily Log'!P6 -> 0 | L17: ='🚚 Suppliers'!H5 -> PENDING COUNT
B21: 📅 LAST 10 DAYS (from Daily Log — updates automatically)
B22: Date | C22: Day | D22: Revenue ($) | E22: Orders | F22: Avg Ticket | G22: Expenses ($) | H22: Net Profit ($) | I22: Margin % | J22: Notes | K22: vs Prev Day
B23: ='📅 Daily Log'!B8 -> 18-May-2026 | C23: ='📅 Daily Log'!F8 -> 3689 | D23: ='📅 Daily Log'!G8 -> 0 | E23: =IFERROR('📅 Daily Log'!F8/'📅 Daily Log'!G8,0) -> 0 | F23: ='📅 Daily Log'!H8 -> 2629 | G23: ='📅 Daily Log'!I8 -> 1060 | H23: ='📅 Daily Log'!J8 -> 0.28734074 | I23: ='📅 Daily Log'!K8 -> 0 | J23: ='📅 Daily Log'!K8 -> 0 | K23: —
B24: ='📅 Daily Log'!B9 -> 19-May-2026 | C24: ='📅 Daily Log'!F9 -> 3854 | D24: ='📅 Daily Log'!G9 -> 0 | E24: =IFERROR('📅 Daily Log'!F9/'📅 Daily Log'!G9,0) -> 0 | F24: ='📅 Daily Log'!H9 -> 30 | G24: ='📅 Daily Log'!I9 -> 3824 | H24: ='📅 Daily Log'!J9 -> 0.99221588 | I24: ='📅 Daily Log'!K9 -> 0 | J24: ='📅 Daily Log'!K9 -> 0 | K24: =IFERROR(IF(D24>D23,"▲ +"&TEXT(D24-D23,"$#,##0"),IF(D24<D23,"▼ "&TEXT(D24-D23,"$#,##0"),"— same")),"") -> — same
B25: ='📅 Daily Log'!B10 -> 20-May-2026 | C25: ='📅 Daily Log'!F10 -> 4124 | D25: ='📅 Daily Log'!G10 -> 0 | E25: =IFERROR('📅 Daily Log'!F10/'📅 Daily Log'!G10,0) -> 0 | F25: ='📅 Daily Log'!H10 -> 3777 | G25: ='📅 Daily Log'!I10 -> 347 | H25: ='📅 Daily Log'!J10 -> 0.08414161 | I25: ='📅 Daily Log'!K10 -> 0 | J25: ='📅 Daily Log'!K10 -> 0 | K25: =IFERROR(IF(D25>D24,"▲ +"&TEXT(D25-D24,"$#,##0"),IF(D25<D24,"▼ "&TEXT(D25-D24,"$#,##0"),"— same")),"") -> — same
B26: ='📅 Daily Log'!B11 -> 21-May-2026 | C26: ='📅 Daily Log'!F11 -> 4733 | D26: ='📅 Daily Log'!G11 -> 0 | E26: =IFERROR('📅 Daily Log'!F11/'📅 Daily Log'!G11,0) -> 0 | F26: ='📅 Daily Log'!H11 -> 2434 | G26: ='📅 Daily Log'!I11 -> 2299 | H26: ='📅 Daily Log'!J11 -> 0.48573843 | I26: ='📅 Daily Log'!K11 -> 0 | J26: ='📅 Daily Log'!K11 -> 0 | K26: =IFERROR(IF(D26>D25,"▲ +"&TEXT(D26-D25,"$#,##0"),IF(D26<D25,"▼ "&TEXT(D26-D25,"$#,##0"),"— same")),"") -> — same
B27: ='📅 Daily Log'!B12 -> 22-May-2026 | C27: ='📅 Daily Log'!F12 -> 4282 | D27: ='📅 Daily Log'!G12 -> 0 | E27: =IFERROR('📅 Daily Log'!F12/'📅 Daily Log'!G12,0) -> 0 | F27: ='📅 Daily Log'!H12 -> 1457 | G27: ='📅 Daily Log'!I12 -> 2825 | H27: ='📅 Daily Log'!J12 -> 0.65973844 | I27: ='📅 Daily Log'!K12 -> 0 | J27: ='📅 Daily Log'!K12 -> 0 | K27: =IFERROR(IF(D27>D26,"▲ +"&TEXT(D27-D26,"$#,##0"),IF(D27<D26,"▼ "&TEXT(D27-D26,"$#,##0"),"— same")),"") -> — same
B28: ='📅 Daily Log'!B13 -> 23-May-2026 | C28: ='📅 Daily Log'!F13 -> 3802 | D28: ='📅 Daily Log'!G13 -> 0 | E28: =IFERROR('📅 Daily Log'!F13/'📅 Daily Log'!G13,0) -> 0 | F28: ='📅 Daily Log'!H13 -> 8953.43 | G28: ='📅 Daily Log'!I13 -> -5151.43 | H28: ='📅 Daily Log'!J13 -> -1.3549264 | I28: ='📅 Daily Log'!K13 -> Payroll week — John $3,250 + Debi $1,500 + Victor $666 + Tips $1,198 | J28: ='📅 Daily Log'!K13 -> Payroll week — John $3,250 + Debi $1,500 + Victor $666 + Tips $1,198 | K28: =IFERROR(IF(D28>D27,"▲ +"&TEXT(D28-D27,"$#,##0"),IF(D28<D27,"▼ "&TEXT(D28-D27,"$#,##0"),"— same")),"") -> — same
B29: ='📅 Daily Log'!B14 -> 24-May-2026 | C29: ='📅 Daily Log'!F14 -> 1198 | D29: ='📅 Daily Log'!G14 -> 0 | E29: =IFERROR('📅 Daily Log'!F14/'📅 Daily Log'!G14,0) -> 0 | F29: ='📅 Daily Log'!H14 -> 1076 | G29: ='📅 Daily Log'!I14 -> 122 | H29: ='📅 Daily Log'!J14 -> 0.10183639 | I29: ='📅 Daily Log'!K14 -> 🔴 CLOSED — Sunday. Expenses are prep purchases for the week ahead. | J29: ='📅 Daily Log'!K14 -> 🔴 CLOSED — Sunday. Expenses are prep purchases for the week ahead. | K29: =IFERROR(IF(D29>D28,"▲ +"&TEXT(D29-D28,"$#,##0"),IF(D29<D28,"▼ "&TEXT(D29-D28,"$#,##0"),"— same")),"") -> — same
B30: ='📅 Daily Log'!B15 -> 25-May-2026 | C30: ='📅 Daily Log'!F15 -> 3730 | D30: ='📅 Daily Log'!G15 -> 0 | E30: =IFERROR('📅 Daily Log'!F15/'📅 Daily Log'!G15,0) -> 0 | F30: ='📅 Daily Log'!H15 -> 3021.45 | G30: ='📅 Daily Log'!I15 -> 708.55 | H30: ='📅 Daily Log'!J15 -> 0.18995979 | I30: ='📅 Daily Log'!K15 -> 0 | J30: ='📅 Daily Log'!K15 -> 0 | K30: =IFERROR(IF(D30>D29,"▲ +"&TEXT(D30-D29,"$#,##0"),IF(D30<D29,"▼ "&TEXT(D30-D29,"$#,##0"),"— same")),"") -> — same
B31: ='📅 Daily Log'!B16 -> 26-May-2026 | C31: ='📅 Daily Log'!F16 -> 4264 | D31: ='📅 Daily Log'!G16 -> 0 | E31: =IFERROR('📅 Daily Log'!F16/'📅 Daily Log'!G16,0) -> 0 | F31: ='📅 Daily Log'!H16 -> 1191.6 | G31: ='📅 Daily Log'!I16 -> 3072.4 | H31: ='📅 Daily Log'!J16 -> 0.72054409 | I31: ='📅 Daily Log'!K16 -> 0 | J31: ='📅 Daily Log'!K16 -> 0 | K31: =IFERROR(IF(D31>D30,"▲ +"&TEXT(D31-D30,"$#,##0"),IF(D31<D30,"▼ "&TEXT(D31-D30,"$#,##0"),"— same")),"") -> — same
B32: ='📅 Daily Log'!B17 -> 27-May-2026 | C32: ='📅 Daily Log'!F17 -> 3621 | D32: ='📅 Daily Log'!G17 -> 0 | E32: =IFERROR('📅 Daily Log'!F17/'📅 Daily Log'!G17,0) -> 0 | F32: ='📅 Daily Log'!H17 -> 1073.22 | G32: ='📅 Daily Log'!I17 -> 2547.78 | H32: ='📅 Daily Log'!J17 -> 0.70361226 | I32: ='📅 Daily Log'!K17 -> 0 | J32: ='📅 Daily Log'!K17 -> 0 | K32: =IFERROR(IF(D32>D31,"▲ +"&TEXT(D32-D31,"$#,##0"),IF(D32<D31,"▼ "&TEXT(D32-D31,"$#,##0"),"— same")),"") -> — same
B34: ⚠️ INVENTORY ALERTS (from Inventory sheet)
B35: Ingredient | F35: Min Level | H35: Status | J35: Action Needed
B36: ='📦 Inventory'!B9 -> Carne de Res | E36: ='📦 Inventory'!E9 -> 0 | G36: ='📦 Inventory'!F9 -> 0 | I36: ='📦 Inventory'!J9 -> — | K36: =IF('📦 Inventory'!E9=0,"🚫 Order immediately",IF('📦 Inventory'!E9<='📦 Inventory'!F9,"⚠️ Reorder soon","✅ OK")) -> 🚫 Order immediately
B37: ='📦 Inventory'!B10 -> Jamon Mexicano | E37: ='📦 Inventory'!E10 -> 0 | G37: ='📦 Inventory'!F10 -> 0 | I37: ='📦 Inventory'!J10 -> — | K37: =IF('📦 Inventory'!E10=0,"🚫 Order immediately",IF('📦 Inventory'!E10<='📦 Inventory'!F10,"⚠️ Reorder soon","✅ OK")) -> 🚫 Order immediately
B38: ='📦 Inventory'!B11 -> Pollo | E38: ='📦 Inventory'!E11 -> 0 | G38: ='📦 Inventory'!F11 -> 0 | I38: ='📦 Inventory'!J11 -> — | K38: =IF('📦 Inventory'!E11=0,"🚫 Order immediately",IF('📦 Inventory'!E11<='📦 Inventory'!F11,"⚠️ Reorder soon","✅ OK")) -> 🚫 Order immediately
B39: ='📦 Inventory'!B12 -> Chuletas de Carne | E39: ='📦 Inventory'!E12 -> 0 | G39: ='📦 Inventory'!F12 -> 0 | I39: ='📦 Inventory'!J12 -> — | K39: =IF('📦 Inventory'!E12=0,"🚫 Order immediately",IF('📦 Inventory'!E12<='📦 Inventory'!F12,"⚠️ Reorder soon","✅ OK")) -> 🚫 Order immediately
B40: ='📦 Inventory'!B13 -> Costillas de Cerdo | E40: ='📦 Inventory'!E13 -> 0 | G40: ='📦 Inventory'!F13 -> 0 | I40: ='📦 Inventory'!J13 -> — | K40: =IF('📦 Inventory'!E13=0,"🚫 Order immediately",IF('📦 Inventory'!E13<='📦 Inventory'!F13,"⚠️ Reorder soon","✅ OK")) -> 🚫 Order immediately
B42: 💼 CAPITAL & ACQUISITION STATUS — live from Capital & Ownership sheet
B44: TOTAL BUDGET | D44: TOTAL CASH OUT | F44: REMAINING BUDGET | H44: ACQUISITION PRICE | J44: ADVANCE PAID | L44: BALANCE PENDING
B45: ='Capital & Ownership'!C63 -> 0 | D45: ='Capital & Ownership'!C72 -> 600000 | F45: ='Capital & Ownership'!C73 -> 390000 | H45: ='Capital & Ownership'!C64 -> 0 | J45: ='Capital & Ownership'!C65 -> 46176 | L45: ='Capital & Ownership'!C66 -> 0
B46: All 3 partners | D46: Excl. internal transfers | F46: Available for operations | H46: To previous owners | J46: ✅ Paid by Lohith | L46: ⏳ Outstanding
B48: 👥 OWNER CAPITAL SUMMARY
B49: OWNER | D49: SHARE % | F49: CAPITAL ($) | G49: ROLE | H49: EXPENSES ($) | J49: REMAINING ($) | L49: % SPENT
B50: ='Capital & Ownership'!B6 -> Lohith Reddy | D50: ='Capital & Ownership'!C6 -> 0.5 | F50: ='Capital & Ownership'!D6 -> 300000 | G50: 50% — Managing Partner | H50: ='Capital & Ownership'!E6 -> 28947 | J50: ='Capital & Ownership'!F6 -> 271053 | L50: =IFERROR('Capital & Ownership'!E6/'Capital & Ownership'!D6,0) -> 0.09649
B51: ='Capital & Ownership'!B7 -> Kashigoud Patil | D51: ='Capital & Ownership'!C7 -> 0.3 | F51: ='Capital & Ownership'!D7 -> 180000 | G51: 30% — Partner | H51: ='Capital & Ownership'!E7 -> 141568.34 | J51: ='Capital & Ownership'!F7 -> 38431.66 | L51: =IFERROR('Capital & Ownership'!E7/'Capital & Ownership'!D7,0) -> 0.78649078
B52: ='Capital & Ownership'!B8 -> Shashirekha Basavaraju | D52: ='Capital & Ownership'!C8 -> 0.2 | F52: ='Capital & Ownership'!D8 -> 120000 | G52: 20% — Partner | H52: ='Capital & Ownership'!E8 -> 106895 | J52: ='Capital & Ownership'!F8 -> 13105 | L52: =IFERROR('Capital & Ownership'!E8/'Capital & Ownership'!D8,0) -> 0.89079167
B53: TOTAL | D53: ='Capital & Ownership'!C9 -> 1 | F53: ='Capital & Ownership'!D9 -> 600000 | H53: ='Capital & Ownership'!E9 -> 277410.34 | J53: ='Capital & Ownership'!F9 -> 322589.66 | L53: =IFERROR('Capital & Ownership'!E9/'Capital & Ownership'!D9,0) -> 0.46235057
B55: 🧾 PRE-OPENING EXPENSES BREAKDOWN
B56: EXPENSE ITEM | E56: PAID BY | G56: AMOUNT ($) | I56: CATEGORY | K56: STATUS
B57: ='Capital & Ownership'!B13 -> TOTAL Purchase Price — Previous Owners | E57: All Partners | G57: ='Capital & Ownership'!D13 -> 390000 | I57: Acquisition | K57: ⚠️ Not Fully Paid
...

Sheet 📅 Daily Log
A2: 📅 LOKA — DAILY LOG | I2: Enter 2 values from Soft App each day → everything else calculates
B5: ✏️ INSTRUCTIONS: Each time you open this file, add a new row below. Fill only the BLUE cells: 📌 Date | 💰 Revenue (from Soft App end-of-day report) | 🛒 Orders (from Soft App) | 📝 Notes (optional). All other columns calculate automatically.
F6: =SUMIFS($D$8:$D$500,$B$8:$B$500,TODAY())+SUMIFS($E$8:$E$500,$B$8:$B$500,TODAY())+SUMIFS($G$8:$G$500,$B$8:$B$500,TODAY()) -> 3727 | G6: =SUMIFS($G$8:$G$500,$B$8:$B$500,TODAY()) -> 99 | H6: =SUMIFS($H$8:$H$500,$B$8:$B$500,TODAY()) -> 3187.11 | I6: =F6-H6 -> 539.89 | J6: =IFERROR(I6/F6,0) -> 0.14485914 | M6: =SUMPRODUCT((ISNUMBER($B$8:$B$500))*($B$8:$B$500>=TODAY()-MOD(TODAY()-2,7))*($B$8:$B$500<TODAY()-MOD(TODAY()-2,7)+7)*IF(ISNUMBER($F$8:$F$500),$F$8:$F$500,0)) -> 0 | N6: =SUMPRODUCT((ISNUMBER($B$8:$B$500))*($B$8:$B$500>=TODAY()-MOD(TODAY()-2,7))*($B$8:$B$500<TODAY()-MOD(TODAY()-2,7)+7)*IF(ISNUMBER($F$8:$F$500),$F$8:$F$500,0)) -> 0 | O6: =SUMPRODUCT((ISNUMBER($B$8:$B$500))*(MONTH($B$8:$B$500)=MONTH(TODAY()))*(YEAR($B$8:$B$500)=YEAR(TODAY()))*IF(ISNUMBER($F$8:$F$500),$F$8:$F$500,0)) -> 0 | P6: =SUMPRODUCT((ISNUMBER($B$8:$B$500))*($B$8:$B$500>=TODAY()-MOD(TODAY()-2,7))*($B$8:$B$500<TODAY()-MOD(TODAY()-2,7)+7)*IF(ISNUMBER($H$8:$H$500),$H$8:$H$500,0)) -> 0 | Q6: =M6-P6 -> 0
B7: Date | C7: Day | D7: Card / Mercado Pago ($) | E7: Cash ($) | F7: Total Revenue ($) | G7: Transfer ($) | H7: Expenses $ | I7: Net Profit $ | J7: Margin % | K7: Notes | L7: Source | M7: WEEK PROFIT | N7: CUMUL. REVENUE | O7: MONTH REVENUE | P7: Week Expenses | Q7: Week Profit
B8: 18-May-2026 | C8: Mon | D8: 2229 | E8: 1460 | F8: =IFERROR(D8+E8+G8,0) -> 3689 | H8: 2629 | I8: =IFERROR(F8-H8,0) -> 1060 | J8: =IFERROR(I8/F8,0) -> 0.28734074 | L8: Manual Bills
B9: 19-May-2026 | C9: Tue | D9: 2125 | E9: 1729 | F9: =IFERROR(D9+E9+G9,0) -> 3854 | H9: 30 | I9: =IFERROR(F9-H9,0) -> 3824 | J9: =IFERROR(I9/F9,0) -> 0.99221588 | L9: Manual Bills
B10: 20-May-2026 | C10: Wed | D10: 1459 | E10: 2665 | F10: =IFERROR(D10+E10+G10,0) -> 4124 | H10: 3777 | I10: =IFERROR(F10-H10,0) -> 347 | J10: =IFERROR(I10/F10,0) -> 0.08414161 | L10: Manual Bills
B11: 21-May-2026 | C11: Thu | D11: 2570 | E11: 2163 | F11: =IFERROR(D11+E11+G11,0) -> 4733 | H11: 2434 | I11: =IFERROR(F11-H11,0) -> 2299 | J11: =IFERROR(I11/F11,0) -> 0.48573843 | L11: Manual Bills
B12: 22-May-2026 | C12: Fri | D12: 1959 | E12: 2323 | F12: =IFERROR(D12+E12+G12,0) -> 4282 | H12: 1457 | I12: =IFERROR(F12-H12,0) -> 2825 | J12: =IFERROR(I12/F12,0) -> 0.65973844 | L12: Manual Bills
B13: 23-May-2026 | C13: Sat | D13: 2044 | E13: 1758 | F13: =IFERROR(D13+E13+G13,0) -> 3802 | H13: 8953.43 | I13: =IFERROR(F13-H13,0) -> -5151.43 | J13: =IFERROR(I13/F13,0) -> -1.3549264 | K13: Payroll week — John $3,250 + Debi $1,500 + Victor $666 + Tips $1,198 | L13: Manual Bills
B14: 24-May-2026 | C14: Sun | E14: 1198 | F14: =IFERROR(D14+E14+G14,0) -> 1198 | H14: 1076 | I14: =IFERROR(F14-H14,0) -> 122 | J14: =IFERROR(I14/F14,0) -> 0.10183639 | K14: 🔴 CLOSED — Sunday. Expenses are prep purchases for the week ahead. | L14: Manual Bills
B15: 25-May-2026 | C15: Mon | D15: 2106 | E15: 1624 | F15: =IFERROR(D15+E15+G15,0) -> 3730 | H15: 3021.45 | I15: =IFERROR(F15-H15,0) -> 708.55 | J15: =IFERROR(I15/F15,0) -> 0.18995979 | L15: Manual Bills
B16: 26-May-2026 | C16: Tue | D16: 1909 | E16: 2355 | F16: =IFERROR(D16+E16+G16,0) -> 4264 | H16: 1191.6 | I16: =IFERROR(F16-H16,0) -> 3072.4 | J16: =IFERROR(I16/F16,0) -> 0.72054409 | L16: Manual Bills
B17: 27-May-2026 | C17: Wed | D17: 1956 | E17: 1665 | F17: =IFERROR(D17+E17+G17,0) -> 3621 | H17: 1073.22 | I17: =IFERROR(F17-H17,0) -> 2547.78 | J17: =IFERROR(I17/F17,0) -> 0.70361226 | L17: Manual Bills
B18: 28-May-2026 | C18: Thu | D18: 1501 | E18: 2569 | F18: =IFERROR(D18+E18+G18,0) -> 4070 | H18: 1931.34 | I18: =IFERROR(F18-H18,0) -> 2138.66 | J18: =IFERROR(I18/F18,0) -> 0.52546929 | L18: Manual Bills
B19: 29-May-2026 | C19: Fri | D19: 3369 | E19: 2717 | F19: =IFERROR(D19+E19+G19,0) -> 6086 | H19: 257.29 | I19: =IFERROR(F19-H19,0) -> 5828.71 | J19: =IFERROR(I19/F19,0) -> 0.95772429 | L19: Manual Bills
B20: 30-May-2026 | C20: Sat | D20: 3457 | E20: 1146 | F20: =IFERROR(D20+E20+G20,0) -> 4603 | H20: 5974.3 | I20: =IFERROR(F20-H20,0) -> -1371.3 | J20: =IFERROR(I20/F20,0) -> -0.2979144 | L20: Manual Bills
B21: 31-May-2026 | C21: Sun | E21: 893 | F21: =IFERROR(D21+E21+G21,0) -> 893 | H21: 312 | I21: =IFERROR(F21-H21,0) -> 581 | J21: =IFERROR(I21/F21,0) -> 0.6506159 | L21: Manual Bills
B22: 01-Jun-2026 | C22: Mon | D22: 3433 | E22: 1276 | F22: =IFERROR(D22+E22+G22,0) -> 5019 | G22: 310 | H22: 6029.64 | I22: =IFERROR(F22-H22,0) -> -1010.64 | J22: =IFERROR(I22/F22,0) -> -0.20136282 | L22: Manual Bills
B23: 02-Jun-2026 | C23: Tue | D23: 1240 | E23: 320 | F23: =IFERROR(D23+E23+G23,0) -> 1843 | G23: 283 | H23: 2379.11 | I23: =IFERROR(F23-H23,0) -> -536.11 | J23: =IFERROR(I23/F23,0) -> -0.29088985 | L23: Manual Bills
B24: 03-Jun-2026 | C24: Wed | D24: 1853 | E24: 1939 | F24: =IFERROR(D24+E24+G24,0) -> 3912 | G24: 120 | H24: 4033.86 | I24: =IFERROR(F24-H24,0) -> -121.86 | J24: =IFERROR(I24/F24,0) -> -0.031150307 | L24: Manual Bills
B25: 04-Jun-2026 | C25: Thu | D25: 2712 | E25: 1045 | F25: =IFERROR(D25+E25+G25,0) -> 3757 | H25: 20959.96 | I25: =IFERROR(F25-H25,0) -> -17202.96 | J25: =IFERROR(I25/F25,0) -> -4.5789087 | L25: Manual Bills
B26: 05-Jun-2026 | C26: Fri | D26: 2495 | E26: 1778 | F26: =IFERROR(D26+E26+G26,0) -> 4408 | G26: 135 | H26: 878.06 | I26: =IFERROR(F26-H26,0) -> 3529.94 | J26: =IFERROR(I26/F26,0) -> 0.80080309 | L26: Manual Bills
B27: 06-Jun-2026 | C27: Sat | D27: 580 | E27: 1754 | F27: =IFERROR(D27+E27+G27,0) -> 2334 | H27: 5414 | I27: =IFERROR(F27-H27,0) -> -3080 | J27: =IFERROR(I27/F27,0) -> -1.319623 | L27: Manual Bills
B28: 07-Jun-2026 | C28: Sun | F28: 0 | H28: 1671 | I28: =IFERROR(F28-H28,0) -> -1671 | L28: Manual Bills
B29: 08-Jun-2026 | C29: Mon | D29: 1778 | E29: 1850 | F29: =IFERROR(D29+E29+G29,0) -> 3727 | G29: 99 | H29: 3187.11 | I29: =IFERROR(F29-H29,0) -> 539.89 | J29: =IFERROR(I29/F29,0) -> 0.14485914 | L29: Manual Bills

Sheet 💸 Expenses
A2: 💸 LOKA — EXPENSES TRACKER | E2: Log every cost: ingredients, staff, utilities, supplies…
B5: TODAY | C5: THIS WEEK | D5: THIS MONTH | E5: INGREDIENTS | F5: STAFF | G5: UTILITIES | H5: TODAY TOTAL | I5: WEEK TOTAL
B6: =SUMIFS($F$8:$F$500,$B$8:$B$500,TODAY()) -> 3187.11 | C6: =SUMIFS($F$8:$F$500,$B$8:$B$500,">="&(TODAY()-WEEKDAY(TODAY(),2)+1),$B$8:$B$500,"<="&(TODAY()-WEEKDAY(TODAY(),2)+7)) -> 3187.11 | D6: =SUMIFS($F$8:$F$500,$B$8:$B$500,">="&DATE(YEAR(TODAY()),MONTH(TODAY()),1),$B$8:$B$500,"<"&DATE(YEAR(TODAY()),MONTH(TODAY())+1,1)) -> 44552.74 | E6: =SUMIF($E$8:$E$500,"Ingredients*",$F$8:$F$500) -> 33818.76 | F6: =SUMIF($E$8:$E$500,"Staff*",$F$8:$F$500) -> 20714.65 | G6: =SUMIF($E$8:$E$500,"Supplies*",$F$8:$F$500)+SUMIF($E$8:$E$500,"Utilities*",$F$8:$F$500) -> 3438.96 | H6: =SUMIFS($F$8:$F$500,$B$8:$B$500,TODAY()) -> 3187.11 | I6: =SUMIFS($F$8:$F$500,$B$8:$B$500,">="&(TODAY()-WEEKDAY(TODAY(),2)+1),$B$8:$B$500,"<="&(TODAY()-WEEKDAY(TODAY(),2)+7)) -> 3187.11
B7: Date | C7: Description | D7: Supplier | E7: Category | F7: Amount ($) | G7: Paid By | H7: Payment Method | I7: Status | J7: Notes
B8: 46160 | C8: Carne | D8: — | E8: Ingredients - Meat | F8: 420 | G8: Restaurant | H8: Cash | I8: ✅ Paid
B9: 46160 | C9: Basicos | D9: — | E9: Ingredients - Pantry | F9: 1068 | G9: Restaurant | H9: Cash | I9: ✅ Paid
B10: 46160 | C10: Real Pan Services | D10: Real Pan | E10: Ingredients - Bread | F10: 522 | G10: Restaurant | H10: Cash | I10: ✅ Paid
B11: 46160 | C11: Chedruai | D11: Chedraui | E11: Supermarket / General | F11: 129 | G11: Restaurant | H11: Cash | I11: ✅ Paid
B12: 46160 | C12: Vegetables | D12: Abastos | E12: Ingredients - Vegetables | F12: 400 | G12: Restaurant | H12: Cash | I12: ✅ Paid
B13: 46160 | C13: Vegetables | D13: — | E13: Ingredients - Vegetables | F13: 90 | G13: Restaurant | H13: Cash | I13: ✅ Paid
B14: 46161 | C14: Arroz | D14: — | E14: Ingredients - Pantry | F14: 30 | G14: Restaurant | H14: Cash | I14: ✅ Paid
B15: 46162 | C15: Lechuga | D15: — | E15: Ingredients - Vegetables | F15: 65 | G15: Restaurant | H15: Cash | I15: ✅ Paid
B16: 46162 | C16: Tortillas | D16: — | E16: Ingredients - Pantry | F16: 26 | G16: Restaurant | H16: Cash | I16: ✅ Paid
B17: 46162 | C17: Jamon Mexicana | D17: — | E17: Ingredients - Meat | F17: 88 | G17: Restaurant | H17: Cash | I17: ✅ Paid
B18: 46162 | C18: Carne | D18: — | E18: Ingredients - Meat | F18: 1104 | G18: Restaurant | H18: Cash | I18: ✅ Paid
B19: 46162 | C19: Salmon | D19: — | E19: Ingredients - Meat & Fish | F19: 397 | G19: Restaurant | H19: Cash | I19: ✅ Paid
... B46: 46165 | C46: Agua Natural | D46: — | E46: Supplies / Other | F46: 30 | G46: Restaurant | H46: Cash | I46: ✅ Paid
B47: 46165 | C47: John - Saldo Semana | D47: Nomina | E47: Staff - Salary | F47: 3250 | G47: Restaurant | H47: Cash | I47: ✅ Paid | J47: Head Chef — weekly salary Week 1
B48: 46165 | C48: Debi - Limpieza | D48: Nomina | E48: Staff - Salary | F48: 1500 | G48: Restaurant | H48: Cash | I48: ✅ Paid | J48: Cleaning staff — weekly salary Week 1
B49: 46165 | C49: Victor - Mesero (2 dias) | D49: Nomina | E49: Staff - Salary | F49: 666 | G49: Restaurant | H49: Cash | I49: ✅ Paid | J49: Waiter — 2 days salary Week 1
B50: 46165 | C50: Propinas - John (6 dias) | D50: Dist. propinas sem 1 | E50: Staff - Tips Distribution | F50: 515 | G50: Restaurant | H50: Cash | I50: ✅ Paid | J50: Tips distribution Week 1
B51: 46165 | C51: Propinas - Debi (6 dias) | D51: Dist. propinas sem 1 | E51: Staff - Tips Distribution | F51: 515 | G51: Restaurant | H51: Cash | I51: ✅ Paid | J51: Tips distribution Week 1
B52: 46165 | C52: Propinas - Victor (2 dias) | D52: Dist. propinas sem 1 | E52: Staff - Tips Distribution | F52: 168 | G52: Restaurant | H52: Cash | I52: ⏳ PENDING | J52: Yet to pay Victor — Week 1 tips
B53: 46165 | C53: Sal Fina (20 x 1 kg) | D53: Costco | E53: Ingredients - Pantry | F53: 408.17 | G53: Restaurant | H53: Card | I53: ✅ Paid | J53: Costco — Sal Fina 20/1KG
B54: 46165 | C54: Coca Cola (24 x 600ml) | D54: Costco | E54: Ingredients - Beverages | F54: 455.23 | G54: Restaurant | H54: Card | I54: ✅ Paid | J54: Costco — discount applied, total $844
B55: 46165 | C55: Leche Deslactosada (12 x 1LT) | D55: Sam's Club | E55: Ingredients - Dairy | F55: 317.13 | G55: Restaurant | H55: Card | I55: ✅ Paid | J55: Sam's Club — reimbursed to Shashirekha, settled
B56: 46165 | C56: Leche Alpura (12 x 1L) | D56: Sam's Club | E56: Ingredients - Dairy | F56: 317.13 | G56: Restaurant | H56: Card | I56: ✅ Paid | J56: Sam's Club — reimbursed to Shashirekha, settled
B57: 46165 | C57: Crema Ácida | D57: Sam's Club | E57: Ingredients - Dairy | F57: 250.63 | G57: Restaurant | H57: Card | I57: ✅ Paid | J57: Sam's Club — reimbursed to Shashirekha, settled
B58: 46165 | C58: Salsa / Tomate (12 x 600ml) | D58: Sam's Club | E58: Ingredients - Pantry | F58: 232.22 | G58: Restaurant | H58: Card | I58: ✅ Paid | J58: Sam's Club — reimbursed to Shashirekha, settled
B59: 46165 | C59: Champiñones (24 x 400ml) | D59: Sam's Club | E59: Ingredients - Vegetables | F59: 218.92 | G59: Restaurant | H59: Card | I59: ✅ Paid | J59: Sam's Club — reimbursed to Shashirekha, settled
B60: 46166 | C60: Guayabas Mediana | D60: Aviles Hernandez | E60: Ingredients - Fruit | F60: 120 | G60: Restaurant | H60: Cash | I60: ✅ Paid
B61: 46166 | C61: Jicamas + Pinas + Melon Chino | D61: El Matamoros | E61: Ingredients - Fruit | F61: 147 | G61: Restaurant | H61: Cash | I61: ✅ Paid
B62: 46166 | C62: Cilantro + Italiana | D62: Oscar Verduras | E62: Ingredients - Vegetables | F62: 100 | G62: Restaurant | H62: Cash | I62: ✅ Paid
B63: 46166 | C63: Habanero + Pepino | D63: Remision Formitec | E63: Ingredients - Vegetables | F63: 90 | G63: Restaurant | H63: Cash | I63: ✅ Paid
B64: 46166 | C64: Betabel (~1.9 kg) | D64: Nota Remision | E64: Ingredients - Vegetables | F64: 78 | G64: Restaurant | H64: Cash | I64: ✅ Paid
B65: 46166 | C65: Jitomate | D65: Brisia y Hermanos | E65: Ingredients - Vegetables | F65: 178 | G65: Restaurant | H65: Cash | I65: ✅ Paid
B66: 46166 | C66: Mango + Sandia | D66: Papayas Maradol | E66: Ingredients - Fruit | F66: 116 | G66: Restaurant | H66: Cash | I66: ✅ Paid
B67: 46166 | C67: Verduras variadas | D67: JP Verduras | E67: Ingredients - Vegetables | F67: 224 | G67: Restaurant | H67: Cash | I67: ✅ Paid
B68: 46166 | C68: Pimiento Morron | D68: Sin factura | E68: Ingredients - Vegetables | F68: 23 | G68: Restaurant | H68: Cash | I68: ✅ Paid | J68: No receipt — Sin factura
B69: 46167 | C69: Pan para Hamburguesa con Ajonjolí + Pan de Caja Arandano | D69: Real Abastos | E69: Ingredients - Bread | F69: 273 | G69: Restaurant | H69: Card | I69: ✅ Paid | J69: Real Sucursal Central de Abastos — 12 pcs hamburger buns + 3x900g bread
...

Sheet 📦 Inventory
A2: 📦 LOKA — INVENTORY | F2: Update stock levels when you receive deliveries or do stock checks
B5: TOTAL ITEMS | D5: ⚠️ LOW STOCK | E5: LOW STOCK # | F5: 🚫 OUT OF STOCK | H5: ALERT COUNT | J5: LAST UPDATED
B6: =COUNTA(B9:B200) -> 65 | D6: =COUNTIF(J9:J200,"⚠️ LOW STOCK") -> 0 | E6: =COUNTIF(J9:J200,"⚠️ LOW STOCK")+COUNTIF(J9:J200,"🚫 OUT OF STOCK") -> 0 | F6: =COUNTIF(J9:J200,"🚫 OUT OF STOCK") -> 0 | H6: =COUNTIF(J9:J200,"⚠️ LOW STOCK")+COUNTIF(J9:J200,"🚫 OUT OF STOCK") -> 0 | J6: =TODAY() -> 46181
B8: Item Name | Category | Unit | Min Stock | Current Stock | Last Ordered | Supplier | Status | Notes
B9: Carne de Res | C9: Ingredients - Meat | D9: kg | E9: 0 | J9: =IF(ISBLANK(F9),"—",IF(F9=0,"🚫 OUT OF STOCK",IF(F9<=E9,"⚠️ LOW STOCK","✅ OK"))) -> —
B10: Jamon Mexicano | C10: Ingredients - Meat | D10: kg | E10: 0 | J10: =IF(ISBLANK(F10),"—",IF(F10=0,"🚫 OUT OF STOCK",IF(F10<=E10,"⚠️ LOW STOCK","✅ OK"))) -> —
B11: Pollo | C11: Ingredients - Meat | D11: kg | E11: 0 | J11: =IF(ISBLANK(F11),"—",IF(F11=0,"🚫 OUT OF STOCK",IF(F11<=E11,"⚠️ LOW STOCK","✅ OK"))) -> —
B12: Chuletas de Carne | C12: Ingredients - Meat | D12: kg | E12: 0 | J12: =IF(ISBLANK(F12),"—",IF(F12=0,"🚫 OUT OF STOCK",IF(F12<=E12,"⚠️ LOW STOCK","✅ OK"))) -> —
B13: Costillas de Cerdo | C13: Ingredients - Meat | D13: kg | E13: 0 | J13: =IF(ISBLANK(F13),"—",IF(F13=0,"🚫 OUT OF STOCK",IF(F13<=E13,"⚠️ LOW STOCK","✅ OK"))) -> —
B14: Salmon | C14: Ingredients - Meat & Fish | D14: kg | E14: 0 | J14: =IF(ISBLANK(F14),"—",IF(F14=0,"🚫 OUT OF STOCK",IF(F14<=E14,"⚠️ LOW STOCK","✅ OK"))) -> —
B15: Filete de Mojarra | C15: Ingredients - Meat & Fish | D15: kg | E15: 0 | J15: =IF(ISBLANK(F15),"—",IF(F15=0,"🚫 OUT OF STOCK",IF(F15<=E15,"⚠️ LOW STOCK","✅ OK"))) -> —
B16: Papas | C16: Ingredients - Vegetables | D16: kg | E16: 0 | J16: =IF(ISBLANK(F16),"—",IF(F16=0,"🚫 OUT OF STOCK",IF(F16<=E16,"⚠️ LOW STOCK","✅ OK"))) -> —
B17: Lechuga | C17: Ingredients - Vegetables | D17: pcs | E17: 0 | J17: =IF(ISBLANK(F17),"—",IF(F17=0,"🚫 OUT OF STOCK",IF(F17<=E17,"⚠️ LOW STOCK","✅ OK"))) -> —
B18: Jitomate | C18: Ingredients - Vegetables | D18: kg | E18: 0 | J18: =IF(ISBLANK(F18),"—",IF(F18=0,"🚫 OUT OF STOCK",IF(F18<=E18,"⚠️ LOW STOCK","✅ OK"))) -> —
B19: Cilantro | C19: Ingredients - Vegetables | D19: pcs | E19: 0 | J19: =IF(ISBLANK(F19),"—",IF(F19=0,"🚫 OUT OF STOCK",IF(F19<=E19,"⚠️ LOW STOCK","✅ OK"))) -> —
B20: Italiana | C20: Ingredients - Vegetables | D20: pcs | E20: 0 | J20: =IF(ISBLANK(F20),"—",IF(F20=0,"🚫 OUT OF STOCK",IF(F20<=E20,"⚠️ LOW STOCK","✅ OK"))) -> —
... B73: Huevo Bachoco | C73: Ingredients - Pantry | D73: pcs | E73: 0 | J73: =IF(ISBLANK(F73),"—",IF(F73=0,"🚫 OUT OF STOCK",IF(F73<=E73,"⚠️ LOW STOCK","✅ OK"))) -> —

Sheet 👥 Staff & Payroll
A2: 👥 LOKA — STAFF & PAYROLL | D2: Weekly schedule + auto payroll calculation
A6: STAFF SCHEDULE — Week of: | D6: =TODAY()-WEEKDAY(TODAY(),2)+1 -> 46181
A7: Staff Name | B7: Role | C7: Daily Rate ($) | D7: Mon | E7: Tue | F7: Wed | G7: Thu | H7: Fri | I7: Sat | J7: Sun | K7: Days Worked | L7: Week Pay ($)
A8: John | B8: Head Chef | C8: 625 | D8: Full Day | E8: Full Day | F8: Full Day | G8: Full Day | H8: Full Day | I8: Full Day | J8: Day Off | K8: =COUNTIF(D8:J8,"Full Day") -> 6 | L8: =K8*C8 -> 3750
A9: Debi | B9: Cleaner | C9: 250 | D9: Full Day | E9: Full Day | F9: Full Day | G9: Full Day | H9: Full Day | I9: Full Day | J9: Day Off | K9: =COUNTIF(D9:J9,"Full Day") -> 6 | L9: =K9*C9 -> 1500
A10: Victor (INACTIVE) | B10: Mesero — Left after Week 1 | C10: 0 | D10: — | E10: — | F10: — | G10: — | H10: — | I10: — | J10: — | K10: 0 | L10: 0
A11: Judith | B11: Mesera / Waitress | C11: 333.33 | D11: Full Day | E11: Full Day | F11: Full Day | G11: Full Day | H11: Full Day | I11: Full Day | J11: Day Off | K11: =COUNTIF(D11:J11,"Full Day") -> 6 | L11: =K11*2000/6 -> 2000
A20: MONTHLY PAYROLL PROJECTION
A21: Staff Name | B21: Role | C21: Week Pay ($) | D21: x Weeks/Month | E21: Monthly ($) | F21: IMSS / Benefits % | G21: Total Monthly Cost ($) | H21: Notes
A22: =A8 -> John | B22: Head Chef | C22: =L8 -> 3750 | D22: 4 | E22: =C22*D22 -> 15000 | F22: 0.08 | G22: =E22*(1+F22) -> 16200
A23: =A9 -> Debi | B23: Sous Chef | C23: =L9 -> 1500 | D23: 4 | E23: =C23*D23 -> 6000 | F23: 0.08 | G23: =E23*(1+F23) -> 6480
A24: =A10 -> Victor (INACTIVE) | B24: Waiter 1 | C24: =L10 -> 0 | D24: 4 | E24: =C24*D24 -> 0 | F24: 0.08 | G24: =E24*(1+F24) -> 0
A25: =A11 -> Judith | B25: Waiter 2 | C25: =L11 -> 2000 | D25: 4 | E25: =C25*D25 -> 8000 | F25: 0.08 | G25: =E25*(1+F25) -> 8640
A26: =A12 -> 0 | B26: Barista | C26: =L12 -> 0 | D26: 4 | E26: =C26*D26 -> 0 | F26: 0.08 | G26: =E26*(1+F26) -> 0
A27: =A13 -> 0 | B27: Cashier | C27: =L13 -> 0 | D27: 4 | E27: =C27*D27 -> 0 | F27: 0.08 | G27: =E27*(1+F27) -> 0
A28: =A14 -> 0 | B28: Kitchen Helper | C28: =L14 -> 0 | D28: 4 | E28: =C28*D28 -> 0 | F28: 0.08 | G28: =E28*(1+F28) -> 0
A29: =A15 -> 0 | E29: =C29*D29 -> 0 | G29: =E29*(1+F29) -> 0
A30: TOTAL MONTHLY PAYROLL COST | G30: =SUM(G21:G28) -> 31320
A33: ── WEEKLY FIXED COSTS & BREAK-EVEN TARGETS ──
A34: COST ITEM | B34: WEEKLY ($) | C34: MONTHLY EST. ($) | D34: NOTES
A35: John — Head Chef Salary | B35: 3750 | C35: 15000 | D35: Confirmed weekly rate
A36: Debi — Limpieza Salary | B36: 1500 | C36: 6000 | D36: Confirmed weekly rate
A37: Rent + Maintenance (actual — $20,000/mo) | B37: 5000 | C37: 20000 | D37: Confirmed — $20,000/month actual
A38: Utilities — Electricity + Gas (estimated) | B38: 1000 | C38: 4000 | D38: ⏳ Approx — bills pending · electricity + gas
A39: TOTAL FIXED COSTS (current) | B39: =SUM(B35:B38) -> 11250 | C39: =SUM(C35:C38) -> 45000 | D39: Before ingredients & supplies
A41: ── WITH MESERO / WAITER — ✅ JUDITH HIRED (1 Jun 2026) ──
A42: Judith — Mesera Salary | B42: 2000 | C42: 8000 | D42: Confirmed — $2,000/week · $333.33/day · absent days deducted
A43: With Judith — Mesera (✅ ACTIVE from 1 Jun) | B43: 13250 | D43: 23750 | E43: 3959 | G43: ✅ NOW ACTIVE — current avg $4,011/day vs break-even $3959/day
A45: ── BREAK-EVEN & WEEKLY REVENUE TARGETS ──
A46: SCENARIO | B46: Fixed Costs ($) | C46: Avg Variable Costs ($) | D46: MIN Weekly Revenue ($) | E46: MIN Daily Revenue ($) | F46: Current Avg/Day ($) | G46: STATUS
A47: Without Mesero (NOW) | B47: 11250 | C47: 10500 | D47: 21750 | E47: 3625 | F47: 4011 | G47: ✅ Above break-even — revised down from $3,792 → $3,625/day
A48: With Mesero (~$2,250) | B48: 13500 | C48: 10500 | D48: 24000 | E48: 4000 | F48: 4011 | G48: ⚠️ Still below — need +$-11/day when mesero hired
A49: Safety buffer (+15%) | B49: 11250 | C49: 10500 | D49: 25012 | E49: 4169 | F49: 4011 | G49: Target for healthy buffer: $4,169/day
A51: NOTES:
A52: Variable costs = avg ingredients + supplies per week based on Weeks 1-2 actual data (~$10,500)
A53: Break-even revised: Rent+Maintenance confirmed $20,000/mo · Utilities est. $4,000/mo → Total overhead $24,000/mo
A54: Min daily (no mesero): $3,625 · With mesero: $4,000 · Comfortable target: $4,169+/day
A55: Utilities (electricity+gas) ~$4,000/mo is ESTIMATED — update when bills arrive
A59: ── LOHITH PERSONAL LEDGER — OWNER BALANCE TRACKER ──
A60: Date | B60: Description | C60: Type | D60: Spent by Lohith ($) | E60: Transferred to Lohith ($) | F60: Running Balance ($) | G60: Status | H60: Notes
...

Sheet 🚚 Suppliers
A2: 🚚 LOKA — SUPPLIER ORDERS | F2: Track purchase orders from suppliers
B5: TOTAL ORDERS | C5: PENDING | D5: IN TRANSIT | E5: RECEIVED | F5: MONTH SPEND | G5: PENDING VALUE | H5: PENDING COUNT
B6: =COUNTA(C9:C308)-1 -> -1 | C6: =COUNTIF(K9:K308,"Pending") -> 0 | D6: =COUNTIF(K9:K308,"In Transit") -> 0 | E6: =COUNTIF(K9:K308,"Received") -> 0 | F6: =SUMIF(K9:K308,"Received",J9:J308) -> 0 | G6: =SUMIF(K9:K308,"Pending",J9:J308) -> 0 | H6: =COUNTIF(K9:K308,"Pending")+COUNTIF(K9:K308,"In Transit") -> 0

Sheet 📋 Supplier Directory
B2: 📋 LOKA — SUPPLIER DIRECTORY
B3: Contact list for all regular suppliers
B6: Supplier Name | C6: Contact / Phone | D6: Products Supplied | E6: Location / Address | F6: Notes
B7: Girigallo | C7: 442-249-4707 | D7: Pollo | E7: Islas Aleutianas 134, Loma Linda, C.P 76070
B8: Alico | C8: 442-796-8876 | D8: Carne de hamburguesa, Papas, Boneless | E8: Cerro de las Campanas 173, Col. Las Americas
B9: Reca (Repartidor) | C9: 442-679-6651 | D9: Aguas Avia / Bebidas | E9: — | F9: Delivery supplier
B10: Toluco | C10: — | D10: Desechables (Plasticos) | E10: Plásticos Desechables el Toluco, C/ 15 de Mayo 189, La Santa Cruz, Centro, 76020 Santiago de Querétaro
B11: Bodega del Queso | C11: 442-114-0827 | D11: Queso, Jamon, Crema | E11: Avenida Universidad 119, Los Cedros, 76165 Santiago de Querétaro, Qro.
B12: Panadería Real | C12: 442-379-1880 | D12: Pan hamburguesa, Mayonesa, Arrachera, Sandwhich | E12: Plaza Capuchinas 149, Central de Abasto, Querétaro | F12: Also supplies at Brisa del Mar area
B13: Etrusca | C13: 442-234-5077 | D13: Sabores de Frappe, Matcha, Taro | E13: Café Etrusca Querétaro, Av. Tecnológico 10-Sur, Niños Héroes, 76010 Santiago de Querétaro
B16: Note: Additional suppliers recorded in expenses — Brisa del Mar, Chedraui, Costco, Real Abastos, OXXO, Pescadería El Faro

Sheet 📈 Monthly P&L
A2: 📈 LOKA — MONTHLY P&L | E2: Revenue & Expense summary — fill monthly totals from Daily Log & Expenses
B6: YEAR: | C6: 2025
C7: 2026

Sheet 📥 Pending Income
B2: LOKA CAFE RESTAURANTE — PENDING INCOME / RECEIVABLES | C2: LOKA CAFE RESTAURANTE — PENDING INCOME / RECEIVABLES | D2: LOKA CAFE RESTAURANTE — PENDING INCOME / RECEIVABLES | E2: LOKA CAFE RESTAURANTE — PENDING INCOME / RECEIVABLES | F2: LOKA CAFE RESTAURANTE — PENDING INCOME / RECEIVABLES | G2: LOKA CAFE RESTAURANTE — PENDING INCOME / RECEIVABLES | H2: LOKA CAFE RESTAURANTE — PENDING INCOME / RECEIVABLES | I2: LOKA CAFE RESTAURANTE — PENDING INCOME / RECEIVABLES
B4: Date Served | C4: Client | D4: Description | E4: Qty | F4: Unit Price ($) | G4: Total Amount ($) | H4: Status | I4: Notes
B5: 21-May-2026 | C5: Government Finances Dept. | D5: Catering order — 25 plates | E5: 25 | F5: 140 | G5: 3500 | H5: ⏳ NOT YET PAID | I5: Awaiting payment — follow up with client
B7: TOTAL PENDING | G7: 3500

Sheet 📊 Weekly Closing
B2: 📊 LOKA — WEEKLY CLOSING & PROPINAS
B3: Every Sunday night: enter closing balances to calculate propinas pool for the week
B6: ── WEEK 1 CLOSING SUMMARY (Sunday 25 May 2026) ──
B7: METRIC | D7: VALUE ($) | F7: NOTES
B8: Total Week Revenue (18–23 May) | D8: 24484 | F8: Card $12,386 + Cash $12,098
B9: Total Week Expenses (incl. propinas) | D9: 18157 | F9: All costs 18–24 May
B10: → Propinas Distributed | D10: 1030 | F10: John $515 + Debi $515
B11: → Propinas Pending | D11: 168 | F11: Victor $168 — yet to pay
B12: → Total Propinas | D12: 1198 | F12: To be paid from closing balance
B13: Total Expenses EXCL. Propinas | D13: 16959 | F13: Operating costs only
B14: Net Income (excl. propinas) | D14: 7525 | F14: =Revenue - Expenses excl. propinas -> #NAME?
B16: ── SUNDAY NIGHT CLOSING BALANCE ──
B17: Mercado Pago Balance | D17: 5553 | F17: Incl. MP commission already deducted
B18: Cash in Hand | D18: 3170 | F18: Physical cash end of week
B19: Total Closing Balance | D19: 8723 | F19: MP + Cash
B21: ── PROPINAS CALCULATION ──
B22: Propinas Pool | D22: 1198 | F22: =Closing Balance - Net (excl. propinas) -> #NAME?
B24: ── PROPINAS DISTRIBUTION ──
B25: Staff Name | C25: Role | D25: Days Worked | F25: Propinas Amount ($) | G25: Paid?
B26: John | C26: Head Chef | D26: 6 | F26: 515 | G26: ✅ Paid
B27: Debi | C27: Limpieza | D27: 6 | F27: 515 | G27: ✅ Paid
B28: Victor | C28: Mesero | D28: 2 | F28: 168 | G28: ⏳ PENDING
B29: TOTAL PROPINAS | F29: 1198
B30: Remaining after distribution | F30: 0 | G30: ← Should be 0 or rolled to next week
B34: ── WEEK 2 CLOSING SUMMARY (Sunday 31 May 2026) ──
B35: METRIC | C35: VALUE ($) | D35: NOTES
B36: Total Week Revenue (25–30 May) | D36: Fill from Daily Log
B37: Total Week Expenses (incl. propinas)
B38: → Propinas Distributed
B39: → Propinas Pending
B40: → Total Propinas
B41: Total Expenses EXCL. Propinas
B42: Net Income (excl. propinas)
B44: ── SUNDAY NIGHT CLOSING BALANCE ──
B45: Mercado Pago Balance | D45: Enter Sunday night amount
B46: Cash in Hand | D46: Enter Sunday night amount
B47: Total Closing Balance | D47: =MP + Cash -> #NAME?
B49: ── PROPINAS CALCULATION ──
B50: Propinas Pool | D50: =Closing Balance - Net (excl. propinas) -> #NAME?
B52: ── PROPINAS DISTRIBUTION ──
...
